Workbook

Sheet Assumptions
B1: All explicit numbers in blue, all calculations in black. No specific numbers in calculations, only reference other cells
B2: Company Assumptions | C2: Amount | D2: Unit | I2: Revenue Assumptions | J2: Amount | K2: Unit | M2: Expense Assumptions | N2: Amount | O2: Unit | Q2: Market Assumptions | R2: Amount
B4: Service frequency | C4: 1 | D4: per year | I4: Service fee | J4: 0.02 | K4: per d per year | M4: Employee Salary | N4: 90000 | O4: per employee | Q4: Total Market | R4: 9.81 | S4: billion
B5: Clients per person | C5: 10 | D5: per sales person | I5: 25kg Installation fee | J5: =N28 -> 1500 | K5: per device | M5: Salesperson Salary | N5: 60000 | Q5: Market Segment 1 | R5: ='Market Info'!B3 -> 0.2
B6: Sales cycle length | C6: 12 | D6: months | I6: 250kg Installation fee | J6: =N29 -> 15000 | K6: per device | M6: Installation cost | N6: 0.1 | O6: of total sale | Q6: Market Segment 2 | R6: ='Market Info'!B4 -> 0.05
B7: Order to Installation time | C7: 7 | D7: months | I7: 2500kg Installation fee | J7: =N30 -> 150000 | K7: per device | M7: Commission rate | N7: 0.05 | O7: of total sale | Q7: Market Segment 3 | R7: ='Market Info'!B5 -> 0.05
B8: Sales success rate | C8: 0.1 | I8: Device profit margin | J8: 1.5 | Q8: Market Segment 4 | R8: ='Market Info'!B6 -> 0.35
B9: Target growth rate | C9: 0.5 | I9: HaaS profit margin | J9: 0.3 | M9: 25kg Device cost | N9: 15000 | O9: per device | Q9: Market Segment 5 | R9: ='Market Info'!B7 -> 0.1
B10: Legal costs per client | C10: 100000 | M10: 250kg Device cost | N10: 150000 | O10: per device | Q10: Market Segment 6 | R10: ='Market Info'!B8 -> 0.05
B11: Employees per accountant | C11: 15 | M11: 2500kg Device cost | N11: 1500000 | O11: per device | Q11: Market Segment 7 | R11: ='Market Info'!B9 -> 0.1
B12: Electrolyzers per engineer | C12: 10 | I12: Haas Revenue | Q12: Market Segment 8 | R12: ='Market Info'!B10 -> 0.1
B13: Technicians per engineer | C13: 2 | M13: HaaS Expenses | Q13: Sum of %'s = 1 even if leaving some small segments out | R13: =SUM(R5:R12) -> 1
I14: H2 Price (including compression) | J14: =(N15*(1+J9))+N23 -> 3.51 | K14: per kg
C15: 1 | D15: 2 | E15: 3 | F15: 4 | G15: 5 | M15: H2 Cost | N15: 2.7 | O15: per kg | R15: Dsales Fit | S15: Haas Fit
B16: Sales people needed | C16: =C25 -> 10 | D16: =D25 -> 15 | E16: =E25 -> 22.5 | F16: =F25 -> 33.75 | G16: =G25 -> 50.625 | I16: 25kg Installation fee | J16: =N28 -> 1500 | K16: per device per contract | Q16: MS1 | R16: ='Market Info'!F3 -> 1 | S16: ='Market Info'!G3 -> 0
B17: Engineers needed | C17: =('Income Sheet'!C2+'Income Sheet'!C4)/Assumptions!$C$12 -> 12.373452 | D17: =('Income Sheet'!D2+'Income Sheet'!D4)/Assumptions!$C$12 -> 18.560178 | E17: =('Income Sheet'!E2+'Income Sheet'!E4)/Assumptions!$C$12 -> 27.840267 | F17: =('Income Sheet'!F2+'Income Sheet'!F4)/Assumptions!$C$12 -> 41.7604 | G17: =('Income Sheet'!G2+'Income Sheet'!G4)/Assumptions!$C$12 -> 62.6406 | I17: 250kg Installation fee | J17: =N29 -> 15000 | K17: per device per contract | M17: 25kg Installation cost | N17: =N9*$N$6 -> 1500 | O17: per device | Q17: MS2 | R17: ='Market Info'!F4 -> 0.25 | S17: ='Market Info'!G4 -> 0.75
B18: Technicians needed | C18: =C17*$C$13 -> 24.746904 | D18: =D17*$C$13 -> 37.120356 | E18: =E17*$C$13 -> 55.680533 | F18: =F17*$C$13 -> 83.5208 | G18: =G17*$C$13 -> 125.2812 | I18: 2500kg Installation fee | J18: =N30 -> 150000 | K18: per device per contract | M18: 250kg Installation cost | N18: =N10*$N$6 -> 15000 | O18: per device | Q18: MS3 | R18: ='Market Info'!F5 -> 0 | S18: ='Market Info'!G5 -> 1
B19: Accounting | C19: =(SUM(C16:C18)+2)/$C$11 -> 3.2746904 | D19: =(SUM(D16:D18)+2)/$C$11 -> 4.8453689 | E19: =(SUM(E16:E18)+2)/$C$11 -> 7.2013867 | F19: =(SUM(F16:F18)+2)/$C$11 -> 10.735413 | G19: =(SUM(G16:G18)+2)/$C$11 -> 16.036453 | M19: 2500kg Installation cost | N19: =N11*$N$6 -> 150000 | O19: per device | Q19: MS4 | R19: ='Market Info'!F6 -> 1 | S19: ='Market Info'!G6 -> 0
B20: Legal services | C20: =$C$10*C25 -> 1000000 | D20: =$C$10*D25 -> 1500000 | E20: =$C$10*E25 -> 2250000 | F20: =$C$10*F25 -> 3375000 | G20: =$C$10*G25 -> 5062500 | Q20: MS5 | R20: ='Market Info'!F7 -> 1 | S20: ='Market Info'!G7 -> 0
M21: Commision | N21: =J14*N7 -> 0.1755 | O21: per kg | Q21: MS6 | R21: ='Market Info'!F8 -> 0 | S21: ='Market Info'!G8 -> 1
C22: 1 | D22: 2 | E22: 3 | F22: 4 | G22: 5 | M22: Service cost | N22: 0.02 | O22: per device | Q22: MS7 | R22: ='Market Info'!F9 -> 0 | S22: ='Market Info'!G9 -> 1
B23: HaaS Customers | C23: =$S$35*C25 -> 2.8555046 | D23: =$S$35*D25 -> 4.2832569 | E23: =$S$35*E25 -> 6.4248853 | F23: =$S$35*F25 -> 9.637328 | G23: =$S$35*G25 -> 14.455992 | Q23: MS8 | R23: ='Market Info'!F10 -> 0.5 | S23: ='Market Info'!G10 -> 0.5
B24: Electrolyzer Sales Customers | C24: =$R$35*C25 -> 7.1444954 | D24: =$R$35*D25 -> 10.716743 | E24: =$R$35*E25 -> 16.075115 | F24: =$R$35*F25 -> 24.112672 | G24: =$R$35*G25 -> 36.169008
B25: Total Customers | C25: 10 | D25: =C25+(C25*$C$9) -> 15 | E25: =D25+(D25*$C$9) -> 22.5 | F25: =E25+(E25*$C$9) -> 33.75 | G25: =F25+(F25*$C$9) -> 50.625 | I25: Device Sales Revenue | R25: Dsales Total | S25: Haas total
M26: Device Sales Expenses | Q26: MS1 | R26: ='Market Info'!H3 -> 1.98 | S26: ='Market Info'!I3 -> 0
I27: 25kg Device price | J27: =N36*(1+$J$8) -> 43125 | K27: per device | Q27: MS2 | R27: ='Market Info'!H4 -> 0.12375 | S27: ='Market Info'!I4 -> 0.37125
C28: 1 | D28: 2 | E28: 3 | F28: 4 | G28: 5 | I28: 250kg Device price | J28: =N37*(1+$J$8) -> 600000 | K28: per device | M28: 25kg Installation cost | N28: =N9*$N$6 -> 1500 | O28: per device | Q28: MS3 | R28: ='Market Info'!H5 -> 0 | S28: ='Market Info'!I5 -> 0.495
B29: E.S | C29: =C24*$R$59 -> 113.59748 | D29: =D24*$R$59 -> 170.39622 | E29: =E24*$R$59 -> 255.59432 | F29: =F24*$R$59 -> 383.39149 | G29: =G24*$R$59 -> 575.08723 | I29: 2500kg Device price | J29: =N38*(1+$J$8) -> 4312500 | K29: per device | M29: 250kg Installation cost | N29: =N10*$N$6 -> 15000 | O29: per device | Q29: MS4 | R29: ='Market Info'!H6 -> 3.465 | S29: ='Market Info'!I6 -> 0
B30: HaaS | C30: =C23*$S$59 -> 10.137041 | D30: =D23*$S$59 -> 15.205562 | E30: =E23*$S$59 -> 22.808343 | F30: =F23*$S$59 -> 34.212514 | G30: =G23*$S$59 -> 51.318772 | M30: 2500kg Installation cost | N30: =N11*$N$6 -> 150000 | O30: per device | Q30: MS5 | R30: ='Market Info'!H7 -> 0.99 | S30: ='Market Info'!I7 -> 0
B31: Total | C31: =SUM(C29:C30) -> 123.73452 | D31: =SUM(D29:D30) -> 185.60178 | E31: =SUM(E29:E30) -> 278.40267 | F31: =SUM(F29:F30) -> 417.604 | G31: =SUM(G29:G30) -> 626.406 | I31: 25kg Device service | J31: =J27*$J$4 -> 862.5 | K31: per d per year | Q31: MS6 | R31: ='Market Info'!H8 -> 0 | S31: ='Market Info'!I8 -> 0.495
I32: 250kg Device service | J32: =J28*$J$4 -> 12000 | K32: per d per year | M32: 25kg Commission cost | N32: =N9*$N$7 -> 750 | O32: per device | Q32: MS7 | R32: ='Market Info'!H9 -> 0 | S32: ='Market Info'!I9 -> 0.99
I33: 2500kg Device service | J33: =J29*$J$4 -> 86250 | K33: per d per year | M33: 250kg Commission cost | N33: =N10*$N$7 -> 7500 | O33: per device | Q33: MS8 | R33: ='Market Info'!H10 -> 0.45 | S33: ='Market Info'!I10 -> 0.45
M34: 2500kg Commission cost | N34: =N11*$N$7 -> 75000 | O34: per device | Q34: Total | R34: =SUM(R26:R33) -> 7.00875 | S34: =SUM(S26:S33) -> 2.80125
Q35: Split | R35: =R34/SUM(R34:S34) -> 0.71444954 | S35: =S34/SUM(R34:S34) -> 0.28555046
M36: 25kg Total cost | N36: =N9+N28+N32 -> 17250 | O36: per device
M37: 250kg Total cost | N37: =N10+N29+N34 -> 240000 | O37: per device | Q37: DSales Market + HaaS Market = X | R37: =SUM(R34:S34) -> 9.81
M38: 2500kg Total cost | N38: =N11+N30+N34 -> 1725000 | O38: per device
Q39: MS1 customer avg H2 | R39: 4000 | S39: kg/day | T39: 750000 | U39: kg/yr
M40: Service cost | N40: 0.02 | O40: per device | Q40: MS2 customer avg H2 | R40: 5000 | S40: kg/day | T40: 300000 | U40: kg/yr
Q41: MS3 customer avg H2 | R41: 200 | S41: kg/day | T41: 60000 | U41: kg/yr
...

Sheet Income Sheet
B2: number of electrolyzers sold | C2: =Assumptions!C24*Assumptions!R59 -> 113.59748 | D2: =Assumptions!D24*Assumptions!R59 -> 170.39622 | E2: =Assumptions!R59*Assumptions!E24 -> 255.59432 | F2: =Assumptions!F24*Assumptions!R59 -> 383.39149 | G2: =Assumptions!R59*Assumptions!G24 -> 575.08723
B3: number of kgs sold (HaaS) | C3: =Assumptions!C23*Assumptions!T59 -> 3712156 | D3: =Assumptions!T59*Assumptions!D23 -> 5568233.9 | E3: =Assumptions!E23*Assumptions!T59 -> 8352350.9 | F3: =Assumptions!T59*Assumptions!F23 -> 12528526 | G3: =Assumptions!G23*Assumptions!T59 -> 18792790
B4: Electrolyzer required for HaaS | C4: =Assumptions!S59*Assumptions!C23 -> 10.137041 | D4: =Assumptions!S59*Assumptions!D23 -> 15.205562 | E4: =Assumptions!E23*Assumptions!S59 -> 22.808343 | F4: =Assumptions!S59*Assumptions!F23 -> 34.212514 | G4: =Assumptions!G23*Assumptions!S59 -> 51.318772
B6: Year | C6: 1* | D6: 2 | E6: 3 | F6: 4 | G6: 5 | I6: *since the sales cycle + installation time is ~1.5 years, year 1 starts 1.5 years after recommendations are implemented
B8: Revenue
B9: Electrolyzer Sales | C9: =C2*Assumptions!$J$28 -> 68158486 | D9: =D2*Assumptions!$J$28 -> 1.0223773e+08 | E9: =E2*Assumptions!$J$28 -> 1.5335659e+08 | F9: =F2*Assumptions!$J$28 -> 2.3003489e+08 | G9: =G2*Assumptions!$J$28 -> 3.4505234e+08
B10: HaaS | C10: =C3*Assumptions!$J$14 -> 13029667 | D10: =D3*Assumptions!$J$14 -> 19544501 | E10: =E3*Assumptions!$J$14 -> 29316752 | F10: =F3*Assumptions!$J$14 -> 43975128 | G10: =G3*Assumptions!$J$14 -> 65962691
B11: Electrolyzer Sales Installation fee | C11: =C2*Assumptions!$J$6 -> 1703962.2 | D11: =D2*Assumptions!$J$6 -> 2555943.2 | E11: =E2*Assumptions!$J$6 -> 3833914.9 | F11: =F2*Assumptions!$J$6 -> 5750872.3 | G11: =G2*Assumptions!$J$6 -> 8626308.4
B12: HaaS Installation fee | C12: =C4*Assumptions!$N$18 -> 152055.62 | D12: =D4*Assumptions!$N$18 -> 228083.43 | E12: =E4*Assumptions!$N$18 -> 342125.14 | F12: =F4*Assumptions!$N$18 -> 513187.72 | G12: =G4*Assumptions!$N$18 -> 769781.57
B13: Electrolyzer Service fee | C13: =C2*Assumptions!$J$32 -> 1363169.7 | D13: =D2*Assumptions!$J$32 -> 2044754.6 | E13: =E2*Assumptions!$J$32 -> 3067131.9 | F13: =F2*Assumptions!$J$32 -> 4600697.8 | G13: =G2*Assumptions!$J$32 -> 6901046.7
B15: total revenue | C15: =SUM(C9:C13) -> 84407341 | D15: =SUM(D9:D13) -> 1.2661101e+08 | E15: =SUM(E9:E13) -> 1.8991652e+08 | F15: =SUM(F9:F13) -> 2.8487478e+08 | G15: =SUM(G9:G13) -> 4.2731216e+08
B17: Expenses
B18: Electrolyzer cost | C18: =(C2*Assumptions!$N$37)+('Income Sheet'!C4*(Assumptions!$N$10+Assumptions!$N$18)) -> 28936006 | D18: =(D2*Assumptions!$N$37)+('Income Sheet'!D4*(Assumptions!$N$10+Assumptions!$N$18)) -> 43404009 | E18: =(E2*Assumptions!$N$37)+('Income Sheet'!E4*(Assumptions!$N$10+Assumptions!$N$18)) -> 65106014 | F18: =(F2*Assumptions!$N$37)+('Income Sheet'!F4*(Assumptions!$N$10+Assumptions!$N$18)) -> 97659021 | G18: =(G2*Assumptions!$N$37)+('Income Sheet'!G4*(Assumptions!$N$10+Assumptions!$N$18)) -> 1.4648853e+08
B19: Service costs | C19: =(C2+C4)*Assumptions!$N$10*Assumptions!$N$22 -> 371203.56 | D19: =(D2+D4)*Assumptions!$N$10*Assumptions!$N$22 -> 556805.33 | E19: =(E2+E4)*Assumptions!$N$10*Assumptions!$N$22 -> 835208 | F19: =(F2+F4)*Assumptions!$N$10*Assumptions!$N$22 -> 1252812 | G19: =(G2+G4)*Assumptions!$N$10*Assumptions!$N$22 -> 1879218
B20: Salaries | C20: =(Assumptions!$N$4*SUM(Assumptions!C17:C19))+(Assumptions!$N$5*Assumptions!C16) -> 4235554.1 | D20: =(Assumptions!$N$4*SUM(Assumptions!D17:D19))+(Assumptions!$N$5*Assumptions!D16) -> 6347331.2 | E20: =(Assumptions!$N$4*SUM(Assumptions!E17:E19))+(Assumptions!$N$5*Assumptions!E16) -> 9514996.8 | F20: =(Assumptions!$N$4*SUM(Assumptions!F17:F19))+(Assumptions!$N$5*Assumptions!F16) -> 14266495 | G20: =(Assumptions!$N$4*SUM(Assumptions!G17:G19))+(Assumptions!$N$5*Assumptions!G16) -> 21393743
B21: Other business services | C21: =Assumptions!C20 -> 1000000 | D21: =Assumptions!D20 -> 1500000 | E21: =Assumptions!E20 -> 2250000 | F21: =Assumptions!F20 -> 3375000 | G21: =Assumptions!G20 -> 5062500
B25: total expanses | C25: =SUM(C18:C21) -> 34542764 | D25: =SUM(D18:D21) -> 51808146 | E25: =SUM(E18:E21) -> 77706219 | F25: =SUM(F18:F21) -> 1.1655333e+08 | G25: =SUM(G18:G21) -> 1.7482399e+08
B27: Profit | C27: =C15-C25 -> 49864577 | D27: =D15-D25 -> 74802866 | E27: =E15-E25 -> 1.122103e+08 | F27: =F15-F25 -> 1.6832145e+08 | G27: =G15-G25 -> 2.5248817e+08 | H27: =SUM(C27:G27) -> 6.5768736e+08

Sheet Market Info
A2: Segment | B2: Market Share | C2: Market Size($B) | D2: Number of Customers | E2: HaaS Probability | F2: E.S. Coverage | G2: HaaS Coverage | H2: E.S. Market | I2: HaaS Market | J2: E.S. Customers | K2: HaaS Customers
A3: 1. Heavy-duty fueling (truck stops, long-haul corridors) | B3: 0.2 | C3: =9.9*B3 -> 1.98 | D3: 6320 | E3: Low | F3: =VLOOKUP(E3,Table1[#All], 2,FALSE) -> 1 | G3: =VLOOKUP(E3,Table1[#All], 3,FALSE) -> 0 | H3: =C3*F3 -> 1.98 | I3: =G3*C3 -> 0 | J3: =D3*F3 -> 6320 | K3: =D3*G3 -> 0
A4: 2. Urban fleet fueling (buses, municipal fleets, ports, airports) | B4: 0.05 | C4: =9.9*B4 -> 0.495 | D4: 6000 | E4: Medium | F4: 0.25 | G4: 0.75 | H4: =C4*F4 -> 0.12375 | I4: =G4*C4 -> 0.37125 | J4: =D4*F4 -> 1500 | K4: =D4*G4 -> 4500
A5: 3. Light & medium-duty commercial fueling (material handling equipment, last-mile delivery fleets, local distribution - Zeeco, Amazon, FedEx) | B5: 0.05 | C5: =9.9*B5 -> 0.495 | D5: 5000 | E5: High | F5: =VLOOKUP(E5,Table1[#All], 2,FALSE) -> 0 | G5: =VLOOKUP(E5,Table1[#All], 3,FALSE) -> 1 | H5: =C5*F5 -> 0 | I5: =G5*C5 -> 0.495 | J5: =D5*F5 -> 0 | K5: =D5*G5 -> 5000
A6: 4. Industrial decarbonization (on-site hydrogen for process heat, fuel substitution - electronics and semiconductor manufacturing, glass and metal processing, and food and beverage hydrogenation) | B6: 0.35 | C6: =9.9*B6 -> 3.465 | D6: 3000 | E6: Low | F6: =VLOOKUP(E6,Table1[#All], 2,FALSE) -> 1 | G6: =VLOOKUP(E6,Table1[#All], 3,FALSE) -> 0 | H6: =C6*F6 -> 3.465 | I6: =G6*C6 -> 0 | J6: =D6*F6 -> 3000 | K6: =D6*G6 -> 0
A7: 5. Chemical production & synthetic fuels (ammonia, methanol, etc.) | B7: 0.1 | C7: =9.9*B7 -> 0.99 | D7: 50 | E7: Low | F7: =VLOOKUP(E7,Table1[#All], 2,FALSE) -> 1 | G7: =VLOOKUP(E7,Table1[#All], 3,FALSE) -> 0 | H7: =C7*F7 -> 0.99 | I7: =G7*C7 -> 0 | J7: =D7*F7 -> 50 | K7: =D7*G7 -> 0
A8: 6. Backup power & microgrids (data centers, hospital backup, remote sites) | B8: 0.05 | C8: =9.9*B8 -> 0.495 | D8: 11500 | E8: High | F8: =VLOOKUP(E8,Table1[#All], 2,FALSE) -> 0 | G8: =VLOOKUP(E8,Table1[#All], 3,FALSE) -> 1 | H8: =C8*F8 -> 0 | I8: =G8*C8 -> 0.495 | J8: =D8*F8 -> 0 | K8: =D8*G8 -> 11500
A9: 7. Energy storage / grid balancing (power-to-gas, seasonal/utility storage) | B9: 0.1 | C9: =9.9*B9 -> 0.99 | D9: 79 | E9: High | F9: =VLOOKUP(E9,Table1[#All], 2,FALSE) -> 0 | G9: =VLOOKUP(E9,Table1[#All], 3,FALSE) -> 1 | H9: =C9*F9 -> 0 | I9: =G9*C9 -> 0.99 | J9: =D9*F9 -> 0 | K9: =D9*G9 -> 79
A10: 8. Already green, can undercut competitors | B10: 0.1 | C10: =0.9 -> 0.9 | D10: 76 | E10: Medium | F10: =VLOOKUP(E10,Table1[#All], 2,FALSE) -> 0.5 | G10: =VLOOKUP(E10,Table1[#All], 3,FALSE) -> 0.5 | H10: =C10*F10 -> 0.45 | I10: =G10*C10 -> 0.45 | J10: =D10*F10 -> 38 | K10: =D10*G10 -> 38
A11: TOTAL | B11: =SUM(B3:B10) -> 1 | C11: =SUM(C3:C10) -> 9.81 | D11: =SUM(D3:D10) -> 32025 | H11: =SUM(H3:H9) -> 6.55875 | I11: =SUM(I3:I9) -> 2.35125 | J11: =SUM(J3:J9) -> 10870 | K11: =SUM(K3:K9) -> 21079
A28: Electrolyzer Sales | B28: 6.44
A29: HaaS | B29: 1.99
A30: Variable | B30: 1.4

Sheet Probability Matrix
B1: Question | C1: If yes
B2: 1. Does the industry require building a fuel station? | C2: Low/Medium* | E2: *Once Tobe has aquired more capital, building a Tobe fueling station becomes more realistic and this will switch from medium -> high
B3: 2. Is the industry a large H2 user? | C3: Low
B4: 3. Does the industry want total self-sufficiency? | C4: medium
B5: 4. Is the industry seasonal? | C5: High
B6: 5. Do factors depend on individual companies? | C6: Medium
B7: 5. Motivations unkown? | C7: Unknown
B8: 6. Other defining factors? | C8: High
B9: 7. All others | C9: Medium
B11: Probability | C11: E.S | D11: SaaS
B12: High | C12: 0 | D12: 1
B13: Medium | C13: 0.5 | D13: 0.5
B14: Low | C14: 1 | D14: 0
B44: <50 mi | C44: 0.7
B45: 50-150 mi | C45: 0.2
B46: 150+ mi | C46: 0.1

Sheet Sources
A1: Green Hydrogen Market Size, Share & Growth Report, 2030
A2: Hydrogen demand – Global Hydrogen Review 2024 – Analysis - IEA
A3: DOE Hydrogen and Fuel Cells Program Record 19002: Current Hydrogen Market Size: Domestic and Global
A4: Hydrogen Generation Market Size | Industry Report, 2030
A5: Hydrogen Storage and Transportation Market Report I BIS Research
A6: Global Energy Perspective 2023: Hydrogen outlook | McKinsey
A7: U.S. Hydrogen Energy Storage Market | Industry Report, 2030
A8: Global-Hydrogen-Flows.pdf
A9: U.S. National Clean Hydrogen Strategy and Roadmap
A10: Number of Allstays Truck Stops locations in the USA in 2025 | ScrapeHero
A11: APTA-2025-Public-Transportation-Fact-Book.pdf
A12: U.S. Automobile and Truck Fleets by Use | Bureau of Transportation Statistics
... A28: Hydrogen Fueling Station Cost Reduction Study
