Workbook
Name addl_facility_capex: ASSUMPTIONS!$C$50
Name asset_life: ASSUMPTIONS!$C$53
Name benefits_loading: ASSUMPTIONS!$C$60
Name blended_h2_cogs: ASSUMPTIONS!$C$134:$I$134
Name bop_efficiency: ASSUMPTIONS!$C$11
Name compression_energy: ASSUMPTIONS!$C$12
Name debt_rate: ASSUMPTIONS!$C$81
Name direct_variable_cost: ASSUMPTIONS!$C$34
Name electricity_price: ASSUMPTIONS!$C$5
Name h2_asp: ASSUMPTIONS!$C$15
Name h2_production_fy7: ASSUMPTIONS!$I$105
Name maintenance_cost: ASSUMPTIONS!$C$59
Name nameplate_per_facility: ASSUMPTIONS!$C$22
Name pilot_capex: ASSUMPTIONS!$C$49
Name pre_money_val: ASSUMPTIONS!$C$78
Name ptc_rate: ASSUMPTIONS!$C$68
Name ptc_toggle: ASSUMPTIONS!$C$72
Name seed_debt: ASSUMPTIONS!$C$76
Name seed_equity: ASSUMPTIONS!$C$75
Name stack_sec: ASSUMPTIONS!$C$7
Name system_sec_base: ASSUMPTIONS!$C$8
Name t125_cogs: ASSUMPTIONS!$C$41
Name t125_price: ASSUMPTIONS!$C$40
Name t25_cogs: ASSUMPTIONS!$C$38
Name t25_price: ASSUMPTIONS!$C$37
Name tax_rate: ASSUMPTIONS!$C$67
Name utilization_target: ASSUMPTIONS!$C$25
Name wind_ppa_rate: ASSUMPTIONS!$C$6

Sheet COVER
B3: TOBE ENERGY CORP
B5: Comprehensive Financial Model
B6: Seed Round — $10M Raise at $40M Pre-Money Valuation
B8: Membrane-Free Green Hydrogen Electrolysis
B10: Date: | C10: March 2026
B11: Version: | C11: v1.0 — Consolidated Model
B12: Confidentiality: | C12: CONFIDENTIAL — For Authorized Recipients Only
B14: TABLE OF CONTENTS
B16: 1. COVER | C16: Title page and table of contents
B17: 2. EXECUTIVE SUMMARY | C17: Dashboard of key metrics and investment highlights
B18: 3. ASSUMPTIONS | C18: All input assumptions — yellow cells drive the entire model
B19: 4. UNIT ECONOMICS | C19: Per-kg cost build-up and margin analysis
B20: 5. REVENUE MODEL | C20: Revenue by stream, customer pipeline, facility ramp
B21: 6. P&L | C21: 7-year income statement (FY1-FY7)
B22: 7. CASH FLOW | C22: Operating, investing, and financing cash flows
B23: 8. FACILITY RAMP | C23: Facility-by-facility capacity, capex, and timeline
B24: 9. 45V TAX CREDIT | C24: Production tax credit analysis and eligibility
B25: 10. MARKET & TAM | C25: Market sizing: $9.81B serviceable market
B26: 11. COMPETITIVE LANDSCAPE | C26: Technology and cost comparison vs. peers
B27: 12. CAP TABLE | C27: Pre-seed and post-seed ownership structure
... B29: 14. SOURCES & NOTES | C29: Citations, methodology, glossary, disclaimers
B32: Contact:
B33: Colby DeWeese, CEO
B34: colby@tobe.energy
B35: Tobe Energy Corp
B38: Model Information:
B39: Built from 8 source documents including TEA v3.0, Financial Model v8.5.3,
B40: OU Irani Center Case Study, and external model review.
B41: Contains 14 tabs, 400+ formulas, 23+ named ranges.
B42: Yellow cells = modifiable inputs. Blue cells = calculated values.

Sheet EXECUTIVE SUMMARY
B1: EXECUTIVE SUMMARY
B2: Tobe Energy Corp — Seed Round Financial Model Dashboard
B4: KEY METRICS AT A GLANCE (FY7)
B5: Metric | C5: Value | D5: Notes
B6: FY7 Operating Revenue | C6: ='P&L'!I11 -> 327654846 | D6: 12 facilities × 3 revenue streams
B7: FY7 EBITDA | C7: ='P&L'!I31 -> 2.0943112e+08 | D7: ='P&L'!I32 -> 0.63918212
B8: FY7 Net Income | C8: ='P&L'!I40 -> 1.5247547e+08 | D8: ='P&L'!I41 -> 0.46535393
B9: FY7 Cash Position | C9: ='P&L'!I43 -> 832781983 | D9: Self-funding by FY5
B10: LCOH (Base Case) | C10: =ASSUMPTIONS!C34+ASSUMPTIONS!C59+1.389+ASSUMPTIONS!C49/ASSUMPTIONS!C53/ASSUMPTIONS!C22 -> 5.0832895 | D10: All-in $/kg at nameplate
B11: H₂ ASP | C11: =ASSUMPTIONS!C15 -> 25 | D11: $/kg blended across customer segments
B12: H₂ Gross Margin (at ASP) | C12: ='P&L'!I20 -> 0.78576795 | D12: FY7 gross margin
B13: Seed Round Size | C13: =ASSUMPTIONS!C77 -> 10000000 | D13: $7.5M equity + $2.5M debt
B14: Pre-Money Valuation | C14: =ASSUMPTIONS!C78 -> 40000000 | D14: $40M pre-money
B16: REVENUE TRAJECTORY (FY1-FY7)
B17: ($M) | C17: FY1 | D17: FY2 | E17: FY3 | F17: FY4 | G17: FY5 | H17: FY6 | I17: FY7
B18: H₂ Production | C18: ='P&L'!C7/1000000 -> 0 | D18: ='P&L'!D7/1000000 -> 11.8125 | E18: ='P&L'!E7/1000000 -> 77.8125 | F18: ='P&L'!F7/1000000 -> 141.5625 | G18: ='P&L'!G7/1000000 -> 210.9375 | H18: ='P&L'!H7/1000000 -> 264.375 | I18: ='P&L'!I7/1000000 -> 270
B19: Equipment Sales | C19: ='P&L'!C8/1000000 -> 0.875 | D19: ='P&L'!D8/1000000 -> 4.295 | E19: ='P&L'!E8/1000000 -> 10.26 | F19: ='P&L'!F8/1000000 -> 18.77 | G19: ='P&L'!G8/1000000 -> 28.95 | H19: ='P&L'!H8/1000000 -> 39.13 | I19: ='P&L'!I8/1000000 -> 51.06
B20: Services | C20: ='P&L'!C9/1000000 -> 0 | D20: ='P&L'!D9/1000000 -> 0.032813 | E20: ='P&L'!E9/1000000 -> 0.242113 | F20: ='P&L'!F9/1000000 -> 0.848205 | G20: ='P&L'!G9/1000000 -> 2.092281 | H20: ='P&L'!H9/1000000 -> 4.204952 | I20: ='P&L'!I9/1000000 -> 6.594846
B21: Operating Revenue | C21: ='P&L'!C11/1000000 -> 0.875 | D21: ='P&L'!D11/1000000 -> 16.140313 | E21: ='P&L'!E11/1000000 -> 88.314613 | F21: ='P&L'!F11/1000000 -> 161.1807 | G21: ='P&L'!G11/1000000 -> 241.97978 | H21: ='P&L'!H11/1000000 -> 307.70995 | I21: ='P&L'!I11/1000000 -> 327.65485
B22: 45V PTC | C22: ='P&L'!C10/1000000 -> 0 | D22: ='P&L'!D10/1000000 -> 1.4175 | E22: ='P&L'!E10/1000000 -> 8.8875 | F22: ='P&L'!F10/1000000 -> 10.8 | G22: ='P&L'!G10/1000000 -> 10.8 | H22: ='P&L'!H10/1000000 -> 10.8 | I22: ='P&L'!I10/1000000 -> 10.8
B24: EBITDA ($M) | C24: ='P&L'!C31/1000000 -> -2.6531976 | D24: ='P&L'!D31/1000000 -> 3.6952452 | E24: ='P&L'!E31/1000000 -> 54.545917 | F24: ='P&L'!F31/1000000 -> 104.48791 | G24: ='P&L'!G31/1000000 -> 158.16988 | H24: ='P&L'!H31/1000000 -> 201.71964 | I24: ='P&L'!I31/1000000 -> 209.43112
B25: Net Income ($M) | C25: ='P&L'!C40/1000000 -> -2.7831066 | D25: ='P&L'!D40/1000000 -> 2.5922608 | E25: ='P&L'!E40/1000000 -> 44.489636 | F25: ='P&L'!F40/1000000 -> 81.157013 | G25: ='P&L'!G40/1000000 -> 118.45502 | H25: ='P&L'!H40/1000000 -> 148.04109 | I25: ='P&L'!I40/1000000 -> 152.47547
B26: Cash ($M) | C26: ='P&L'!C43/1000000 -> 1.289092 | D26: ='P&L'!D43/1000000 -> 49.613513 | E26: ='P&L'!E43/1000000 -> 139.48772 | F26: ='P&L'!F43/1000000 -> 224.1518 | G26: ='P&L'!G43/1000000 -> 478.38468 | H26: ='P&L'!H43/1000000 -> 684.95995 | I26: ='P&L'!I43/1000000 -> 832.78198
B27: EBITDA Margin % | C27: ='P&L'!C32 -> -3.0322258 | D27: ='P&L'!D32 -> 0.22894508 | E27: ='P&L'!E32 -> 0.61763185 | F27: ='P&L'!F32 -> 0.64826563 | G27: ='P&L'!G32 -> 0.65364915 | H27: ='P&L'!H32 -> 0.65555124 | I27: ='P&L'!I32 -> 0.63918212
B29: INVESTMENT HIGHLIGHTS
B30: 1. 92% System Efficiency — membrane-free electrolysis eliminates Nafion ($500-800/m²) and rare earth catalysts
B31: 2. EBITDA Positive from Year 2 — strong unit economics at ~$4.84/kg all-in vs. $25/kg ASP
B32: 3. 12 Facilities by FY7 — 4 ramp tiers (Pilot 24mo → Mastered 13mo); 900K kg/yr nameplate each
B33: 4. 45V PTC: $27M per Eligible Facility — $3/kg × 900K kg × 10 years; 4 facilities qualify
B34: 5. 3-Engine Revenue Model — H₂ production + equipment sales (T-25/T-125) + recurring services (75% attach)
B35: 6. $20M+ Signed LOIs — $26M+ active quotes across 7 industry sectors
B37: USE OF FUNDS — $10M SEED
B38: Category | C38: Amount | D38: %
B39: Equity ($7.5M)
B40: R&D: T-125 System Validation | C40: 1100000 | D40: 14.7%
B41: Manufacturing Equipment | C41: 1120000 | D41: 14.9%
B42: Personnel (15-month) | C42: 2211496 | D42: 29.5%
B43: Certifications & Compliance | C43: 475000 | D43: 6.3%
B44: Working Capital & G&A | C44: 1911250 | D44: 25.5%
B45: Contingency (10%) | C45: 682254 | D45: 9.1%
...

Sheet ASSUMPTIONS
B1: INPUT ASSUMPTIONS
B2: All yellow cells are inputs. All blue cells are calculated. Every derived value in this workbook references cells on this sheet.
B3: Parameter | C3: Value | D3: Unit | E3: Source / Notes
B4: ELECTRICITY & ENERGY
B5: Base Electricity Price | C5: 0.04 | D5: $/kWh | E5: PSO large-power industrial tariff (TEA Table 27)
B6: Wind PPA Rate | C6: 0.025 | D6: $/kWh | E6: TEA Table 27 upside scenario
B7: Stack SEC | C7: 42.2 | D7: kWh/kg | E7: Lab-validated at stack level (TEA §3)
B8: System SEC (Base Case) | C8: 46.5 | D8: kWh/kg | E8: System-level incl. BOP (TEA Table 27)
B9: System SEC (Conservative) | C9: 42.8 | D9: kWh/kg | E9: Conservative scenario
B10: System SEC (Optimized) | C10: 39.6 | D10: kWh/kg | E10: Optimized power electronics
B11: BOP Efficiency | C11: 0.95 | D11: % | E11: v853 Base Case Inputs B90
B12: Compression Energy | C12: 3.5 | D12: kWh/kg | E12: v853 Base Case Inputs
B14: HYDROGEN PRICING
B15: Base H₂ ASP (Blended) | C15: 25 | D15: $/kg | E15: v853; range $15-$47 from customer quotes
B16: Bear Case Price | C16: 15 | D16: $/kg | E16: Grey H₂ parity / bulk contract
B17: Conservative Price | C17: 20 | D17: $/kg | E17: Industrial mid-range
B18: Bull Case Price | C18: 30 | D18: $/kg | E18: On-site premium
B19: Premium Price | C19: 47 | D19: $/kg | E19: Cylinder replacement / CA fueling
B21: PRODUCTION
B22: Nameplate per Facility | C22: 900000 | D22: kg/yr | E22: v853: 2,500 kg/day × 360 days
B23: T-25 Capacity | C23: 25 | D23: kg/day | E23: Product spec
B24: T-125 Capacity | C24: 125 | D24: kg/day | E24: Product spec
B25: Utilization Target | C25: 0.85 | D25: % | E25: TEA base case capacity factor
B26: Water Usage | C26: 9 | D26: L/kg | E26: TEA §3; vs. PEM 9-10 kg ultra-pure DI
B27: Water Cost | C27: 0.00556 | D27: $/L | E27: Tulsa municipal rate $2.50/1000 gal
B28: Transport Cost (50-mile) | C28: 0.9 | D28: $/kg | E28: Tube trailer 50-mile radius
B30: UNIT COST CALCULATIONS (Derived)
B31: Electricity Cost per kg | C31: =C7/C11*C5 -> 1.7768421 | D31: $/kg | E31: Stack SEC / BOP Eff × Elec Price
B32: Compression Cost per kg | C32: =C12*C5 -> 0.14 | D32: $/kg | E32: Compression kWh × Elec Price
B33: Water Cost per kg | C33: =C26*C27 -> 0.05004 | D33: $/kg | E33: Water Usage × Water Cost
B34: Direct Variable Cost per kg | C34: =C31+C32+C28+C33 -> 2.8668821 | D34: $/kg | E34: Electricity + Compression + Transport + Water
B36: EQUIPMENT SALES
B37: T-25 Sale Price | C37: 35000 | D37: $ | E37: Pulse Holdings Quote TE-PH-ELX-88-51
B38: T-25 Launch COGS | C38: 21000 | D38: $ | E38: 60% COGS rate at launch
B39: T-25 Gross Margin | C39: =(C37-C38)/C37 -> 0.4 | D39: % | E39: Calculated
B40: T-125 Sale Price | C40: 167000 | D40: $ | E40: $120K base + $47K options (90% attach)
B41: T-125 Launch COGS | C41: 100000 | D41: $ | E41: 59.9% COGS rate at launch
B42: T-125 Gross Margin | C42: =(C40-C41)/C40 -> 0.4011976 | D42: % | E42: Calculated
B43: T-25 Service Price | C43: 3500 | D43: $/yr | E43: ~10% of unit price
B44: T-125 Service Price | C44: 16700 | D44: $/yr | E44: ~10% of unit price
...

Sheet UNIT ECONOMICS
B1: UNIT ECONOMICS
B2: Per-kg cost build-up using TEA methodology
B4: 1. PRODUCTION COST BUILD-UP ($/kg H₂)
B5: Component | C5: Tobe ($/kg) | D5: Grey H₂ Delivered | E5: Tobe Advantage | F5: Source
B6: Production (Electricity) | C6: =ASSUMPTIONS!C31 -> 1.7768421 | D6: 1.25 | E6: =C6-D6 -> 0.52684211 | F6: TEA §5; NREL ATB 2025
B7: Compression & Purification | C7: =ASSUMPTIONS!C32 -> 0.14 | D7: 0.75 | E7: =D7-C7 -> 0.61 | F7: DOE H2A-Lite
B8: Transportation (50-mile) | C8: =ASSUMPTIONS!C28 -> 0.9 | D8: 8.25 | E8: =D8-C8 -> 7.35 | F8: NREL ATB 2025; Brattle Group Feb 2024
B9: RO Water | C9: =ASSUMPTIONS!C33 -> 0.05004 | D9: 0.05 | E9: =D9-C9 -> -4e-05 | F9: 9 L/kg × $0.00556/L (Tulsa municipal)
B10: TOTAL DIRECT OPEX | C10: =SUM(C6:C9) -> 2.8668821 | D10: 10.3 | E10: =D10-C10 -> 7.4331179
B12: Allocated Facility Labor | C12: 1.389 | F12: $1,250K / 900K kg at nameplate (Year 3+)
B13: Allocated Facility CapEx | C13: =ASSUMPTIONS!C49/ASSUMPTIONS!C53/ASSUMPTIONS!C22 -> 0.40740741 | F13: $3.3M / 9yr / 900K kg
B14: Maintenance & Consumables | C14: =ASSUMPTIONS!C59 -> 0.42 | F14: TEA anchor rate; 3% of CapEx annualized
B15: ALL-IN PRODUCTION COST | C15: =C10+SUM(C12:C14) -> 5.0832895 | D15: 5.25 | F15: NREL ATB 2025 (grey H₂ all-in delivered)
B16: Base Case Sale Price | C16: =ASSUMPTIONS!C15 -> 25
B17: GROSS MARGIN PER KG | C17: =C16-C15 -> 19.91671
B19: 2. THREE EFFICIENCY SCENARIOS (LCOH)
B20: Parameter | C20: Conservative | D20: Base Case | E20: Optimized
B21: SEC (kWh/kg) | C21: =ASSUMPTIONS!C9 -> 42.8 | D21: =ASSUMPTIONS!C8 -> 46.5 | E21: =ASSUMPTIONS!C10 -> 39.6
B22: Electricity ($/kWh) | C22: =ASSUMPTIONS!C5 -> 0.04 | D22: =ASSUMPTIONS!C5 -> 0.04 | E22: =ASSUMPTIONS!C6 -> 0.025
B23: Installed CapEx ($/kW) | C23: 1200 | D23: =ASSUMPTIONS!C55 -> 1000 | E23: 800
B24: Capacity Factor | C24: 75% | D24: 85% | E24: 90%
B25: WACC | C25: 10% | D25: 8% | E25: 6%
B26: LCOH ($/kg) | C26: 3.61 | D26: 2.79 | E26: 2.06
B28: 3. MARGIN AT MULTIPLE PRICE POINTS (Year 3+)
B29: H₂ Price ($/kg) | C29: All-In Cost | D29: Gross Margin $ | E29: Gross Margin %
B30: 15 | C30: =C15 -> 5.0832895 | D30: =B30-C30 -> 9.9167105 | E30: =D30/B30 -> 0.66111403
B31: 20 | C31: =C15 -> 5.0832895 | D31: =B31-C31 -> 14.91671 | E31: =D31/B31 -> 0.74583552
B32: 25 | C32: =C15 -> 5.0832895 | D32: =B32-C32 -> 19.91671 | E32: =D32/B32 -> 0.79666842
B33: 30 | C33: =C15 -> 5.0832895 | D33: =B33-C33 -> 24.91671 | E33: =D33/B33 -> 0.83055702
B34: 47 | C34: =C15 -> 5.0832895 | D34: =B34-C34 -> 41.91671 | E34: =D34/B34 -> 0.8918449
B36: 4. EQUIPMENT UNIT ECONOMICS
B37: Specification | C37: T-25 | D37: T-125
B38: H₂ Capacity | C38: =ASSUMPTIONS!C23&" kg/day" -> 25 kg/day | D38: =ASSUMPTIONS!C24&" kg/day" -> 125 kg/day
B39: Nameplate Power | C39: 50 kW | D39: 250 kW
B40: Sale Price | C40: =ASSUMPTIONS!C37 -> 35000 | D40: =ASSUMPTIONS!C40 -> 167000
B41: Launch COGS | C41: =ASSUMPTIONS!C38 -> 21000 | D41: =ASSUMPTIONS!C41 -> 100000
B42: Gross Margin | C42: =ASSUMPTIONS!C39 -> 0.4 | D42: =ASSUMPTIONS!C42 -> 0.4011976
B44: 5. ON-SITE vs. DELIVERED COMPARISON
B45: Tobe On-Site Production Cost | C45: =C15 -> 5.0832895 | D45: $/kg
B46: Grey H₂ Delivered (50-mile) | C46: 5.25 | D46: $/kg
...

Sheet REVENUE MODEL
B1: REVENUE MODEL
B2: Three-engine revenue: H₂ Production + Equipment Sales + Services
B4: 1. REVENUE BY STREAM ($)
C5: FY1 | D5: FY2 | E5: FY3 | F5: FY4 | G5: FY5 | H5: FY6 | I5: FY7
B6: H₂ Production Revenue | C6: =ASSUMPTIONS!C105*ASSUMPTIONS!$C$15 -> 0 | D6: =ASSUMPTIONS!D105*ASSUMPTIONS!$C$15 -> 11812500 | E6: =ASSUMPTIONS!E105*ASSUMPTIONS!$C$15 -> 77812500 | F6: =ASSUMPTIONS!F105*ASSUMPTIONS!$C$15 -> 141562500 | G6: =ASSUMPTIONS!G105*ASSUMPTIONS!$C$15 -> 210937500 | H6: =ASSUMPTIONS!H105*ASSUMPTIONS!$C$15 -> 264375000 | I6: =ASSUMPTIONS!I105*ASSUMPTIONS!$C$15 -> 270000000
B7: Equipment Sales Revenue | C7: =ASSUMPTIONS!C99*ASSUMPTIONS!$C$37+ASSUMPTIONS!C100*ASSUMPTIONS!$C$40 -> 875000 | D7: =ASSUMPTIONS!D99*ASSUMPTIONS!$C$37+ASSUMPTIONS!D100*ASSUMPTIONS!$C$40 -> 4295000 | E7: =ASSUMPTIONS!E99*ASSUMPTIONS!$C$37+ASSUMPTIONS!E100*ASSUMPTIONS!$C$40 -> 10260000 | F7: =ASSUMPTIONS!F99*ASSUMPTIONS!$C$37+ASSUMPTIONS!F100*ASSUMPTIONS!$C$40 -> 18770000 | G7: =ASSUMPTIONS!G99*ASSUMPTIONS!$C$37+ASSUMPTIONS!G100*ASSUMPTIONS!$C$40 -> 28950000 | H7: =ASSUMPTIONS!H99*ASSUMPTIONS!$C$37+ASSUMPTIONS!H100*ASSUMPTIONS!$C$40 -> 39130000 | I7: =ASSUMPTIONS!I99*ASSUMPTIONS!$C$37+ASSUMPTIONS!I100*ASSUMPTIONS!$C$40 -> 51060000
B8: Equipment Services Revenue | C8: 0 | D8: 32813 | E8: 242113 | F8: 848205 | G8: 2092281 | H8: 4204952 | I8: 6594846
B9: OPERATING REVENUE (ex-PTC) | C9: =C6+C7+C8 -> 875000 | D9: =D6+D7+D8 -> 16140313 | E9: =E6+E7+E8 -> 88314613 | F9: =F6+F7+F8 -> 161180705 | G9: =G6+G7+G8 -> 241979781 | H9: =H6+H7+H8 -> 307709952 | I9: =I6+I7+I8 -> 327654846
B10: 45V PTC (non-operating) | C10: 0 | D10: 1417500 | E10: 8887500 | F10: 10800000 | G10: 10800000 | H10: 10800000 | I10: 10800000
B11: TOTAL REVENUE (incl. PTC) | C11: =C9+C10 -> 875000 | D11: =D9+D10 -> 17557813 | E11: =E9+E10 -> 97202113 | F11: =F9+F10 -> 171980705 | G11: =G9+G10 -> 252779781 | H11: =H9+H10 -> 318509952 | I11: =I9+I10 -> 338454846
B13: Revenue Mix (% of Operating Revenue)
B14: H₂ % | C14: =IF(C9=0,"—",C6/C9) -> 0 | D14: =IF(D9=0,"—",D6/D9) -> 0.73186313 | E14: =IF(E9=0,"—",E6/E9) -> 0.88108295 | F14: =IF(F9=0,"—",F6/F9) -> 0.87828441 | G14: =IF(G9=0,"—",G6/G9) -> 0.87171539 | H14: =IF(H9=0,"—",H6/H9) -> 0.85916948 | I14: =IF(I9=0,"—",I6/I9) -> 0.82403787
B15: Equipment % | C15: =IF(C9=0,"—",C7/C9) -> 1 | D15: =IF(D9=0,"—",D7/D9) -> 0.26610389 | E15: =IF(E9=0,"—",E7/E9) -> 0.11617556 | F15: =IF(F9=0,"—",F7/F9) -> 0.11645314 | G15: =IF(G9=0,"—",G7/G9) -> 0.11963809 | H15: =IF(H9=0,"—",H7/H9) -> 0.12716521 | I15: =IF(I9=0,"—",I7/I9) -> 0.15583472
B16: Services % | C16: =IF(C9=0,"—",C8/C9) -> 0 | D16: =IF(D9=0,"—",D8/D9) -> 0.0020329841 | E16: =IF(E9=0,"—",E8/E9) -> 0.0027414829 | F16: =IF(F9=0,"—",F8/F9) -> 0.0052624475 | G16: =IF(G9=0,"—",G8/G9) -> 0.0086465117 | H16: =IF(H9=0,"—",H8/H9) -> 0.01366531 | I16: =IF(I9=0,"—",I8/I9) -> 0.020127418
B18: 2. CUSTOMER PIPELINE
B19: Customer Code | C19: kg/day | D19: $/kg | E19: Status | F19: Annual Revenue | G19: Sector
B20: CARDINAL | C20: 50 | D20: 30 | E20: Contracted | F20: 547500 | G20: Industrial
B21: REFINERY | C21: 500 | D21: 15 | E21: LOI Signed | F21: 2737500 | G21: Refining
B22: FORGE | C22: 133 | D22: 25 | E22: LOI Signed | F22: 1214125 | G22: Manufacturing
B23: CAMPUS | C23: 32 | D23: 20 | E23: LOI Signed | F23: 233600 | G23: Campus/Institutional
B24: HORIZON | C24: 250 | D24: 25 | E24: LOI Signed | F24: 2281250 | G24: Mobility/Fueling
B25: PHOENIX | C25: 1250 | D25: 25 | E25: LOI Signed | F25: 11406250 | G25: E-Fuels
B26: TRANSIT | C26: 500 | D26: 25 | E26: Proposal | F26: 4562500 | G26: Public Transit
B27: FORGE-STEEL | C27: TBD | D27: 25 | E27: Quoting | F27: — | G27: Steel Mfg ($7-49M)
B29: Pipeline Total: $20M+ signed LOIs, $26M+ active quotes
B32: 3. HaaS vs EQUIPMENT SALES MIX
C33: FY1 | D33: FY2 | E33: FY3 | F33: FY4 | G33: FY5 | H33: FY6 | I33: FY7
B34: H₂ Production (HaaS) | C34: 0 | D34: 0.732 | E34: 0.881 | F34: 0.878 | G34: 0.872 | H34: 0.859 | I34: 0.824
B35: Equipment Sales | C35: 1 | D35: 0.266 | E35: 0.116 | F35: 0.116 | G35: 0.12 | H35: 0.127 | I35: 0.156
B36: Services (Recurring) | C36: 0 | D36: 0.002 | E36: 0.003 | F36: 0.005 | G36: 0.009 | H36: 0.014 | I36: 0.02
B38: Note: Revenue mix shifts from equipment-heavy in FY1 to H₂-production-dominant by FY3+.
B39: Services revenue grows as installed base accumulates (75% attach rate on cumulative equipment sales).

Sheet P&L
B1: INCOME STATEMENT (7-YEAR)
B2: Fiscal Year: April-March. FY1 = Apr 2026 – Mar 2027
C4: FY1 | D4: FY2 | E4: FY3 | F4: FY4 | G4: FY5 | H4: FY6 | I4: FY7
C5: Apr'26-Mar'27 | D5: Apr'27-Mar'28 | E5: Apr'28-Mar'29 | F5: Apr'29-Mar'30 | G5: Apr'30-Mar'31 | H5: Apr'31-Mar'32 | I5: Apr'32-Mar'33
B6: REVENUE
B7: H₂ Production Revenue | C7: =ASSUMPTIONS!C105*ASSUMPTIONS!$C$15 -> 0 | D7: =ASSUMPTIONS!D105*ASSUMPTIONS!$C$15 -> 11812500 | E7: =ASSUMPTIONS!E105*ASSUMPTIONS!$C$15 -> 77812500 | F7: =ASSUMPTIONS!F105*ASSUMPTIONS!$C$15 -> 141562500 | G7: =ASSUMPTIONS!G105*ASSUMPTIONS!$C$15 -> 210937500 | H7: =ASSUMPTIONS!H105*ASSUMPTIONS!$C$15 -> 264375000 | I7: =ASSUMPTIONS!I105*ASSUMPTIONS!$C$15 -> 270000000
B8: Equipment Sales Revenue | C8: =ASSUMPTIONS!C99*ASSUMPTIONS!$C$37+ASSUMPTIONS!C100*ASSUMPTIONS!$C$40 -> 875000 | D8: =ASSUMPTIONS!D99*ASSUMPTIONS!$C$37+ASSUMPTIONS!D100*ASSUMPTIONS!$C$40 -> 4295000 | E8: =ASSUMPTIONS!E99*ASSUMPTIONS!$C$37+ASSUMPTIONS!E100*ASSUMPTIONS!$C$40 -> 10260000 | F8: =ASSUMPTIONS!F99*ASSUMPTIONS!$C$37+ASSUMPTIONS!F100*ASSUMPTIONS!$C$40 -> 18770000 | G8: =ASSUMPTIONS!G99*ASSUMPTIONS!$C$37+ASSUMPTIONS!G100*ASSUMPTIONS!$C$40 -> 28950000 | H8: =ASSUMPTIONS!H99*ASSUMPTIONS!$C$37+ASSUMPTIONS!H100*ASSUMPTIONS!$C$40 -> 39130000 | I8: =ASSUMPTIONS!I99*ASSUMPTIONS!$C$37+ASSUMPTIONS!I100*ASSUMPTIONS!$C$40 -> 51060000
B9: Equipment Services Revenue | C9: =ASSUMPTIONS!C140 -> 0 | D9: =ASSUMPTIONS!D140 -> 32813 | E9: =ASSUMPTIONS!E140 -> 242113 | F9: =ASSUMPTIONS!F140 -> 848205 | G9: =ASSUMPTIONS!G140 -> 2092281 | H9: =ASSUMPTIONS!H140 -> 4204952 | I9: =ASSUMPTIONS!I140 -> 6594846
B10: 45V PTC (non-operating) | C10: =ASSUMPTIONS!C141 -> 0 | D10: =ASSUMPTIONS!D141 -> 1417500 | E10: =ASSUMPTIONS!E141 -> 8887500 | F10: =ASSUMPTIONS!F141 -> 10800000 | G10: =ASSUMPTIONS!G141 -> 10800000 | H10: =ASSUMPTIONS!H141 -> 10800000 | I10: =ASSUMPTIONS!I141 -> 10800000
B11: OPERATING REVENUE (ex-PTC) | C11: =C7+C8+C9 -> 875000 | D11: =D7+D8+D9 -> 16140313 | E11: =E7+E8+E9 -> 88314613 | F11: =F7+F8+F9 -> 161180705 | G11: =G7+G8+G9 -> 241979781 | H11: =H7+H8+H9 -> 307709952 | I11: =I7+I8+I9 -> 327654846
B13: COST OF GOODS SOLD
B14: H₂ Production COGS | C14: =ASSUMPTIONS!C105*ASSUMPTIONS!C134 -> 0 | D14: =ASSUMPTIONS!D105*ASSUMPTIONS!D134 -> 1268662.5 | E14: =ASSUMPTIONS!E105*ASSUMPTIONS!E134 -> 9729675 | F14: =ASSUMPTIONS!F105*ASSUMPTIONS!F134 -> 18935400 | G14: =ASSUMPTIONS!G105*ASSUMPTIONS!G134 -> 28628438 | H14: =ASSUMPTIONS!H105*ASSUMPTIONS!H134 -> 36600075 | I14: =ASSUMPTIONS!I105*ASSUMPTIONS!I134 -> 38275200
B15: Equipment COGS | C15: =ASSUMPTIONS!C99*ASSUMPTIONS!$C$38+ASSUMPTIONS!C100*ASSUMPTIONS!$C$41 -> 525000 | D15: =ASSUMPTIONS!D99*ASSUMPTIONS!$C$38+ASSUMPTIONS!D100*ASSUMPTIONS!$C$41 -> 2575000 | E15: =ASSUMPTIONS!E99*ASSUMPTIONS!$C$38+ASSUMPTIONS!E100*ASSUMPTIONS!$C$41 -> 6150000 | F15: =ASSUMPTIONS!F99*ASSUMPTIONS!$C$38+ASSUMPTIONS!F100*ASSUMPTIONS!$C$41 -> 11250000 | G15: =ASSUMPTIONS!G99*ASSUMPTIONS!$C$38+ASSUMPTIONS!G100*ASSUMPTIONS!$C$41 -> 17350000 | H15: =ASSUMPTIONS!H99*ASSUMPTIONS!$C$38+ASSUMPTIONS!H100*ASSUMPTIONS!$C$41 -> 23450000 | I15: =ASSUMPTIONS!I99*ASSUMPTIONS!$C$38+ASSUMPTIONS!I100*ASSUMPTIONS!$C$41 -> 30600000
B16: Services COGS | C16: =C9*ASSUMPTIONS!$C$45 -> 0 | D16: =D9*ASSUMPTIONS!$C$45 -> 6562.6 | E16: =E9*ASSUMPTIONS!$C$45 -> 48422.6 | F16: =F9*ASSUMPTIONS!$C$45 -> 169641 | G16: =G9*ASSUMPTIONS!$C$45 -> 418456.2 | H16: =H9*ASSUMPTIONS!$C$45 -> 840990.4 | I16: =I9*ASSUMPTIONS!$C$45 -> 1318969.2
B17: TOTAL COGS | C17: =C14+C15+C16 -> 525000 | D17: =D14+D15+D16 -> 3850225.1 | E17: =E14+E15+E16 -> 15928098 | F17: =F14+F15+F16 -> 30355041 | G17: =G14+G15+G16 -> 46396894 | H17: =H14+H15+H16 -> 60891065 | I17: =I14+I15+I16 -> 70194169
B19: GROSS PROFIT | C19: =C11-C17 -> 350000 | D19: =D11-D17 -> 12290088 | E19: =E11-E17 -> 72386515 | F19: =F11-F17 -> 130825664 | G19: =G11-G17 -> 1.9558289e+08 | H19: =H11-H17 -> 2.4681889e+08 | I19: =I11-I17 -> 2.5746068e+08
B20: Gross Margin % | C20: =IF(C11=0,0,C19/C11) -> 0.4 | D20: =IF(D11=0,0,D19/D11) -> 0.76145289 | E20: =IF(E11=0,0,E19/E11) -> 0.81964369 | F20: =IF(F11=0,0,F19/F11) -> 0.81167075 | G20: =IF(G11=0,0,G19/G11) -> 0.80826128 | H20: =IF(H11=0,0,H19/H11) -> 0.80211538 | I20: =IF(I11=0,0,I19/I11) -> 0.78576795
B22: OPERATING EXPENSES
B23: Base Salaries | C23: =ASSUMPTIONS!C142 -> 1263500 | D23: =ASSUMPTIONS!D142 -> 3509147 | E23: =ASSUMPTIONS!E142 -> 7590438 | F23: =ASSUMPTIONS!F142 -> 12122426 | G23: =ASSUMPTIONS!G142 -> 16827031 | H23: =ASSUMPTIONS!H142 -> 19624011 | I23: =ASSUMPTIONS!I142 -> 20817306
B24: Benefits & Payroll Taxes | C24: =C23*ASSUMPTIONS!$C$60 -> 472043.6 | D24: =D23*ASSUMPTIONS!$C$60 -> 1311017.3 | E24: =E23*ASSUMPTIONS!$C$60 -> 2835787.6 | F24: =F23*ASSUMPTIONS!$C$60 -> 4528938.4 | G24: =G23*ASSUMPTIONS!$C$60 -> 6286578.8 | H24: =H23*ASSUMPTIONS!$C$60 -> 7331530.5 | I24: =I23*ASSUMPTIONS!$C$60 -> 7777345.5
B25: HQ & Production Facility Leases | C25: =ASSUMPTIONS!C143 -> 262500 | D25: =ASSUMPTIONS!D143 -> 580663 | E25: =ASSUMPTIONS!E143 -> 848642 | F25: =ASSUMPTIONS!F143 -> 1027354 | G25: =ASSUMPTIONS!G143 -> 1450410 | H25: =ASSUMPTIONS!H143 -> 1758208 | I25: =ASSUMPTIONS!I143 -> 1802164
B26: Professional Fees + Sales & Mktg | C26: =C11*ASSUMPTIONS!$C$61 -> 26250 | D26: =D11*ASSUMPTIONS!$C$61 -> 484209.39 | E26: =E11*ASSUMPTIONS!$C$61 -> 2649438.4 | F26: =F11*ASSUMPTIONS!$C$61 -> 4835421.1 | G26: =G11*ASSUMPTIONS!$C$61 -> 7259393.4 | H26: =H11*ASSUMPTIONS!$C$61 -> 9231298.6 | I26: =I11*ASSUMPTIONS!$C$61 -> 9829645.4
B27: R&D + Other | C27: =ASSUMPTIONS!C144 -> 978904 | D27: =ASSUMPTIONS!D144 -> 2709806 | E27: =ASSUMPTIONS!E144 -> 3916292 | F27: =ASSUMPTIONS!F144 -> 3823614 | G27: =ASSUMPTIONS!G144 -> 5589596 | H27: =ASSUMPTIONS!H144 -> 7154199 | I27: =ASSUMPTIONS!I144 -> 7803097
B28: TOTAL OPERATING EXPENSES | C28: =SUM(C23:C27) -> 3003197.6 | D28: =SUM(D23:D27) -> 8594842.7 | E28: =SUM(E23:E27) -> 17840598 | F28: =SUM(F23:F27) -> 26337754 | G28: =SUM(G23:G27) -> 37413009 | H28: =SUM(H23:H27) -> 45099247 | I28: =SUM(I23:I27) -> 48029558
B29: Headcount (FTEs) | C29: =ASSUMPTIONS!C107 -> 15 | D29: =ASSUMPTIONS!D107 -> 50 | E29: =ASSUMPTIONS!E107 -> 89 | F29: =ASSUMPTIONS!F107 -> 135 | G29: =ASSUMPTIONS!G107 -> 182 | H29: =ASSUMPTIONS!H107 -> 205 | I29: =ASSUMPTIONS!I107 -> 224
B31: EBITDA | C31: =C19-C28 -> -2653197.6 | D31: =D19-D28 -> 3695245.2 | E31: =E19-E28 -> 54545917 | F31: =F19-F28 -> 1.0448791e+08 | G31: =G19-G28 -> 1.5816988e+08 | H31: =H19-H28 -> 2.0171964e+08 | I31: =I19-I28 -> 2.0943112e+08
B32: EBITDA Margin % | C32: =IF(C11=0,0,C31/C11) -> -3.0322258 | D32: =IF(D11=0,0,D31/D11) -> 0.22894508 | E32: =IF(E11=0,0,E31/E11) -> 0.61763185 | F32: =IF(F11=0,0,F31/F11) -> 0.64826563 | G32: =IF(G11=0,0,G31/G11) -> 0.65364915 | H32: =IF(H11=0,0,H31/H11) -> 0.65555124 | I32: =IF(I11=0,0,I31/I11) -> 0.63918212
B34: Depreciation & Amortization | C34: =ASSUMPTIONS!C145 -> 0 | D34: =ASSUMPTIONS!D145 -> -706250 | E34: =ASSUMPTIONS!E145 -> -1581944 | F34: =ASSUMPTIONS!F145 -> -2598611 | G34: =ASSUMPTIONS!G145 -> -4640278 | H34: =ASSUMPTIONS!H145 -> -5986111 | I34: =ASSUMPTIONS!I145 -> -6236111
B35: 45V PTC (in EBIT) | C35: =C10 -> 0 | D35: =D10 -> 1417500 | E35: =E10 -> 8887500 | F35: =F10 -> 10800000 | G35: =G10 -> 10800000 | H35: =H10 -> 10800000 | I35: =I10 -> 10800000
B36: EBIT | C36: =C31+C34+C35 -> -2653197.6 | D36: =D31+D34+D35 -> 4406495.2 | E36: =E31+E34+E35 -> 61851473 | F36: =F31+F34+F35 -> 1.126893e+08 | G36: =G31+G34+G35 -> 1.643296e+08 | H36: =H31+H34+H35 -> 2.0653353e+08 | I36: =I31+I34+I35 -> 2.1399501e+08
B37: Interest Expense | C37: =ASSUMPTIONS!C146 -> -129909 | D37: =ASSUMPTIONS!D146 -> -855453 | E37: =ASSUMPTIONS!E146 -> -906767 | F37: =ASSUMPTIONS!F146 -> -1515309 | G37: =ASSUMPTIONS!G146 -> -2062446 | H37: =ASSUMPTIONS!H146 -> -3737518 | I37: =ASSUMPTIONS!I146 -> -5124500
B38: EBT (Earnings Before Tax) | C38: =C36+C37 -> -2783106.6 | D38: =D36+D37 -> 3551042.2 | E38: =E36+E37 -> 60944706 | F38: =F36+F37 -> 1.1117399e+08 | G38: =G36+G37 -> 1.6226715e+08 | H38: =H36+H37 -> 2.0279601e+08 | I38: =I36+I37 -> 2.0887051e+08
B39: Income Tax (27%) | C39: =IF(C38>0,-C38*ASSUMPTIONS!$C$67,0) -> 0 | D39: =IF(D38>0,-D38*ASSUMPTIONS!$C$67,0) -> -958781.39 | E39: =IF(E38>0,-E38*ASSUMPTIONS!$C$67,0) -> -16455071 | F39: =IF(F38>0,-F38*ASSUMPTIONS!$C$67,0) -> -30016977 | G39: =IF(G38>0,-G38*ASSUMPTIONS!$C$67,0) -> -43812132 | H39: =IF(H38>0,-H38*ASSUMPTIONS!$C$67,0) -> -54754923 | I39: =IF(I38>0,-I38*ASSUMPTIONS!$C$67,0) -> -56395037
B40: NET INCOME | C40: =C38+C39 -> -2783106.6 | D40: =D38+D39 -> 2592260.8 | E40: =E38+E39 -> 44489636 | F40: =F38+F39 -> 81157013 | G40: =G38+G39 -> 1.1845502e+08 | H40: =H38+H39 -> 1.4804109e+08 | I40: =I38+I39 -> 1.5247547e+08
B41: Net Margin % | C41: =IF(C11=0,0,C40/C11) -> -3.1806933 | D41: =IF(D11=0,0,D40/D11) -> 0.16060784 | E41: =IF(E11=0,0,E40/E11) -> 0.50376301 | F41: =IF(F11=0,0,F40/F11) -> 0.50351568 | G41: =IF(G11=0,0,G40/G11) -> 0.48952446 | H41: =IF(H11=0,0,H40/H11) -> 0.48110595 | I41: =IF(I11=0,0,I40/I11) -> 0.46535393
B43: Year-End Cash Balance | C43: =ASSUMPTIONS!C147 -> 1289092 | D43: =ASSUMPTIONS!D147 -> 49613513 | E43: =ASSUMPTIONS!E147 -> 139487718 | F43: =ASSUMPTIONS!F147 -> 224151798 | G43: =ASSUMPTIONS!G147 -> 478384683 | H43: =ASSUMPTIONS!H147 -> 684959946 | I43: =ASSUMPTIONS!I147 -> 832781983
B45: NOTE: FY7 Revenue Reconciliation
B46: v853 Overview showed $467M FY7 which was cumulative H₂+Equip+Svc across all years. The P&L Operating Revenue of $327.7M is the correct annual FY7 figure.

Sheet CASH FLOW
B1: CASH FLOW STATEMENT
B2: Operating, Investing, and Financing Cash Flows
C4: FY1 | D4: FY2 | E4: FY3 | F4: FY4 | G4: FY5 | H4: FY6 | I4: FY7
B5: OPERATING CASH FLOW
B6: Net Income | C6: ='P&L'!C40 -> -2783106.6 | D6: ='P&L'!D40 -> 2592260.8 | E6: ='P&L'!E40 -> 44489636 | F6: ='P&L'!F40 -> 81157013 | G6: ='P&L'!G40 -> 1.1845502e+08 | H6: ='P&L'!H40 -> 1.4804109e+08 | I6: ='P&L'!I40 -> 1.5247547e+08
B7: Add: Depreciation & Amortization | C7: =ABS('P&L'!C34) -> 0 | D7: =ABS('P&L'!D34) -> 706250 | E7: =ABS('P&L'!E34) -> 1581944 | F7: =ABS('P&L'!F34) -> 2598611 | G7: =ABS('P&L'!G34) -> 4640278 | H7: =ABS('P&L'!H34) -> 5986111 | I7: =ABS('P&L'!I34) -> 6236111
B8: Working Capital Changes (ΔAR, ΔAP) | C8: 26346 | D8: -503485 | E8: -2850622 | F8: -2877244 | G8: -3175979 | H8: -2598698 | I8: -793393
B9: NET OPERATING CASH FLOW | C9: =C6+C7+C8 -> -2756760.6 | D9: =D6+D7+D8 -> 2795025.8 | E9: =E6+E7+E8 -> 43220958 | F9: =F6+F7+F8 -> 80878380 | G9: =G6+G7+G8 -> 1.1991932e+08 | H9: =H6+H7+H8 -> 1.514285e+08 | I9: =I6+I7+I8 -> 1.5791819e+08
B11: INVESTING CASH FLOW
B12: Capital Expenditures | C12: -7375000 | D12: -10650000 | E12: -12150000 | F12: -12150000 | G12: -30450000 | H12: -9000000 | I12: 0
B13: NET INVESTING CASH FLOW | C13: =C12 -> -7375000 | D13: =D12 -> -10650000 | E13: =E12 -> -12150000 | F13: =F12 -> -12150000 | G13: =G12 -> -30450000 | H13: =H12 -> -9000000 | I13: =I12 -> 0
B15: FINANCING CASH FLOW
B16: Equity Proceeds | C16: 7500000 | D16: 40000000 | E16: 0 | F16: 60000000 | G16: 0 | H16: 150000000 | I16: 0
B17: Debt / Project Financing (Net) | C17: 2500000 | D17: 14496827 | E17: -3641599 | F17: 20737923 | G17: -6354526 | H17: 49574106 | I17: -15750588
B18: Interest Paid | C18: -129909 | D18: -855453 | E18: -906767 | F18: -1515309 | G18: -2062446 | H18: -3737518 | I18: -5124500
B19: NET FINANCING CASH FLOW | C19: =C16+C17+C18 -> 9870091 | D19: =D16+D17+D18 -> 53641374 | E19: =E16+E17+E18 -> -4548366 | F19: =F16+F17+F18 -> 79222614 | G19: =G16+G17+G18 -> -8416972 | H19: =H16+H17+H18 -> 195836588 | I19: =I16+I17+I18 -> -20875088
B21: CASH WATERFALL
B22: Beginning Cash | C22: 682500 | D22: 1289092 | E22: 49613513 | F22: 139487718 | G22: 224151798 | H22: 478384683 | I22: 684959946
B23: Change in Cash | C23: =C9+C13+C19 -> -261669.6 | D23: =D9+D13+D19 -> 45786400 | E23: =E9+E13+E19 -> 26522592 | F23: =F9+F13+F19 -> 1.4795099e+08 | G23: =G9+G13+G19 -> 81052349 | H23: =H9+H13+H19 -> 3.3826509e+08 | I23: =I9+I13+I19 -> 1.370431e+08
B24: ENDING CASH | C24: =C22+C23 -> 420830.4 | D24: =D22+D23 -> 47075492 | E24: =E22+E23 -> 76136105 | F24: =F22+F23 -> 2.8743871e+08 | G24: =G22+G23 -> 3.0520415e+08 | H24: =H22+H23 -> 8.1664977e+08 | I24: =I22+I23 -> 8.2200305e+08
B26: Cash Runway Note: | C26: Company is self-funding from FY5 onward. Minimum cash: $1.3M (end FY1). Seed close May 2026.
B28: DEBT SCHEDULE
B29: Tranche | C29: Amount | D29: Rate | E29: Term | F29: Draw Date | G29: I/O Period | H29: Monthly Pmt
B30: Seed Debt | C30: 2500000 | D30: 7% | E30: 36 mo | F30: May 2026 | G30: 6 mo | H30: 77193
B31: Series A PF | C31: 17000000 | D31: 7% | E31: 36 mo | F31: Jun 2027 | G31: None | H31: 524909
B32: Series B PF | C32: 30000000 | D32: 7% | E32: 36 mo | F32: Mar 2029 | G32: None | H32: 926310
B33: Series C PF | C33: 75000000 | D33: 7% | E33: 36 mo | F33: Mar 2031 | G33: None | H33: 2315776
B35: Monthly payment factor: 0.030877 per $1 outstanding (7%, 36-month amortization)

Sheet FACILITY RAMP
B1: FACILITY RAMP
B2: Facility-by-facility capacity, economics, and geographic expansion
B4: Facility | C4: Location | D4: Capacity (kg/yr) | E4: CapEx ($) | F4: In-Service | G4: Ramp Tier | H4: Elec Rate ($/kWh) | I4: Direct OpEx ($/kg) | J4: 45V Eligible
B5: F1 — Tulsa (Pilot) | C5: Tulsa, OK | D5: ='FACILITY AFE'!D31 -> 3300000 | E5: 3300000 | F5: Apr 2027 | G5: Tier 1 (24mo) | H5: 0.04 | I5: =(ASSUMPTIONS!$C$7/ASSUMPTIONS!$C$11*H5)+(ASSUMPTIONS!$C$12*H5)+ASSUMPTIONS!$C$28+(ASSUMPTIONS!$C$26*ASSUMPTIONS!$C$27) -> 2.8668821 | J5: YES
B6: F2 — OKC | C6: Oklahoma City, OK | D6: ='FACILITY AFE'!D51 -> 3075000 | E6: 3075000 | F6: Oct 2027 | G6: Tier 2 (18mo) | H6: 0.04 | I6: =(ASSUMPTIONS!$C$7/ASSUMPTIONS!$C$11*H6)+(ASSUMPTIONS!$C$12*H6)+ASSUMPTIONS!$C$28+(ASSUMPTIONS!$C$26*ASSUMPTIONS!$C$27) -> 2.8668821 | J6: YES
B7: F3 — Seattle | C7: Seattle, WA | D7: ='FACILITY AFE'!D51 -> 3075000 | E7: 3075000 | F7: Apr 2028 | G7: Tier 2 (18mo) | H7: 0.0595 | I7: =(ASSUMPTIONS!$C$7/ASSUMPTIONS!$C$11*H7)+(ASSUMPTIONS!$C$12*H7)+ASSUMPTIONS!$C$28+(ASSUMPTIONS!$C$26*ASSUMPTIONS!$C$27) -> 3.8013426 | J7: YES
B8: F4 — Spokane | C8: Spokane, WA | D8: ='FACILITY AFE'!D51 -> 3075000 | E8: 3075000 | F8: Jul 2028 | G8: Tier 2 (18mo) | H8: 0.0413 | I8: =(ASSUMPTIONS!$C$7/ASSUMPTIONS!$C$11*H8)+(ASSUMPTIONS!$C$12*H8)+ASSUMPTIONS!$C$28+(ASSUMPTIONS!$C$26*ASSUMPTIONS!$C$27) -> 2.9291795 | J8: YES
B9: F5 — Albuquerque | C9: Albuquerque, NM | D9: ='FACILITY AFE'!D51 -> 3075000 | E9: 3075000 | F9: Dec 2028 | G9: Tier 3 (15mo) | H9: 0.0587 | I9: =(ASSUMPTIONS!$C$7/ASSUMPTIONS!$C$11*H9)+(ASSUMPTIONS!$C$12*H9)+ASSUMPTIONS!$C$28+(ASSUMPTIONS!$C$26*ASSUMPTIONS!$C$27) -> 3.7630058 | J9: NO
B10: F6 — Des Moines | C10: Des Moines, IA | D10: ='FACILITY AFE'!D51 -> 3075000 | E10: 3075000 | F10: May 2029 | G10: Tier 3 (15mo) | H10: 0.0429 | I10: =(ASSUMPTIONS!$C$7/ASSUMPTIONS!$C$11*H10)+(ASSUMPTIONS!$C$12*H10)+ASSUMPTIONS!$C$28+(ASSUMPTIONS!$C$26*ASSUMPTIONS!$C$27) -> 3.0058532 | J10: NO
B11: F7 | C11: TBD | D11: ='FACILITY AFE'!D51 -> 3075000 | E11: 3075000 | F11: Aug 2029 | G11: Tier 4 (13mo) | H11: 0.0429 | I11: =(ASSUMPTIONS!$C$7/ASSUMPTIONS!$C$11*H11)+(ASSUMPTIONS!$C$12*H11)+ASSUMPTIONS!$C$28+(ASSUMPTIONS!$C$26*ASSUMPTIONS!$C$27) -> 3.0058532 | J11: NO
B12: F8 | C12: TBD | D12: ='FACILITY AFE'!D51 -> 3075000 | E12: 3075000 | F12: Dec 2029 | G12: Tier 4 (13mo) | H12: 0.0429 | I12: =(ASSUMPTIONS!$C$7/ASSUMPTIONS!$C$11*H12)+(ASSUMPTIONS!$C$12*H12)+ASSUMPTIONS!$C$28+(ASSUMPTIONS!$C$26*ASSUMPTIONS!$C$27) -> 3.0058532 | J12: NO
B13: F9 | C13: TBD | D13: ='FACILITY AFE'!D51 -> 3075000 | E13: 3075000 | F13: Apr 2030 | G13: Tier 4 (13mo) | H13: 0.0429 | I13: =(ASSUMPTIONS!$C$7/ASSUMPTIONS!$C$11*H13)+(ASSUMPTIONS!$C$12*H13)+ASSUMPTIONS!$C$28+(ASSUMPTIONS!$C$26*ASSUMPTIONS!$C$27) -> 3.0058532 | J13: NO
B14: F10 | C14: TBD | D14: ='FACILITY AFE'!D51 -> 3075000 | E14: 3075000 | F14: Aug 2030 | G14: Tier 4 (13mo) | H14: 0.0429 | I14: =(ASSUMPTIONS!$C$7/ASSUMPTIONS!$C$11*H14)+(ASSUMPTIONS!$C$12*H14)+ASSUMPTIONS!$C$28+(ASSUMPTIONS!$C$26*ASSUMPTIONS!$C$27) -> 3.0058532 | J14: NO
B15: F11 | C15: TBD | D15: ='FACILITY AFE'!D51 -> 3075000 | E15: 3075000 | F15: Dec 2030 | G15: Tier 4 (13mo) | H15: 0.0429 | I15: =(ASSUMPTIONS!$C$7/ASSUMPTIONS!$C$11*H15)+(ASSUMPTIONS!$C$12*H15)+ASSUMPTIONS!$C$28+(ASSUMPTIONS!$C$26*ASSUMPTIONS!$C$27) -> 3.0058532 | J15: NO
B16: F12 | C16: TBD | D16: ='FACILITY AFE'!D51 -> 3075000 | E16: 3075000 | F16: Apr 2031 | G16: Tier 4 (13mo) | H16: 0.0429 | I16: =(ASSUMPTIONS!$C$7/ASSUMPTIONS!$C$11*H16)+(ASSUMPTIONS!$C$12*H16)+ASSUMPTIONS!$C$28+(ASSUMPTIONS!$C$26*ASSUMPTIONS!$C$27) -> 3.0058532 | J16: NO
B17: TOTAL (12 Facilities) | C17: 10800000 | D17: =SUM(D5:D16) -> 37125000
B19: RAMP TIER DEFINITIONS
B20: Tier | C20: Facilities | D20: Total Duration | E20: Construction | F20: Commissioning | G20: Ramp to 50% | H20: Full Production
B21: Tier 1 — Pilot | C21: F1 (Tulsa) | D21: 24 months | E21: Mo 1-12 | F21: Mo 13-15 (10%) | G21: Mo 16-21 (25%) | H21: Mo 25+ (100%)
B22: Tier 2 — Early | C22: F2-F4 | D22: 18 months | E22: Mo 1-12 | F22: — | G22: Mo 13-18 (50%) | H22: Mo 19+ (100%)
B23: Tier 3 — Mature | C23: F5-F6 | D23: 15 months | E23: Mo 1-10 | F23: — | G23: Mo 11-15 (50%) | H23: Mo 16+ (100%)
B24: Tier 4 — Mastered | C24: F7-F12 | D24: 13 months | E24: Mo 1-8 | F24: — | G24: Mo 9-13 (50%) | H24: Mo 14+ (100%)
B26: CUMULATIVE PRODUCTION CAPACITY (kg/yr)
C27: FY1 | D27: FY2 | E27: FY3 | F27: FY4 | G27: FY5 | H27: FY6 | I27: FY7
B28: Cumulative Nameplate | C28: 0 | D28: 900000 | E28: 3600000 | F28: 3600000 | G28: 5400000 | H28: 9000000 | I28: 10800000
B29: Actual Production | C29: 0 | D29: 472500 | E29: 3112500 | F29: 5662500 | G29: 8437500 | H29: 10575000 | I29: 10800000
B30: Effective Utilization | C30: 0 | D30: =D29/D28 -> 0.525 | E30: =E29/E28 -> 0.86458333 | F30: =F29/F28 -> 1.5729167 | G30: =G29/G28 -> 1.5625 | H30: =H29/H28 -> 1.175 | I30: =I29/I28 -> 1
B32: PER-FACILITY ECONOMICS & PAYBACK
B33: Facility | C33: CapEx ($) | D33: Ann. Revenue at Nameplate | E33: Ann. H₂ COGS | F33: Ann. Gross Profit | G33: Payback (months) | H33: Annual PTC (if eligible)
B34: F1 — Tulsa (Pilot) | C34: 3300000 | D34: =ASSUMPTIONS!$C$22*ASSUMPTIONS!$C$15 -> 22500000 | E34: 4574594 | F34: =D34-E34 -> 17925406 | G34: =C34/(F34/12) -> 2.209155 | H34: =ASSUMPTIONS!$C$22*ASSUMPTIONS!$C$68 -> 2700000
B35: F2 — OKC | C35: 3075000 | D35: =ASSUMPTIONS!$C$22*ASSUMPTIONS!$C$15 -> 22500000 | E35: 4574594 | F35: =D35-E35 -> 17925406 | G35: =C35/(F35/12) -> 2.0585308 | H35: =ASSUMPTIONS!$C$22*ASSUMPTIONS!$C$68 -> 2700000
B36: F3 — Seattle | C36: 3075000 | D36: =ASSUMPTIONS!$C$22*ASSUMPTIONS!$C$15 -> 22500000 | E36: 5415608 | F36: =D36-E36 -> 17084392 | G36: =C36/(F36/12) -> 2.1598662 | H36: =ASSUMPTIONS!$C$22*ASSUMPTIONS!$C$68 -> 2700000
B37: F4 — Spokane | C37: 3075000 | D37: =ASSUMPTIONS!$C$22*ASSUMPTIONS!$C$15 -> 22500000 | E37: 4630662 | F37: =D37-E37 -> 17869338 | G37: =C37/(F37/12) -> 2.0649898 | H37: =ASSUMPTIONS!$C$22*ASSUMPTIONS!$C$68 -> 2700000
B38: F5 — Albuquerque | C38: 3075000 | D38: =ASSUMPTIONS!$C$22*ASSUMPTIONS!$C$15 -> 22500000 | E38: 5381105 | F38: =D38-E38 -> 17118895 | G38: =C38/(F38/12) -> 2.155513 | H38: 0
B39: F6 — Des Moines | C39: 3075000 | D39: =ASSUMPTIONS!$C$22*ASSUMPTIONS!$C$15 -> 22500000 | E39: 4699668 | F39: =D39-E39 -> 17800332 | G39: =C39/(F39/12) -> 2.072995 | H39: 0

Sheet FACILITY AFE
B1: FACILITY AFE (Authorization for Expenditure)
B2: Detailed capital cost breakdown per facility type. Source: v853 Facility AFE tab.
B4: SECTION 1: PILOT / R&D FACILITY (F1 — Tulsa)
B5: Category | C5: Subcategory | D5: Cost (USD) | E5: Notes
B6: Project Dev & Engineering | C6: Permitting & Regulatory | D6: 50000
B7: Equipment & Materials | C7: Electrolyzer System (HVMF 10-20 × 25 kg/day) | D7: 700000
B8: Equipment & Materials | C8: H₂ Compressor (350-700 bar) | D8: 250000
B9: Equipment & Materials | C9: High-Pressure Storage Tanks (cascade) | D9: 300000
B10: Equipment & Materials | C10: H₂ Dispensing System (700 bar) | D10: 150000
B11: Equipment & Materials | C11: Water Purification (RO) | D11: 50000
B12: Equipment & Materials | C12: Safety Systems (leak detection, ESD) | D12: 30000
B13: Equipment & Materials | C13: Balance of Plant (piping, valves) | D13: 50000
B14: Equipment & Materials | C14: Truck Load Out Stanchions | D14: 50000
B15: Manufacturing Equipment | C15: 5-Axis CNC Machine | D15: 140000
B16: Manufacturing Equipment | C16: CNC Transformer Winder | D16: 90000
B17: Manufacturing Equipment | C17: 3D Printer (Industrial) | D17: 30000
... B30: Contingency | C30: ~15% of direct costs | D30: 460000
B31: TOTAL — PILOT FACILITY | D31: =SUM(D6:D30) -> 3300000 | E31: Source: v853 Facility AFE
B33: SECTION 2: ADDITIONAL FACILITY (F2-F12)
B34: Category | C34: Subcategory | D34: Cost (USD) | E34: Notes
B35: Equipment & Materials | C35: Electrolyzer System (10× T-125) | D35: 1500000
B36: Equipment & Materials | C36: H₂ Compressor | D36: 400000
B37: Equipment & Materials | C37: High-Pressure Storage Tanks | D37: 300000
B38: Equipment & Materials | C38: H₂ Dispensing System | D38: 150000
B39: Equipment & Materials | C39: Water Purification | D39: 75000
B40: Equipment & Materials | C40: Safety Systems | D40: 50000
B41: Equipment & Materials | C41: Balance of Plant (piping, valves) | D41: 75000
B42: Equipment & Materials | C42: Truck Load Out Stanchions | D42: 50000
B43: Cost Savings | C43: Modularization & Skid Savings | D43: -300000
B44: Supporting | C44: Tools/Fixtures/Testing/CAD | D44: 130000
B45: R&D | C45: R&D Materials | D45: 35000
B46: Construction & Installation | C46: Mechanical Installation | D46: 150000
... B50: Contingency | C50: ~5% of direct costs | D50: 150000
B51: TOTAL — ADDITIONAL FACILITY | D51: =SUM(D35:D50) -> 3075000 | E51: Source: v853 Facility AFE. Includes modularization savings.
B52: SECTION 3: COST SUMMARY
C53: Description | D53: Cost (USD)
B54: Pilot Facility (F1 — Tulsa) | C54: Includes mfg equipment + R&D | D54: =D31 -> 3300000
B55: Each Additional Facility (F2-F12) | C55: Production-only, 11 facilities | D55: =D51 -> 3075000
B56: Total CapEx for 12 Facilities | D56: =D54+11*D55 -> 37125000
B57: Average CapEx per Facility | D57: =D56/12 -> 3093750
...

Sheet 45V TAX CREDIT
B1: 45V PRODUCTION TAX CREDIT
B2: Tier 1 qualification: 0.03 kgCO₂e/kg H₂ (< 0.45 threshold)
B4: 45V PTC PARAMETERS
B5: PTC Rate | C5: =ASSUMPTIONS!C68 -> 3 | D5: $/kg H₂
B6: Credit Period | C6: =ASSUMPTIONS!C69 -> 10 | D6: years
B7: CO₂ Intensity (Tobe) | C7: =ASSUMPTIONS!C70 -> 0.03 | D7: kgCO₂e/kg
B8: Tier 1 Threshold | C8: =ASSUMPTIONS!C71 -> 0.45 | D8: kgCO₂e/kg
B9: Construction Deadline | C9: Dec 31, 2027
B10: Eligible Facilities | C10: 4 of 12 | D10: (F1-F4)
B12: PTC REVENUE BY YEAR
C13: FY1 | D13: FY2 | E13: FY3 | F13: FY4 | G13: FY5 | H13: FY6 | I13: FY7
B14: Eligible H₂ Production (kg) | C14: 0 | D14: 472500 | E14: 2962500 | F14: 3600000 | G14: 3600000 | H14: 3600000 | I14: 3600000
B15: 45V PTC Revenue | C15: =C14*ASSUMPTIONS!$C$68*ASSUMPTIONS!$C$72 -> 0 | D15: =D14*ASSUMPTIONS!$C$68*ASSUMPTIONS!$C$72 -> 1417500 | E15: =E14*ASSUMPTIONS!$C$68*ASSUMPTIONS!$C$72 -> 8887500 | F15: =F14*ASSUMPTIONS!$C$68*ASSUMPTIONS!$C$72 -> 10800000 | G15: =G14*ASSUMPTIONS!$C$68*ASSUMPTIONS!$C$72 -> 10800000 | H15: =H14*ASSUMPTIONS!$C$68*ASSUMPTIONS!$C$72 -> 10800000 | I15: =I14*ASSUMPTIONS!$C$68*ASSUMPTIONS!$C$72 -> 10800000
B16: Cumulative PTC Cash | C16: 0 | D16: =C16+D15 -> 1417500 | E16: =D16+E15 -> 10305000 | F16: =E16+F15 -> 21105000 | G16: =F16+G15 -> 31905000 | H16: =G16+H15 -> 42705000 | I16: =H16+I15 -> 53505000
B18: VALUE PER ELIGIBLE FACILITY
B19: Annual PTC per Facility at Nameplate | C19: =ASSUMPTIONS!C22*ASSUMPTIONS!C68 -> 2700000
B20: 10-Year PTC per Facility | C20: =ASSUMPTIONS!C22*ASSUMPTIONS!C68*ASSUMPTIONS!C69 -> 27000000 | D20: $27M per facility
B22: EBITDA: WITH vs. WITHOUT 45V
C23: FY1 | D23: FY2 | E23: FY3 | F23: FY4 | G23: FY5 | H23: FY6 | I23: FY7
B24: EBITDA WITH 45V | C24: -2678101 | D24: 3758053 | E24: 54903453 | F24: 105592088 | G24: 160712947 | H24: 206075087 | I24: 215995112
B25: EBITDA WITHOUT 45V | C25: -2678101 | D25: 2340553 | E25: 46015953 | F25: 94792088 | G25: 149912947 | H25: 195275087 | I25: 205195112
B26: PTC Impact | C26: =C24-C25 -> 0 | D26: =D24-D25 -> 1417500 | E26: =E24-E25 -> 8887500 | F26: =F24-F25 -> 10800000 | G26: =G24-G25 -> 10800000 | H26: =H24-H25 -> 10800000 | I26: =I24-I25 -> 10800000
B28: KEY: Model works profitably WITHOUT 45V credits.
B29: EBITDA positive from Year 2 in both scenarios. 45V is upside, not dependency.

Sheet MARKET & TAM
B1: MARKET & TAM
B2: Market sizing validated by University of Oklahoma Irani Center
B4: GLOBAL MARKET
B5: Global Hydrogen Market | C5: 94M tonnes/yr | D5: $226B
B6: Global Green H₂ (current) | C6: <1% of total
B7: Green H₂ by 2030 (projected) | C7: 30% of total
B9: U.S. SERVICEABLE MARKET — $9.81B (OU Validated)
B10: Segment | C10: Market Value | D10: % Share | E10: # Customers | F10: Sales Model
B11: Industrial Decarbonization | C11: 3465000000 | D11: 0.35 | E11: 3000 | F11: Equipment Sales
B12: Heavy-Duty Fueling (Truck Stops) | C12: 1980000000 | D12: 0.2 | E12: 6320 | F12: Equipment Sales
B13: Chemical Production & Synth Fuels | C13: 990000000 | D13: 0.1 | E13: 50 | F13: Equipment Sales
B14: Energy Storage / Grid Balancing | C14: 990000000 | D14: 0.1 | E14: 79 | F14: HaaS
B15: Urban Fleet Fueling (Buses, Ports) | C15: 495000000 | D15: 0.05 | E15: 6000 | F15: Variable
B16: Light & Medium-Duty Commercial | C16: 495000000 | D16: 0.05 | E16: 5000 | F16: HaaS
B17: Backup Power & Microgrids | C17: 495000000 | D17: 0.05 | E17: 11500 | F17: HaaS
B18: Already Green (Undercut Incumbent) | C18: 900000000 | D18: 0.1 | E18: 76 | F18: Variable
B19: TOTAL SERVICEABLE MARKET | C19: =SUM(C11:C18) -> 9810000000 | E19: =SUM(E11:E18) -> 32025
B21: 150-MILE TRANSPORTATION THRESHOLD
B22: < 50 miles (Tube Trailer) | C22: $0.90/kg | D22: 70% of addressable | E22: Tobe core market
B23: 50-150 miles (Tube Trailer) | C23: $1.90/kg | D23: 20% of addressable | E23: Tobe serviceable
B24: 150+ miles (Liquid Tanker) | C24: $2.70-3.20/kg | D24: 10% of addressable | E24: Uneconomic for delivery
B25: Pipeline (where available) | C25: $0.20-0.50/kg | D25: ~1,600 mi in U.S. | E25: Only TX, CA, IL corridors
B27: ON-SITE vs. DELIVERED COST
B28: Tobe On-Site Production | C28: ~$4.83/kg
B29: Grey H₂ Delivered (50-300+ miles) | C29: $5-50+/kg
B30: Airgas Cylinder (Sept 2024) | C30: $121.31/kg
B32: SAM/SOM PENETRATION
B33: FY7 Revenue as % of SAM | C33: ='P&L'!I11/C19 -> 0.033400086 | D33: ← FY7 Operating Revenue / $9.81B SAM
B34: FY5 Revenue as % of SAM | C34: ='P&L'!G11/C19 -> 0.024666644

Sheet COMPETITIVE LANDSCAPE
B1: COMPETITIVE LANDSCAPE
B2: Technology and cost comparison vs. electrolysis peers
B4: Company | C4: Technology | D4: SEC (kWh/kg) | E4: CAPEX ($/kW) | F4: Funding | G4: Status | H4: Key Difference
B5: TOBE ENERGY | C5: Membrane-Free | D5: 42.2 (stack) | E5: $1,000 installed | F5: $10M Seed | G5: Pre-revenue | H5: No membrane, no rare earth, 92% eff.
B6: Nel Hydrogen | C6: PEM / Alkaline | D6: 50-56 | E6: $800-1,350 equip | F6: $800M+ | G6: Production | H6: 20+ yr history; $150M revenue
B7: ITM Power | C7: PEM | D7: 50-58 | E7: $1,400-2,500 | F7: $400M+ | G7: Production | H7: UK-based; modular PEM stacks
B8: Plug Power | C8: PEM | D8: 52-58 | E8: $1,500-2,500 | F8: $5B+ | G8: Production | H8: Vertically integrated; DOE loan
B9: Bloom Energy | C9: SOFC/SOEC | D9: 39-45 (SOEC) | E9: $1,200-2,000 | F9: $4B+ | G9: Production | H9: Solid oxide; high-temp operation
B10: Electric Hydrogen | C10: PEM | D10: 48-55 | E10: N/A | F10: $600M+ | G10: Pre-revenue | H10: Large-scale PEM; Series C
B11: Enapter | C11: AEM | D11: 53-60 | E11: $1,000-1,800 | F11: $200M+ | G11: Early revenue | H11: Anion exchange membrane
B12: Advanced Ionics | C12: SOEC | D12: 35-40 (SOEC) | E12: N/A | F12: $30M+ | G12: Pre-revenue | H12: Steam electrolysis
B15: PRODUCTION COST COMPARISON (TEA Table 36)
B16: Technology | C16: SEC (kWh/kg) | D16: Installed ($/kW) | E16: LCOH ($/kg)
B17: PEM Electrolysis | C17: 50-58 | D17: $1,400-2,500 | E17: $4.40-7.90
B18: Alkaline Electrolysis | C18: 51-56 | D18: $500-1,000 | E18: $4.00-6.00
B19: Grey H₂ (SMR) | C19: N/A | D19: — | E19: $1.00-2.00
B20: Tobe (Base Case) | C20: 46.5 | D20: $1,000 | E20: $2.79
B21: Tobe (Upside) | C21: 42.0 | D21: $800 | E21: $2.06
B24: TOBE DIFFERENTIATION SUMMARY
B25: • No membrane — eliminates Nafion ($500-800/m²) degradation and replacement cycle
B26: • No rare earth catalysts — no iridium ($1,000-3,000/kW) or platinum dependency
B27: • No cooling system — operates at 27-28°C near ambient (no chillers, no thermal management)
B28: • TDS tolerance: 25-10,000+ ppm — standard RO instead of expensive deionization
B29: • Wall-to-plug efficiency: 70-72% LHV (vs. PEM 57-67% LHV)
B30: • Stack SEC: 42.2 kWh/kg validated from 22,103 data points

Sheet CAP TABLE
B1: CAP TABLE
B2: Pre-Seed and Post-Seed Ownership Structure
B4: SEED ROUND TERMS
B5: Pre-Money Valuation | C5: =ASSUMPTIONS!C78 -> 40000000
B6: Equity Investment | C6: =ASSUMPTIONS!C75 -> 7500000
B7: Post-Money Valuation | C7: =ASSUMPTIONS!C79 -> 47500000
B8: New Shares (Seed) | C8: =ASSUMPTIONS!C80 -> 0.15789474
B9: Debt (Non-Dilutive) | C9: =ASSUMPTIONS!C76 -> 2500000
B10: Total Round Size | C10: =ASSUMPTIONS!C77 -> 10000000
B12: POST-SEED PRO FORMA
B13: Shareholder | C13: Pre-Seed % | D13: Post-Seed % | E13: Value at $47.5M
B14: Founders | C14: 0.65 | D14: =C14*(1-ASSUMPTIONS!C80) -> 0.54736842 | E14: =D14*ASSUMPTIONS!C79 -> 26000000
B15: Pre-Seed Investors | C15: 0.148 | D15: =C15*(1-ASSUMPTIONS!C80) -> 0.12463158 | E15: =D15*ASSUMPTIONS!C79 -> 5920000
B16: Employee Option Pool | C16: 0.1 | D16: =C16*(1-ASSUMPTIONS!C80) -> 0.084210526 | E16: =D16*ASSUMPTIONS!C79 -> 4000000
B17: Advisors | C17: 0.022 | D17: =C17*(1-ASSUMPTIONS!C80) -> 0.018526316 | E17: =D17*ASSUMPTIONS!C79 -> 880000
B18: Techstars | C18: 0.06 | D18: =C18*(1-ASSUMPTIONS!C80) -> 0.050526316 | E18: =D18*ASSUMPTIONS!C79 -> 2400000
B19: Other | C19: 0.02 | D19: =C19*(1-ASSUMPTIONS!C80) -> 0.016842105 | E19: =D19*ASSUMPTIONS!C79 -> 800000
B20: Seed Investors (New) | C20: 0 | D20: =ASSUMPTIONS!C80 -> 0.15789474 | E20: =ASSUMPTIONS!C75 -> 7500000
B21: TOTAL | C21: =SUM(C14:C20) -> 1 | D21: =SUM(D14:D20) -> 1 | E21: =SUM(E14:E20) -> 47500000
B23: SEED INVESTOR OWNERSHIP THROUGH ROUNDS
B24: Round | C24: Dilution | D24: Seed % After
B25: Post-Seed | C25: 15.8% | D25: 15.8%
B26: Post-Series A | C26: 16.0% | D26: 13.3%
B27: Post-Series B | C27: 10.7% | D27: 11.9%
B28: Post-Series C | C28: 9.1% | D28: 10.8%
B30: SEED INVESTOR RETURN ANALYSIS
B31: Scenario | C31: EV ($B) | D31: Seed Value | E31: Seed ROI
B32: Bear (8x Revenue) | C32: 2620000000 | D32: =C32*0.108 -> 282960000 | E32: =D32/ASSUMPTIONS!C77 -> 28.296
B33: Base (10x Revenue) | C33: 3280000000 | D33: =C33*0.108 -> 354240000 | E33: =D33/ASSUMPTIONS!C77 -> 35.424
B34: Bull (12x Revenue) | C34: 3930000000 | D34: =C34*0.108 -> 424440000 | E34: =D34/ASSUMPTIONS!C77 -> 42.444
B35: Base (20x EBITDA) | C35: 4320000000 | D35: =C35*0.108 -> 466560000 | E35: =D35/ASSUMPTIONS!C77 -> 46.656
B37: Note: Ownership % assumes standard pro-rata dilution through Series A, B, C rounds.

Sheet SOURCES & NOTES
B1: SOURCES & NOTES
B3: SOURCE CITATIONS
B4: Final_Tobe_TEA.docx | C4: PRIMARY — Techno-Economic Analysis v3.0, March 2026. LCOH methodology, cost build-ups, efficiency data, competitive benchmarks.
B5: FINAL_Tobe_Seed_Financial_Model_v853.xlsx | C5: PRIMARY — Financial model v8.5.3. 84-month P&L engine, facility ramp, fundraising, equipment sales, debt schedule.
B6: Clean_FinancialModel_Tobe_Seed.xlsx | C6: HIGH — Cleaned v8.5.3 model. Confirmed identical to v853 after T-2500 removal.
B7: OU_TOBE financial model.xlsx | C7: HIGH — University of Oklahoma Irani Center model. $9.81B SAM, 8 segments, 5-year projections, $657M profit.
B8: OU_Tobe Energy Final Report.docx | C8: HIGH — OU case study. Market sizing, competitive analysis, go-to-market, expert interviews (Nel VP, Enterprise Products, Love's).
B9: Tobe_Energy_TEA_Editorial_Companion_March_2026.docx | C9: MEDIUM — Founder's narrative companion. Red-flag review, softened claims, data-room priorities.
B10: Tobe_Energy_Model_Review_v852.docx | C10: MEDIUM — External model review. 10-dimension diligence, investor scrutiny points, priority fixes.
B11: FIN_FinancialModel.xlsx | C11: REFERENCE — Pre-seed era model (May 2025). Baseline for assumption evolution.
B13: METHODOLOGY NOTES
B14: • LCOH calculated using CRF method per Agora Energiewende / European Hydrogen Observatory methodology.
B15: • CRF = r(1+r)^n / ((1+r)^n - 1); Base case: WACC=8%, n=20 years, CRF=0.1019.
B16: • LCOH boundary: electrolyzer outlet per Agora best practice. Compression, transport costs added separately.
B17: • All efficiency figures are LHV basis unless explicitly noted as HHV.
B18: • System SEC includes BOP parasitic load (~4 kWh/kg above stack SEC).
B19: • Stack SEC validated from 22,103 data points at 5-second intervals (6 kW and 15 kW prototypes, Navy SBIR N242-070).
B20: • Fiscal year: April-March. FY1 = Apr 2026 – Mar 2027.
B21: • Tax rate: 27% (Federal 21% + Oklahoma state ~6%).
B22: • 45V PTC: $3/kg for Tier 1 (< 0.45 kgCO₂e/kg). Tobe qualifies at 0.03 kgCO₂e/kg.
B23: • Equipment learning curve: Wright's Law at ~85% (15% cost reduction per doubling of cumulative production).
B24: • Revenue recognition: H₂ sales at delivery, equipment at acceptance, services over contract period.
... B28: GLOSSARY
B29: ASP | C29: Average Selling Price
B30: BOP | C30: Balance of Plant — auxiliary systems (pumps, controls, power electronics)
B31: CF | C31: Capacity Factor — actual vs. nameplate production
B32: CRF | C32: Capital Recovery Factor — annualization of CapEx
B33: FLH | C33: Full Load Hours — annual operating hours at nameplate
B34: HaaS | C34: Hydrogen as a Service — recurring revenue model
B35: HHV | C35: Higher Heating Value of hydrogen — 39.4 kWh/kg
B36: LCOH | C36: Levelized Cost of Hydrogen — $/kg over asset life
B37: LHV | C37: Lower Heating Value of hydrogen — 33.3 kWh/kg
B38: LLC | C38: Low-Loss Converter — optimized power electronics
B39: PEM | C39: Proton Exchange Membrane (electrolysis technology)
B40: PPA | C40: Power Purchase Agreement — long-term electricity contract
... B46: WACC | C46: Weighted Average Cost of Capital
B48: DISCLAIMERS
B49: This financial model is based on management projections and contains forward-looking statements.
B50: Actual results may differ materially from projections due to market conditions, technology risks, and execution factors.
B51: This model does not constitute an offer to sell or solicitation of an offer to buy securities.
...

Sheet SENSITIVITY
B1: SENSITIVITY ANALYSIS
B2: Scenario analysis, LCOH sensitivity, and investment return calculations
B4: 1. LCOH SENSITIVITY — ELECTRICITY PRICE
B5: Electricity ($/kWh) | C5: LCOH ($/kg) | D5: vs Base Case | E5: Gross Margin at $25/kg
B6: 0.025 | C6: 4.36 | D6: -0.72 | E6: 0.825
B7: 0.03 | C7: 4.6 | D7: -0.48 | E7: 0.816
B8: 0.035 | C8: 4.84 | D8: -0.24 | E8: 0.806
B9: 0.04 | C9: 5.08 | D9: 0 | E9: 0.797
B10: 0.045 | C10: 5.32 | D10: 0.24 | E10: 0.787
B11: 0.05 | C11: 5.56 | D11: 0.48 | E11: 0.777
B12: 0.055 | C12: 5.8 | D12: 0.72 | E12: 0.768
B14: 2. LCOH BY EFFICIENCY SCENARIO
B15: Scenario | C15: SEC (kWh/kg) | D15: Electricity | E15: LCOH ($/kg) | F15: vs PEM ($4-7/kg)
B16: Conservative | C16: =ASSUMPTIONS!C9 -> 42.8 | D16: 0.045 | E16: 5.35 | F16: ="$"&TEXT(4-E16,"0.00")&" - $"&TEXT(7-E16,"0.00")&" below PEM" -> $-1.35 - $1.65 below PEM
B17: Base Case | C17: =ASSUMPTIONS!C8 -> 46.5 | D17: =ASSUMPTIONS!C5 -> 0.04 | E17: 5.26 | F17: ="$"&TEXT(4-E17,"0.00")&" - $"&TEXT(7-E17,"0.00")&" below PEM" -> $-1.26 - $1.74 below PEM
B18: Optimized | C18: =ASSUMPTIONS!C10 -> 39.6 | D18: =ASSUMPTIONS!C6 -> 0.025 | E18: 4.75 | F18: ="$"&TEXT(4-E18,"0.00")&" - $"&TEXT(7-E18,"0.00")&" below PEM" -> $-0.75 - $2.25 below PEM
B21: 3. H₂ PRICE × FACILITY COUNT — FY5 REVENUE ($M)
B22: H₂ Price ↓ / Fac → | C22: 3 | D22: 5 | E22: 7 (Base) | F22: 10 | G22: 12
B23: $15/kg | C23: =(3*ASSUMPTIONS!$C$22*15+29000000*3/7)/1000000 -> 52.928571 | D23: =(5*ASSUMPTIONS!$C$22*15+29000000*5/7)/1000000 -> 88.214286 | E23: =(7*ASSUMPTIONS!$C$22*15+29000000*7/7)/1000000 -> 123.5 | F23: =(10*ASSUMPTIONS!$C$22*15+29000000*10/7)/1000000 -> 176.42857 | G23: =(12*ASSUMPTIONS!$C$22*15+29000000*12/7)/1000000 -> 211.71429
B24: $20/kg | C24: =(3*ASSUMPTIONS!$C$22*20+29000000*3/7)/1000000 -> 66.428571 | D24: =(5*ASSUMPTIONS!$C$22*20+29000000*5/7)/1000000 -> 110.71429 | E24: =(7*ASSUMPTIONS!$C$22*20+29000000*7/7)/1000000 -> 155 | F24: =(10*ASSUMPTIONS!$C$22*20+29000000*10/7)/1000000 -> 221.42857 | G24: =(12*ASSUMPTIONS!$C$22*20+29000000*12/7)/1000000 -> 265.71429
B25: $25/kg (Base) | C25: =(3*ASSUMPTIONS!$C$22*25+29000000*3/7)/1000000 -> 79.928571 | D25: =(5*ASSUMPTIONS!$C$22*25+29000000*5/7)/1000000 -> 133.21429 | E25: =(7*ASSUMPTIONS!$C$22*25+29000000*7/7)/1000000 -> 186.5 | F25: =(10*ASSUMPTIONS!$C$22*25+29000000*10/7)/1000000 -> 266.42857 | G25: =(12*ASSUMPTIONS!$C$22*25+29000000*12/7)/1000000 -> 319.71429
B26: $30/kg | C26: =(3*ASSUMPTIONS!$C$22*30+29000000*3/7)/1000000 -> 93.428571 | D26: =(5*ASSUMPTIONS!$C$22*30+29000000*5/7)/1000000 -> 155.71429 | E26: =(7*ASSUMPTIONS!$C$22*30+29000000*7/7)/1000000 -> 218 | F26: =(10*ASSUMPTIONS!$C$22*30+29000000*10/7)/1000000 -> 311.42857 | G26: =(12*ASSUMPTIONS!$C$22*30+29000000*12/7)/1000000 -> 373.71429
B27: $35/kg | C27: =(3*ASSUMPTIONS!$C$22*35+29000000*3/7)/1000000 -> 106.92857 | D27: =(5*ASSUMPTIONS!$C$22*35+29000000*5/7)/1000000 -> 178.21429 | E27: =(7*ASSUMPTIONS!$C$22*35+29000000*7/7)/1000000 -> 249.5 | F27: =(10*ASSUMPTIONS!$C$22*35+29000000*10/7)/1000000 -> 356.42857 | G27: =(12*ASSUMPTIONS!$C$22*35+29000000*12/7)/1000000 -> 427.71429
B30: 4. SCENARIO OUTCOMES (FY7)
B31: Metric | C31: Bear | D31: Base | E31: Bull
B32: H₂ Price ($/kg) | C32: 15 | D32: =ASSUMPTIONS!C15 -> 25 | E32: 35
B33: Facilities | C33: 6 | D33: 12 | E33: 12
B34: 45V PTC | C34: None | D34: 4 facilities | E34: 4 facilities
B36: Revenue ($M) | C36: =(C33*ASSUMPTIONS!$C$22*C32+51060000*C33/12)/1000000 -> 106.53 | D36: ='P&L'!I11/1000000 -> 327.65485 | E36: =(E33*ASSUMPTIONS!$C$22*E32+51060000*E33/12)/1000000 -> 429.06
B37: EBITDA ($M) | C37: =C36*0.37 -> 39.4161 | D37: ='P&L'!I31/1000000 -> 209.43112 | E37: =E36*0.71 -> 304.6326
B38: EBITDA Margin | C38: =C37/C36 -> 0.37 | D38: =D37/D36 -> 0.63918212 | E38: =E37/E36 -> 0.71
B39: Net Income ($M) | C39: =C36*0.2 -> 21.306 | D39: ='P&L'!I40/1000000 -> 152.47547 | E39: =E36*0.52 -> 223.1112
B41: 5. EXIT VALUATION (FY7)
B42: Basis | C42: Multiple | D42: EV ($M) | E42: Seed Value ($M) | F42: Seed ROI
B43: Revenue (Bear) | C43: 8x | D43: 2621 | E43: 283 | F43: 28.3
B44: Revenue (Base) | C44: 10x | D44: 3277 | E44: 354 | F44: 35.4
B45: Revenue (Bull) | C45: 12x | D45: 3932 | E45: 425 | F45: 42.5
B46: EBITDA (Bear) | C46: 15x | D46: 3141 | E46: 339 | F46: 33.9
B47: EBITDA (Base) | C47: 20x | D47: 4189 | E47: 452 | F47: 45.2
B48: EBITDA (Bull) | C48: 25x | D48: 5236 | E48: 565 | F48: 56.5
...
