Workbook

Sheet Overview
C4: Financial Model
C7: https://tobe.energy
C10: Table of Contents
C12: Model Assumptions
C13: Financials
C14: Project Overview
C15: H2 Cost Assumptions
C16: H2 Production Costs
C17: Personnel
C18: Volumes at Electric Loads
C19: Facility AFE
C20: Additional Engineering Detail

Sheet Model Assumptions
B1: Year Counter | G1: 1 | H1: 1 | I1: 1 | J1: 1 | K1: 1 | L1: 1 | M1: 1 | N1: 1 | O1: 1 | P1: 1 | Q1: 1 | R1: 1 | S1: 2 | T1: 2 | U1: 2 | V1: 2 | W1: 2 | X1: 2 | Y1: 2 | Z1: 2 | AA1: 2 | AB1: 2 | AC1: 2 | AD1: 2 | AE1: 3 | AF1: 3 | AG1: 3 | AH1: 3 | AI1: 3 | AJ1: 3 | AK1: 3 | AL1: 3 | AM1: 3 | AN1: 3 | AO1: 3 | AP1: 3 | AQ1: 4 | AR1: 4 | AS1: 4 | AT1: 4 | AU1: 4 | AV1: 4 | AW1: 4 | AX1: 4 | AY1: 4 | AZ1: 4 | BA1: 4 | BB1: 4 | BC1: 5 | BD1: 5 | BE1: 5 | BF1: 5 | BG1: 5 | BH1: 5 | BI1: 5 | BJ1: 5 | BK1: 5 | BL1: 5 | BM1: 5 | BN1: 5 | BO1: 6 | BP1: 6 | BQ1: 6 | BR1: 6 | BS1: 6 | BT1: 6 | BU1: 6 | BV1: 6 | BW1: 6 | BX1: 6 | BY1: 6 | BZ1: 6 | CA1: 7 | CB1: 7 | CC1: 7 | CD1: 7 | CE1: 7 | CF1: 7 | CG1: 7 | CH1: 7 | CI1: 7 | CJ1: 7 | CK1: 7 | CL1: 7
B2: Year | G2: 2025 | H2: 2025 | I2: 2025 | J2: 2025 | K2: 2025 | L2: 2025 | M2: 2026 | N2: 2026 | O2: 2026 | P2: 2026 | Q2: 2026 | R2: 2026 | S2: 2026 | T2: 2026 | U2: 2026 | V2: 2026 | W2: 2026 | X2: 2026 | Y2: 2027 | Z2: 2027 | AA2: 2027 | AB2: 2027 | AC2: 2027 | AD2: 2027 | AE2: 2027 | AF2: 2027 | AG2: 2027 | AH2: 2027 | AI2: 2027 | AJ2: 2027 | AK2: 2028 | AL2: 2028 | AM2: 2028 | AN2: 2028 | AO2: 2028 | AP2: 2028 | AQ2: 2028 | AR2: 2028 | AS2: 2028 | AT2: 2028 | AU2: 2028 | AV2: 2028 | AW2: 2029 | AX2: 2029 | AY2: 2029 | AZ2: 2029 | BA2: 2029 | BB2: 2029 | BC2: 2029 | BD2: 2029 | BE2: 2029 | BF2: 2029 | BG2: 2029 | BH2: 2029 | BI2: 2030 | BJ2: 2030 | BK2: 2030 | BL2: 2030 | BM2: 2030 | BN2: 2030 | BO2: 2030 | BP2: 2030 | BQ2: 2030 | BR2: 2030 | BS2: 2030 | BT2: 2030 | BU2: 2031 | BV2: 2031 | BW2: 2031 | BX2: 2031 | BY2: 2031 | BZ2: 2031 | CA2: =2024+CA1 -> 2031 | CB2: =2024+CB1 -> 2031 | CC2: =2024+CC1 -> 2031 | CD2: =2024+CD1 -> 2031 | CE2: =2024+CE1 -> 2031 | CF2: =2024+CF1 -> 2031 | CG2: 2032 | CH2: 2032 | CI2: 2032 | CJ2: 2032 | CK2: 2032 | CL2: 2032
B3: Month Counter | G3: 1 | H3: 2 | I3: 3 | J3: 4 | K3: 5 | L3: 6 | M3: 7 | N3: 8 | O3: 9 | P3: 10 | Q3: 11 | R3: 12 | S3: 13 | T3: 14 | U3: 15 | V3: 16 | W3: 17 | X3: 18 | Y3: 19 | Z3: 20 | AA3: 21 | AB3: 22 | AC3: 23 | AD3: 24 | AE3: 25 | AF3: 26 | AG3: 27 | AH3: 28 | AI3: 29 | AJ3: 30 | AK3: 31 | AL3: 32 | AM3: 33 | AN3: 34 | AO3: 35 | AP3: 36 | AQ3: 37 | AR3: 38 | AS3: 39 | AT3: 40 | AU3: 41 | AV3: 42 | AW3: 43 | AX3: 44 | AY3: 45 | AZ3: 46 | BA3: 47 | BB3: 48 | BC3: 49 | BD3: 50 | BE3: 51 | BF3: 52 | BG3: 53 | BH3: 54 | BI3: 55 | BJ3: 56 | BK3: 57 | BL3: 58 | BM3: 59 | BN3: 60 | BO3: 61 | BP3: 62 | BQ3: 63 | BR3: 64 | BS3: 65 | BT3: 66 | BU3: 67 | BV3: 68 | BW3: 69 | BX3: 70 | BY3: 71 | BZ3: 72 | CA3: 73 | CB3: 74 | CC3: 75 | CD3: 76 | CE3: 77 | CF3: 78 | CG3: 79 | CH3: 80 | CI3: 81 | CJ3: 82 | CK3: 83 | CL3: 84
B4: Date | G4: 45839 | H4: 45870 | I4: 45901 | J4: 45931 | K4: 45962 | L4: 45992 | M4: 46023 | N4: 46054 | O4: 46082 | P4: 46113 | Q4: 46143 | R4: 46174 | S4: 46204 | T4: 46235 | U4: 46266 | V4: 46296 | W4: 46327 | X4: 46357 | Y4: 46388 | Z4: 46419 | AA4: 46447 | AB4: 46478 | AC4: 46508 | AD4: 46539 | AE4: 46569 | AF4: 46600 | AG4: 46631 | AH4: 46661 | AI4: 46692 | AJ4: 46722 | AK4: 46753 | AL4: 46784 | AM4: 46813 | AN4: 46844 | AO4: 46874 | AP4: 46905 | AQ4: 46935 | AR4: 46966 | AS4: 46997 | AT4: 47027 | AU4: 47058 | AV4: 47088 | AW4: 47119 | AX4: 47150 | AY4: 47178 | AZ4: 47209 | BA4: 47239 | BB4: 47270 | BC4: 47300 | BD4: 47331 | BE4: 47362 | BF4: 47392 | BG4: 47423 | BH4: 47453 | BI4: 47484 | BJ4: 47515 | BK4: 47543 | BL4: 47574 | BM4: 47604 | BN4: 47635 | BO4: 47665 | BP4: 47696 | BQ4: 47727 | BR4: 47757 | BS4: 47788 | BT4: 47818 | BU4: 47849 | BV4: 47880 | BW4: 47908 | BX4: 47939 | BY4: 47969 | BZ4: 48000 | CA4: 48030 | CB4: 48061 | CC4: 48092 | CD4: 48122 | CE4: 48153 | CF4: 48183 | CG4: 48214 | CH4: 48245 | CI4: 48274 | CJ4: 48305 | CK4: 48335 | CL4: 48366
B6: Tobe Energy Corp. Overall
C7: Total Cost | G7: =G12+G13+G20+G21+G28+G29+G36+G37+G44+G45+G52+G53+G60+G61 -> 370833.33 | H7: =H12+H13+H20+H21+H28+H29+H36+H37+H44+H45+H52+H53+H60+H61 -> 370833.33 | I7: =I12+I13+I20+I21+I28+I29+I36+I37+I44+I45+I52+I53+I60+I61 -> 370833.33 | J7: =J12+J13+J20+J21+J28+J29+J36+J37+J44+J45+J52+J53+J60+J61 -> 370833.33 | K7: =K12+K13+K20+K21+K28+K29+K36+K37+K44+K45+K52+K53+K60+K61 -> 370833.33 | L7: =L12+L13+L20+L21+L28+L29+L36+L37+L44+L45+L52+L53+L60+L61 -> 370833.33 | M7: =M12+M13+M20+M21+M28+M29+M36+M37+M44+M45+M52+M53+M60+M61 -> 370833.33 | N7: =N12+N13+N20+N21+N28+N29+N36+N37+N44+N45+N52+N53+N60+N61 -> 370833.33 | ... CL7: =CL12+CL13+CL20+CL21+CL28+CL29+CL36+CL37+CL44+CL45+CL52+CL53+CL60+CL61 -> 1457151.8
C8: Total Production | G8: =G14+G22+G30+G38+G46+G54+G62 -> 0 | H8: =H14+H22+H30+H38+H46+H54+H62 -> 0 | I8: =I14+I22+I30+I38+I46+I54+I62 -> 0 | J8: =J14+J22+J30+J38+J46+J54+J62 -> 0 | K8: =K14+K22+K30+K38+K46+K54+K62 -> 0 | L8: =L14+L22+L30+L38+L46+L54+L62 -> 0 | M8: =M14+M22+M30+M38+M46+M54+M62 -> 0 | N8: =N14+N22+N30+N38+N46+N54+N62 -> 0 | ... CL8: =CL14+CL22+CL30+CL38+CL46+CL54+CL62 -> 900000
C9: Total Profit | G9: =(G17+G25+G33+G41+G49+G57+G65)-G7 -> -370833.33 | H9: =(H17+H25+H33+H41+H49+H57+H65)-H7 -> -370833.33 | I9: =(I17+I25+I33+I41+I49+I57+I65)-I7 -> -370833.33 | J9: =(J17+J25+J33+J41+J49+J57+J65)-J7 -> -370833.33 | K9: =(K17+K25+K33+K41+K49+K57+K65)-K7 -> -370833.33 | L9: =(L17+L25+L33+L41+L49+L57+L65)-L7 -> -370833.33 | M9: =(M17+M25+M33+M41+M49+M57+M65)-M7 -> -370833.33 | N9: =(N17+N25+N33+N41+N49+N57+N65)-N7 -> -370833.33 | ... CL9: =(CL17+CL25+CL33+CL41+CL49+CL57+CL65)-CL7 -> 18684967
B11: GH2x - OKC
B12: kg Opex | C12: Capital Costs | G12: =('Project Overview'!$C$4/12) -> 266666.67 | H12: =('Project Overview'!$C$4/12) -> 266666.67 | I12: =('Project Overview'!$C$4/12) -> 266666.67 | J12: =('Project Overview'!$C$4/12) -> 266666.67 | K12: =('Project Overview'!$C$4/12) -> 266666.67 | L12: =('Project Overview'!$C$4/12) -> 266666.67 | M12: =('Project Overview'!$C$4/12) -> 266666.67 | N12: =('Project Overview'!$C$4/12) -> 266666.67 | ... R12: =('Project Overview'!$C$4/12) -> 266666.67 | S12: ='Project Overview'!$D$4/12 -> 83333.333 | T12: ='Project Overview'!$D$4/12 -> 83333.333 | U12: ='Project Overview'!$D$4/12 -> 83333.333 | V12: ='Project Overview'!$D$4/12 -> 83333.333 | W12: ='Project Overview'!$D$4/12 -> 83333.333 | X12: ='Project Overview'!$D$4/12 -> 83333.333 | Y12: ='Project Overview'!$D$4/12 -> 83333.333 | Z12: ='Project Overview'!$D$4/12 -> 83333.333 | ... AD12: ='Project Overview'!$D$4/12 -> 83333.333 | AE12: =('Project Overview'!$E$4/12) -> 125000 | AF12: =('Project Overview'!$E$4/12) -> 125000 | AG12: =('Project Overview'!$E$4/12) -> 125000 | AH12: =('Project Overview'!$E$4/12) -> 125000 | AI12: =('Project Overview'!$E$4/12) -> 125000 | AJ12: =('Project Overview'!$E$4/12) -> 125000 | AK12: =('Project Overview'!$E$4/12) -> 125000 | AL12: =('Project Overview'!$E$4/12) -> 125000 | ... AP12: =('Project Overview'!$E$4/12) -> 125000 | AQ12: ='Project Overview'!$F$4/12 -> 0 | AR12: ='Project Overview'!$F$4/12 -> 0 | AS12: ='Project Overview'!$F$4/12 -> 0 | AT12: ='Project Overview'!$F$4/12 -> 0 | AU12: ='Project Overview'!$F$4/12 -> 0 | AV12: ='Project Overview'!$F$4/12 -> 0 | AW12: ='Project Overview'!$F$4/12 -> 0 | AX12: ='Project Overview'!$F$4/12 -> 0 | ... BB12: ='Project Overview'!$F$4/12 -> 0 | BC12: ='Project Overview'!$G$4/12 -> 0 | BD12: ='Project Overview'!$G$4/12 -> 0 | BE12: ='Project Overview'!$G$4/12 -> 0 | BF12: ='Project Overview'!$G$4/12 -> 0 | BG12: ='Project Overview'!$G$4/12 -> 0 | BH12: ='Project Overview'!$G$4/12 -> 0 | BI12: ='Project Overview'!$G$4/12 -> 0 | BJ12: ='Project Overview'!$G$4/12 -> 0 | ... CL12: ='Project Overview'!$G$4/12 -> 0
B13: ='H2 Production Costs'!$D$9 -> 2.6198684 | C13: Personnel | G13: ='Project Overview'!$C$5/12 -> 104166.67 | H13: ='Project Overview'!$C$5/12 -> 104166.67 | I13: ='Project Overview'!$C$5/12 -> 104166.67 | J13: ='Project Overview'!$C$5/12 -> 104166.67 | K13: ='Project Overview'!$C$5/12 -> 104166.67 | L13: ='Project Overview'!$C$5/12 -> 104166.67 | M13: ='Project Overview'!$C$5/12 -> 104166.67 | N13: ='Project Overview'!$C$5/12 -> 104166.67 | ... R13: ='Project Overview'!$C$5/12 -> 104166.67 | S13: ='Project Overview'!$D$5/12 -> 147828.67 | T13: ='Project Overview'!$D$5/12 -> 147828.67 | U13: ='Project Overview'!$D$5/12 -> 147828.67 | V13: ='Project Overview'!$D$5/12 -> 147828.67 | W13: ='Project Overview'!$D$5/12 -> 147828.67 | X13: ='Project Overview'!$D$5/12 -> 147828.67 | Y13: ='Project Overview'!$D$5/12 -> 147828.67 | Z13: ='Project Overview'!$D$5/12 -> 147828.67 | ... AD13: ='Project Overview'!$D$5/12 -> 147828.67 | AE13: ='Project Overview'!$E$5/12 -> 190158.65 | AF13: ='Project Overview'!$E$5/12 -> 190158.65 | AG13: ='Project Overview'!$E$5/12 -> 190158.65 | AH13: ='Project Overview'!$E$5/12 -> 190158.65 | AI13: ='Project Overview'!$E$5/12 -> 190158.65 | AJ13: ='Project Overview'!$E$5/12 -> 190158.65 | AK13: ='Project Overview'!$E$5/12 -> 190158.65 | AL13: ='Project Overview'!$E$5/12 -> 190158.65 | ... AP13: ='Project Overview'!$E$5/12 -> 190158.65 | AQ13: ='Project Overview'!$F$5/12 -> 238714.63 | AR13: ='Project Overview'!$F$5/12 -> 238714.63 | AS13: ='Project Overview'!$F$5/12 -> 238714.63 | AT13: ='Project Overview'!$F$5/12 -> 238714.63 | AU13: ='Project Overview'!$F$5/12 -> 238714.63 | AV13: ='Project Overview'!$F$5/12 -> 238714.63 | AW13: ='Project Overview'!$F$5/12 -> 238714.63 | AX13: ='Project Overview'!$F$5/12 -> 238714.63 | ... BB13: ='Project Overview'!$F$5/12 -> 238714.63 | BC13: ='Project Overview'!$G$5/12 -> 238714.63 | BD13: ='Project Overview'!$G$5/12 -> 238714.63 | BE13: ='Project Overview'!$G$5/12 -> 238714.63 | BF13: ='Project Overview'!$G$5/12 -> 238714.63 | BG13: ='Project Overview'!$G$5/12 -> 238714.63 | BH13: ='Project Overview'!$G$5/12 -> 238714.63 | BI13: ='Project Overview'!$G$5/12 -> 238714.63 | BJ13: ='Project Overview'!$G$5/12 -> 238714.63 | ... CL13: ='Project Overview'!$G$5/12 -> 238714.63
B14: kg Market | C14: Production | G14: 0 | H14: 0 | I14: 0 | J14: 0 | K14: 0 | L14: 0 | M14: 0 | N14: 0 | O14: 0 | P14: 0 | Q14: 0 | R14: 0 | S14: 7500 | T14: 7500 | U14: 7500 | V14: 7500 | W14: 7500 | X14: 7500 | Y14: 37500 | Z14: 37500 | AA14: 37500 | AB14: 37500 | AC14: 37500 | AD14: 37500 | AE14: 37500 | AF14: 37500 | AG14: 37500 | AH14: 37500 | AI14: 37500 | AJ14: 37500 | AK14: 75000 | AL14: 75000 | AM14: 75000 | AN14: 75000 | AO14: 75000 | AP14: 75000 | AQ14: 75000 | AR14: 75000 | AS14: 75000 | AT14: 75000 | AU14: 75000 | AV14: 75000 | AW14: 75000 | AX14: 75000 | AY14: 75000 | AZ14: 75000 | BA14: 75000 | BB14: 75000 | BC14: 75000 | BD14: 75000 | BE14: 75000 | BF14: 75000 | BG14: 75000 | BH14: 75000 | BI14: 75000 | BJ14: 75000 | BK14: 75000 | BL14: 75000 | BM14: 75000 | BN14: 75000 | BO14: 75000 | BP14: 75000 | BQ14: 75000 | BR14: 75000 | BS14: 75000 | BT14: 75000 | BU14: 75000 | BV14: 75000 | BW14: 75000 | BX14: 75000 | BY14: 75000 | BZ14: 75000 | CA14: 75000 | CB14: 75000 | CC14: 75000 | CD14: 75000 | CE14: 75000 | CF14: 75000 | CG14: 75000 | CH14: 75000 | CI14: 75000 | CJ14: 75000 | CK14: 75000 | CL14: 75000
B15: 25 | C15: Revenue | G15: =G14*$B$15 -> 0 | H15: =H14*$B$15 -> 0 | I15: =I14*$B$15 -> 0 | J15: =J14*$B$15 -> 0 | K15: =K14*$B$15 -> 0 | L15: =L14*$B$15 -> 0 | M15: =M14*$B$15 -> 0 | N15: =N14*$B$15 -> 0 | ... CL15: =CL14*$B$15 -> 1875000
C16: COGS | G16: =G14*$B$13 -> 0 | H16: =H14*$B$13 -> 0 | I16: =I14*$B$13 -> 0 | J16: =J14*$B$13 -> 0 | K16: =K14*$B$13 -> 0 | L16: =L14*$B$13 -> 0 | M16: =M14*$B$13 -> 0 | N16: =N14*$B$13 -> 0 | ... CL16: =CL14*$B$13 -> 196490.13
C17: Gross Profit | G17: =G14*($B$15-$B$13) -> 0 | H17: =H14*($B$15-$B$13) -> 0 | I17: =I14*($B$15-$B$13) -> 0 | J17: =J14*($B$15-$B$13) -> 0 | K17: =K14*($B$15-$B$13) -> 0 | L17: =L14*($B$15-$B$13) -> 0 | M17: =M14*($B$15-$B$13) -> 0 | N17: =N14*($B$15-$B$13) -> 0 | ... CL17: =CL14*($B$15-$B$13) -> 1678509.9
F18: =G12*12 -> 3200000
B19: GH2x2 - Tulsa
B20: kg Opex | C20: Capital Costs | S20: ='Project Overview'!$C$12/12 -> 270000 | T20: ='Project Overview'!$C$12/12 -> 270000 | U20: ='Project Overview'!$C$12/12 -> 270000 | V20: ='Project Overview'!$C$12/12 -> 270000 | W20: ='Project Overview'!$C$12/12 -> 270000 | X20: ='Project Overview'!$C$12/12 -> 270000 | Y20: ='Project Overview'!$C$12/12 -> 270000 | Z20: ='Project Overview'!$C$12/12 -> 270000 | ... AD20: ='Project Overview'!$C$12/12 -> 270000 | AE20: ='Project Overview'!$D$12/12 -> 125000 | AF20: ='Project Overview'!$D$12/12 -> 125000 | AG20: ='Project Overview'!$D$12/12 -> 125000 | AH20: ='Project Overview'!$D$12/12 -> 125000 | AI20: ='Project Overview'!$D$12/12 -> 125000 | AJ20: ='Project Overview'!$D$12/12 -> 125000 | AK20: ='Project Overview'!$D$12/12 -> 125000 | AL20: ='Project Overview'!$D$12/12 -> 125000 | ... AP20: ='Project Overview'!$D$12/12 -> 125000 | AQ20: ='Project Overview'!$E$12/12 -> 0 | AR20: ='Project Overview'!$E$12/12 -> 0 | AS20: ='Project Overview'!$E$12/12 -> 0 | AT20: ='Project Overview'!$E$12/12 -> 0 | AU20: ='Project Overview'!$E$12/12 -> 0 | AV20: ='Project Overview'!$E$12/12 -> 0 | AW20: ='Project Overview'!$E$12/12 -> 0 | AX20: ='Project Overview'!$E$12/12 -> 0 | ... BB20: ='Project Overview'!$E$12/12 -> 0 | BC20: ='Project Overview'!$F$12/12 -> 0 | BD20: ='Project Overview'!$F$12/12 -> 0 | BE20: ='Project Overview'!$F$12/12 -> 0 | BF20: ='Project Overview'!$F$12/12 -> 0 | BG20: ='Project Overview'!$F$12/12 -> 0 | BH20: ='Project Overview'!$F$12/12 -> 0 | BI20: ='Project Overview'!$F$12/12 -> 0 | BJ20: ='Project Overview'!$F$12/12 -> 0 | ... BN20: ='Project Overview'!$F$12/12 -> 0 | BO20: ='Project Overview'!$G$12/12 -> 0 | BP20: ='Project Overview'!$G$12/12 -> 0 | BQ20: ='Project Overview'!$G$12/12 -> 0 | BR20: ='Project Overview'!$G$12/12 -> 0 | BS20: ='Project Overview'!$G$12/12 -> 0 | BT20: ='Project Overview'!$G$12/12 -> 0 | BU20: ='Project Overview'!$G$12/12 -> 0 | BV20: ='Project Overview'!$G$12/12 -> 0 | ... CL20: ='Project Overview'!$G$12/12 -> 0
B21: ='H2 Production Costs'!$D$9 -> 2.6198684 | C21: Personnel | S21: ='Project Overview'!$C$13/12 -> 68107.667 | T21: ='Project Overview'!$C$13/12 -> 68107.667 | U21: ='Project Overview'!$C$13/12 -> 68107.667 | V21: ='Project Overview'!$C$13/12 -> 68107.667 | W21: ='Project Overview'!$C$13/12 -> 68107.667 | X21: ='Project Overview'!$C$13/12 -> 68107.667 | Y21: ='Project Overview'!$C$13/12 -> 68107.667 | Z21: ='Project Overview'!$C$13/12 -> 68107.667 | ... AD21: ='Project Overview'!$C$13/12 -> 68107.667 | AE21: ='Project Overview'!$D$13/12 -> 90171.117 | AF21: ='Project Overview'!$D$13/12 -> 90171.117 | AG21: ='Project Overview'!$D$13/12 -> 90171.117 | AH21: ='Project Overview'!$D$13/12 -> 90171.117 | AI21: ='Project Overview'!$D$13/12 -> 90171.117 | AJ21: ='Project Overview'!$D$13/12 -> 90171.117 | AK21: ='Project Overview'!$D$13/12 -> 90171.117 | AL21: ='Project Overview'!$D$13/12 -> 90171.117 | ... AP21: ='Project Overview'!$D$13/12 -> 90171.117 | AQ21: ='Project Overview'!$E$13/12 -> 103696.78 | AR21: ='Project Overview'!$E$13/12 -> 103696.78 | AS21: ='Project Overview'!$E$13/12 -> 103696.78 | AT21: ='Project Overview'!$E$13/12 -> 103696.78 | AU21: ='Project Overview'!$E$13/12 -> 103696.78 | AV21: ='Project Overview'!$E$13/12 -> 103696.78 | AW21: ='Project Overview'!$E$13/12 -> 103696.78 | AX21: ='Project Overview'!$E$13/12 -> 103696.78 | ... BB21: ='Project Overview'!$E$13/12 -> 103696.78 | BC21: ='Project Overview'!$F$13/12 -> 119251.3 | BD21: ='Project Overview'!$F$13/12 -> 119251.3 | BE21: ='Project Overview'!$F$13/12 -> 119251.3 | BF21: ='Project Overview'!$F$13/12 -> 119251.3 | BG21: ='Project Overview'!$F$13/12 -> 119251.3 | BH21: ='Project Overview'!$F$13/12 -> 119251.3 | BI21: ='Project Overview'!$F$13/12 -> 119251.3 | BJ21: ='Project Overview'!$F$13/12 -> 119251.3 | ... BN21: ='Project Overview'!$F$13/12 -> 119251.3 | BO21: ='Project Overview'!$G$13/12 -> 119251.3 | BP21: ='Project Overview'!$G$13/12 -> 119251.3 | BQ21: ='Project Overview'!$G$13/12 -> 119251.3 | BR21: ='Project Overview'!$G$13/12 -> 119251.3 | BS21: ='Project Overview'!$G$13/12 -> 119251.3 | BT21: ='Project Overview'!$G$13/12 -> 119251.3 | BU21: ='Project Overview'!$G$13/12 -> 119251.3 | BV21: ='Project Overview'!$G$13/12 -> 119251.3 | ... CL21: ='Project Overview'!$G$13/12 -> 119251.3
B22: kg Market | C22: Production | S22: 0 | T22: 0 | U22: 0 | V22: 0 | W22: 0 | X22: 0 | Y22: 0 | Z22: 0 | AA22: 0 | AB22: 0 | AC22: 0 | AD22: 0 | AE22: 37500 | AF22: 37500 | AG22: 37500 | AH22: 37500 | AI22: 37500 | AJ22: 37500 | AK22: 37500 | AL22: 37500 | AM22: 37500 | AN22: 37500 | AO22: 37500 | AP22: 37500 | AQ22: 75000 | AR22: 75000 | AS22: 75000 | AT22: 75000 | AU22: 75000 | AV22: 75000 | AW22: 75000 | AX22: 75000 | AY22: 75000 | AZ22: 75000 | BA22: 75000 | BB22: 75000 | BC22: 75000 | BD22: 75000 | BE22: 75000 | BF22: 75000 | BG22: 75000 | BH22: 75000 | BI22: 75000 | BJ22: 75000 | BK22: 75000 | BL22: 75000 | BM22: 75000 | BN22: 75000 | BO22: 75000 | BP22: 75000 | BQ22: 75000 | BR22: 75000 | BS22: 75000 | BT22: 75000 | BU22: 75000 | BV22: 75000 | BW22: 75000 | BX22: 75000 | BY22: 75000 | BZ22: 75000 | CA22: 75000 | CB22: 75000 | CC22: 75000 | CD22: 75000 | CE22: 75000 | CF22: 75000 | CG22: 75000 | CH22: 75000 | CI22: 75000 | CJ22: 75000 | CK22: 75000 | CL22: 75000
B23: 25 | C23: Revenue | G23: =G22*$B$15 -> 0 | H23: =H22*$B$15 -> 0 | I23: =I22*$B$15 -> 0 | J23: =J22*$B$15 -> 0 | K23: =K22*$B$15 -> 0 | L23: =L22*$B$15 -> 0 | M23: =M22*$B$15 -> 0 | N23: =N22*$B$15 -> 0 | ... CL23: =CL22*$B$15 -> 1875000
C24: COGS | G24: =G22*$B$13 -> 0 | H24: =H22*$B$13 -> 0 | I24: =I22*$B$13 -> 0 | J24: =J22*$B$13 -> 0 | K24: =K22*$B$13 -> 0 | L24: =L22*$B$13 -> 0 | M24: =M22*$B$13 -> 0 | N24: =N22*$B$13 -> 0 | ... CL24: =CL22*$B$13 -> 196490.13
C25: Gross Profit | S25: =S22*($B$23-$B$21) -> 0 | T25: =T22*($B$23-$B$21) -> 0 | U25: =U22*($B$23-$B$21) -> 0 | V25: =V22*($B$23-$B$21) -> 0 | W25: =W22*($B$23-$B$21) -> 0 | X25: =X22*($B$23-$B$21) -> 0 | Y25: =Y22*($B$23-$B$21) -> 0 | Z25: =Z22*($B$23-$B$21) -> 0 | ... CL25: =CL22*($B$23-$B$21) -> 1678509.9
S26: =S20*12 -> 3240000 | AE26: =AE20*12 -> 1500000
B27: GH2x3 - Seattle | S27: =S20*12+S12*12 -> 4240000
B28: kg Opex | C28: Capital Costs | AE28: ='Project Overview'!$C$12/12 -> 270000 | AF28: ='Project Overview'!$C$12/12 -> 270000 | AG28: ='Project Overview'!$C$12/12 -> 270000 | AH28: ='Project Overview'!$C$12/12 -> 270000 | AI28: ='Project Overview'!$C$12/12 -> 270000 | AJ28: ='Project Overview'!$C$12/12 -> 270000 | AK28: ='Project Overview'!$C$12/12 -> 270000 | AL28: ='Project Overview'!$C$12/12 -> 270000 | ... AP28: ='Project Overview'!$C$12/12 -> 270000 | AQ28: ='Project Overview'!$D$12/12 -> 125000 | AR28: ='Project Overview'!$D$12/12 -> 125000 | AS28: ='Project Overview'!$D$12/12 -> 125000 | AT28: ='Project Overview'!$D$12/12 -> 125000 | AU28: ='Project Overview'!$D$12/12 -> 125000 | AV28: ='Project Overview'!$D$12/12 -> 125000 | AW28: ='Project Overview'!$D$12/12 -> 125000 | AX28: ='Project Overview'!$D$12/12 -> 125000 | ... BB28: ='Project Overview'!$D$12/12 -> 125000 | BC28: ='Project Overview'!$E$12/12 -> 0 | BD28: ='Project Overview'!$E$12/12 -> 0 | BE28: ='Project Overview'!$E$12/12 -> 0 | BF28: ='Project Overview'!$E$12/12 -> 0 | BG28: ='Project Overview'!$E$12/12 -> 0 | BH28: ='Project Overview'!$E$12/12 -> 0 | BI28: ='Project Overview'!$E$12/12 -> 0 | BJ28: ='Project Overview'!$E$12/12 -> 0 | ... BN28: ='Project Overview'!$E$12/12 -> 0 | BO28: ='Project Overview'!$F$12/12 -> 0 | BP28: ='Project Overview'!$F$12/12 -> 0 | BQ28: ='Project Overview'!$F$12/12 -> 0 | BR28: ='Project Overview'!$F$12/12 -> 0 | BS28: ='Project Overview'!$F$12/12 -> 0 | BT28: ='Project Overview'!$F$12/12 -> 0 | BU28: ='Project Overview'!$F$12/12 -> 0 | BV28: ='Project Overview'!$F$12/12 -> 0 | ... BZ28: ='Project Overview'!$F$12/12 -> 0 | CA28: ='Project Overview'!$G$12/12 -> 0 | CB28: ='Project Overview'!$G$12/12 -> 0 | CC28: ='Project Overview'!$G$12/12 -> 0 | CD28: ='Project Overview'!$G$12/12 -> 0 | CE28: ='Project Overview'!$G$12/12 -> 0 | CF28: ='Project Overview'!$G$12/12 -> 0 | CG28: ='Project Overview'!$G$12/12 -> 0 | CH28: ='Project Overview'!$G$12/12 -> 0 | ... CL28: ='Project Overview'!$G$12/12 -> 0
B29: ='H2 Production Costs'!$D$9 -> 2.6198684 | C29: Personnel | AE29: ='Project Overview'!$C$13/12 -> 68107.667 | AF29: ='Project Overview'!$C$13/12 -> 68107.667 | AG29: ='Project Overview'!$C$13/12 -> 68107.667 | AH29: ='Project Overview'!$C$13/12 -> 68107.667 | AI29: ='Project Overview'!$C$13/12 -> 68107.667 | AJ29: ='Project Overview'!$C$13/12 -> 68107.667 | AK29: ='Project Overview'!$C$13/12 -> 68107.667 | AL29: ='Project Overview'!$C$13/12 -> 68107.667 | ... AP29: ='Project Overview'!$C$13/12 -> 68107.667 | AQ29: ='Project Overview'!$D$13/12 -> 90171.117 | AR29: ='Project Overview'!$D$13/12 -> 90171.117 | AS29: ='Project Overview'!$D$13/12 -> 90171.117 | AT29: ='Project Overview'!$D$13/12 -> 90171.117 | AU29: ='Project Overview'!$D$13/12 -> 90171.117 | AV29: ='Project Overview'!$D$13/12 -> 90171.117 | AW29: ='Project Overview'!$D$13/12 -> 90171.117 | AX29: ='Project Overview'!$D$13/12 -> 90171.117 | ... BB29: ='Project Overview'!$D$13/12 -> 90171.117 | BC29: ='Project Overview'!$E$13/12 -> 103696.78 | BD29: ='Project Overview'!$E$13/12 -> 103696.78 | BE29: ='Project Overview'!$E$13/12 -> 103696.78 | BF29: ='Project Overview'!$E$13/12 -> 103696.78 | BG29: ='Project Overview'!$E$13/12 -> 103696.78 | BH29: ='Project Overview'!$E$13/12 -> 103696.78 | BI29: ='Project Overview'!$E$13/12 -> 103696.78 | BJ29: ='Project Overview'!$E$13/12 -> 103696.78 | ... BN29: ='Project Overview'!$E$13/12 -> 103696.78 | BO29: ='Project Overview'!$F$13/12 -> 119251.3 | BP29: ='Project Overview'!$F$13/12 -> 119251.3 | BQ29: ='Project Overview'!$F$13/12 -> 119251.3 | BR29: ='Project Overview'!$F$13/12 -> 119251.3 | BS29: ='Project Overview'!$F$13/12 -> 119251.3 | BT29: ='Project Overview'!$F$13/12 -> 119251.3 | BU29: ='Project Overview'!$F$13/12 -> 119251.3 | BV29: ='Project Overview'!$F$13/12 -> 119251.3 | ... BZ29: ='Project Overview'!$F$13/12 -> 119251.3 | CA29: ='Project Overview'!$G$13/12 -> 119251.3 | CB29: ='Project Overview'!$G$13/12 -> 119251.3 | CC29: ='Project Overview'!$G$13/12 -> 119251.3 | CD29: ='Project Overview'!$G$13/12 -> 119251.3 | CE29: ='Project Overview'!$G$13/12 -> 119251.3 | CF29: ='Project Overview'!$G$13/12 -> 119251.3 | CG29: ='Project Overview'!$G$13/12 -> 119251.3 | CH29: ='Project Overview'!$G$13/12 -> 119251.3 | ... CL29: ='Project Overview'!$G$13/12 -> 119251.3
B30: kg Market | C30: Production | AE30: 0 | AF30: 0 | AG30: 0 | AH30: 0 | AI30: 0 | AJ30: 0 | AK30: 0 | AL30: 0 | AM30: 0 | AN30: 0 | AO30: 0 | AP30: 0 | AQ30: 37500 | AR30: 37500 | AS30: 37500 | AT30: 37500 | AU30: 37500 | AV30: 37500 | AW30: 37500 | AX30: 37500 | AY30: 37500 | AZ30: 37500 | BA30: 37500 | BB30: 37500 | BC30: 75000 | BD30: 75000 | BE30: 75000 | BF30: 75000 | BG30: 75000 | BH30: 75000 | BI30: 75000 | BJ30: 75000 | BK30: 75000 | BL30: 75000 | BM30: 75000 | BN30: 75000 | BO30: 75000 | BP30: 75000 | BQ30: 75000 | BR30: 75000 | BS30: 75000 | BT30: 75000 | BU30: 75000 | BV30: 75000 | BW30: 75000 | BX30: 75000 | BY30: 75000 | BZ30: 75000 | CA30: 75000 | CB30: 75000 | CC30: 75000 | CD30: 75000 | CE30: 75000 | CF30: 75000 | CG30: 75000 | CH30: 75000 | CI30: 75000 | CJ30: 75000 | CK30: 75000 | CL30: 75000
B31: 25 | C31: Revenue | G31: =G30*$B$15 -> 0 | H31: =H30*$B$15 -> 0 | I31: =I30*$B$15 -> 0 | J31: =J30*$B$15 -> 0 | K31: =K30*$B$15 -> 0 | L31: =L30*$B$15 -> 0 | M31: =M30*$B$15 -> 0 | N31: =N30*$B$15 -> 0 | ... CL31: =CL30*$B$15 -> 1875000
C32: COGS | G32: =G30*$B$13 -> 0 | H32: =H30*$B$13 -> 0 | I32: =I30*$B$13 -> 0 | J32: =J30*$B$13 -> 0 | K32: =K30*$B$13 -> 0 | L32: =L30*$B$13 -> 0 | M32: =M30*$B$13 -> 0 | N32: =N30*$B$13 -> 0 | ... CL32: =CL30*$B$13 -> 196490.13
C33: Gross Profit | AE33: =AE30*($B$31-$B$29) -> 0 | AF33: =AF30*($B$31-$B$29) -> 0 | AG33: =AG30*($B$31-$B$29) -> 0 | AH33: =AH30*($B$31-$B$29) -> 0 | AI33: =AI30*($B$31-$B$29) -> 0 | AJ33: =AJ30*($B$31-$B$29) -> 0 | AK33: =AK30*($B$31-$B$29) -> 0 | AL33: =AL30*($B$31-$B$29) -> 0 | ... CL33: =CL30*($B$31-$B$29) -> 1678509.9
B35: GH2x4 - Spokane | AE35: =AE28*12+AE20*12+AE12*12+AE36*12 -> 9480000
B36: kg Opex | C36: Capital Costs | AE36: ='Project Overview'!$C$12/12 -> 270000 | AF36: ='Project Overview'!$C$12/12 -> 270000 | AG36: ='Project Overview'!$C$12/12 -> 270000 | AH36: ='Project Overview'!$C$12/12 -> 270000 | AI36: ='Project Overview'!$C$12/12 -> 270000 | AJ36: ='Project Overview'!$C$12/12 -> 270000 | AK36: ='Project Overview'!$C$12/12 -> 270000 | AL36: ='Project Overview'!$C$12/12 -> 270000 | ... AP36: ='Project Overview'!$C$12/12 -> 270000 | AQ36: ='Project Overview'!$D$12/12 -> 125000 | AR36: ='Project Overview'!$D$12/12 -> 125000 | AS36: ='Project Overview'!$D$12/12 -> 125000 | AT36: ='Project Overview'!$D$12/12 -> 125000 | AU36: ='Project Overview'!$D$12/12 -> 125000 | AV36: ='Project Overview'!$D$12/12 -> 125000 | AW36: ='Project Overview'!$D$12/12 -> 125000 | AX36: ='Project Overview'!$D$12/12 -> 125000 | ... BB36: ='Project Overview'!$D$12/12 -> 125000 | BC36: ='Project Overview'!$E$12/12 -> 0 | BD36: ='Project Overview'!$E$12/12 -> 0 | BE36: ='Project Overview'!$E$12/12 -> 0 | BF36: ='Project Overview'!$E$12/12 -> 0 | BG36: ='Project Overview'!$E$12/12 -> 0 | BH36: ='Project Overview'!$E$12/12 -> 0 | BI36: ='Project Overview'!$E$12/12 -> 0 | BJ36: ='Project Overview'!$E$12/12 -> 0 | ... BN36: ='Project Overview'!$E$12/12 -> 0 | BO36: ='Project Overview'!$F$12/12 -> 0 | BP36: ='Project Overview'!$F$12/12 -> 0 | BQ36: ='Project Overview'!$F$12/12 -> 0 | BR36: ='Project Overview'!$F$12/12 -> 0 | BS36: ='Project Overview'!$F$12/12 -> 0 | BT36: ='Project Overview'!$F$12/12 -> 0 | BU36: ='Project Overview'!$F$12/12 -> 0 | BV36: ='Project Overview'!$F$12/12 -> 0 | ... BZ36: ='Project Overview'!$F$12/12 -> 0 | CA36: ='Project Overview'!$G$12/12 -> 0 | CB36: ='Project Overview'!$G$12/12 -> 0 | CC36: ='Project Overview'!$G$12/12 -> 0 | CD36: ='Project Overview'!$G$12/12 -> 0 | CE36: ='Project Overview'!$G$12/12 -> 0 | CF36: ='Project Overview'!$G$12/12 -> 0 | CG36: ='Project Overview'!$G$12/12 -> 0 | CH36: ='Project Overview'!$G$12/12 -> 0 | ... CL36: ='Project Overview'!$G$12/12 -> 0
B37: ='H2 Production Costs'!$D$9 -> 2.6198684 | C37: Personnel | AE37: ='Project Overview'!$C$13/12 -> 68107.667 | AF37: ='Project Overview'!$C$13/12 -> 68107.667 | AG37: ='Project Overview'!$C$13/12 -> 68107.667 | AH37: ='Project Overview'!$C$13/12 -> 68107.667 | AI37: ='Project Overview'!$C$13/12 -> 68107.667 | AJ37: ='Project Overview'!$C$13/12 -> 68107.667 | AK37: ='Project Overview'!$C$13/12 -> 68107.667 | AL37: ='Project Overview'!$C$13/12 -> 68107.667 | ... AP37: ='Project Overview'!$C$13/12 -> 68107.667 | AQ37: ='Project Overview'!$D$13/12 -> 90171.117 | AR37: ='Project Overview'!$D$13/12 -> 90171.117 | AS37: ='Project Overview'!$D$13/12 -> 90171.117 | AT37: ='Project Overview'!$D$13/12 -> 90171.117 | AU37: ='Project Overview'!$D$13/12 -> 90171.117 | AV37: ='Project Overview'!$D$13/12 -> 90171.117 | AW37: ='Project Overview'!$D$13/12 -> 90171.117 | AX37: ='Project Overview'!$D$13/12 -> 90171.117 | ... BB37: ='Project Overview'!$D$13/12 -> 90171.117 | BC37: ='Project Overview'!$E$13/12 -> 103696.78 | BD37: ='Project Overview'!$E$13/12 -> 103696.78 | BE37: ='Project Overview'!$E$13/12 -> 103696.78 | BF37: ='Project Overview'!$E$13/12 -> 103696.78 | BG37: ='Project Overview'!$E$13/12 -> 103696.78 | BH37: ='Project Overview'!$E$13/12 -> 103696.78 | BI37: ='Project Overview'!$E$13/12 -> 103696.78 | BJ37: ='Project Overview'!$E$13/12 -> 103696.78 | ... BN37: ='Project Overview'!$E$13/12 -> 103696.78 | BO37: ='Project Overview'!$F$13/12 -> 119251.3 | BP37: ='Project Overview'!$F$13/12 -> 119251.3 | BQ37: ='Project Overview'!$F$13/12 -> 119251.3 | BR37: ='Project Overview'!$F$13/12 -> 119251.3 | BS37: ='Project Overview'!$F$13/12 -> 119251.3 | BT37: ='Project Overview'!$F$13/12 -> 119251.3 | BU37: ='Project Overview'!$F$13/12 -> 119251.3 | BV37: ='Project Overview'!$F$13/12 -> 119251.3 | ... BZ37: ='Project Overview'!$F$13/12 -> 119251.3 | CA37: ='Project Overview'!$G$13/12 -> 119251.3 | CB37: ='Project Overview'!$G$13/12 -> 119251.3 | CC37: ='Project Overview'!$G$13/12 -> 119251.3 | CD37: ='Project Overview'!$G$13/12 -> 119251.3 | CE37: ='Project Overview'!$G$13/12 -> 119251.3 | CF37: ='Project Overview'!$G$13/12 -> 119251.3 | CG37: ='Project Overview'!$G$13/12 -> 119251.3 | CH37: ='Project Overview'!$G$13/12 -> 119251.3 | ... CL37: ='Project Overview'!$G$13/12 -> 119251.3
B38: kg Market | C38: Production | AE38: 0 | AF38: 0 | AG38: 0 | AH38: 0 | AI38: 0 | AJ38: 0 | AK38: 0 | AL38: 0 | AM38: 0 | AN38: 0 | AO38: 0 | AP38: 0 | AQ38: 37500 | AR38: 37500 | AS38: 37500 | AT38: 37500 | AU38: 37500 | AV38: 37500 | AW38: 37500 | AX38: 37500 | AY38: 37500 | AZ38: 37500 | BA38: 37500 | BB38: 37500 | BC38: 75000 | BD38: 75000 | BE38: 75000 | BF38: 75000 | BG38: 75000 | BH38: 75000 | BI38: 75000 | BJ38: 75000 | BK38: 75000 | BL38: 75000 | BM38: 75000 | BN38: 75000 | BO38: 75000 | BP38: 75000 | BQ38: 75000 | BR38: 75000 | BS38: 75000 | BT38: 75000 | BU38: 75000 | BV38: 75000 | BW38: 75000 | BX38: 75000 | BY38: 75000 | BZ38: 75000 | CA38: 75000 | CB38: 75000 | CC38: 75000 | CD38: 75000 | CE38: 75000 | CF38: 75000 | CG38: 75000 | CH38: 75000 | CI38: 75000 | CJ38: 75000 | CK38: 75000 | CL38: 75000
B39: 25 | C39: Revenue | G39: =G38*$B$15 -> 0 | H39: =H38*$B$15 -> 0 | I39: =I38*$B$15 -> 0 | J39: =J38*$B$15 -> 0 | K39: =K38*$B$15 -> 0 | L39: =L38*$B$15 -> 0 | M39: =M38*$B$15 -> 0 | N39: =N38*$B$15 -> 0 | ... CL39: =CL38*$B$15 -> 1875000
C40: COGS | G40: =G38*$B$13 -> 0 | H40: =H38*$B$13 -> 0 | I40: =I38*$B$13 -> 0 | J40: =J38*$B$13 -> 0 | K40: =K38*$B$13 -> 0 | L40: =L38*$B$13 -> 0 | M40: =M38*$B$13 -> 0 | N40: =N38*$B$13 -> 0 | ... CL40: =CL38*$B$13 -> 196490.13
C41: Gross Profit | AE41: =AE38*($B$39-$B$37) -> 0 | AF41: =AF38*($B$39-$B$37) -> 0 | AG41: =AG38*($B$39-$B$37) -> 0 | AH41: =AH38*($B$39-$B$37) -> 0 | AI41: =AI38*($B$39-$B$37) -> 0 | AJ41: =AJ38*($B$39-$B$37) -> 0 | AK41: =AK38*($B$39-$B$37) -> 0 | AL41: =AL38*($B$39-$B$37) -> 0 | ... CL41: =CL38*($B$39-$B$37) -> 1678509.9
B43: GH2x5 - Albuquerque | AQ43: =(AQ28+AQ36+AQ44+AQ52)*12 -> 9480000
B44: kg Opex | C44: Capital Costs | AQ44: ='Project Overview'!$C$12/12 -> 270000 | AR44: ='Project Overview'!$C$12/12 -> 270000 | AS44: ='Project Overview'!$C$12/12 -> 270000 | AT44: ='Project Overview'!$C$12/12 -> 270000 | AU44: ='Project Overview'!$C$12/12 -> 270000 | AV44: ='Project Overview'!$C$12/12 -> 270000 | AW44: ='Project Overview'!$C$12/12 -> 270000 | AX44: ='Project Overview'!$C$12/12 -> 270000 | ... BB44: ='Project Overview'!$C$12/12 -> 270000 | BC44: ='Project Overview'!$D$12/12 -> 125000 | BD44: ='Project Overview'!$D$12/12 -> 125000 | BE44: ='Project Overview'!$D$12/12 -> 125000 | BF44: ='Project Overview'!$D$12/12 -> 125000 | BG44: ='Project Overview'!$D$12/12 -> 125000 | BH44: ='Project Overview'!$D$12/12 -> 125000 | BI44: ='Project Overview'!$D$12/12 -> 125000 | BJ44: ='Project Overview'!$D$12/12 -> 125000 | ... BN44: ='Project Overview'!$D$12/12 -> 125000 | BO44: ='Project Overview'!$E$12/12 -> 0 | BP44: ='Project Overview'!$E$12/12 -> 0 | BQ44: ='Project Overview'!$E$12/12 -> 0 | BR44: ='Project Overview'!$E$12/12 -> 0 | BS44: ='Project Overview'!$E$12/12 -> 0 | BT44: ='Project Overview'!$E$12/12 -> 0 | BU44: ='Project Overview'!$E$12/12 -> 0 | BV44: ='Project Overview'!$E$12/12 -> 0 | ... BZ44: ='Project Overview'!$E$12/12 -> 0 | CA44: ='Project Overview'!$G$12/12 -> 0 | CB44: ='Project Overview'!$G$12/12 -> 0 | CC44: ='Project Overview'!$G$12/12 -> 0 | CD44: ='Project Overview'!$G$12/12 -> 0 | CE44: ='Project Overview'!$G$12/12 -> 0 | CF44: ='Project Overview'!$G$12/12 -> 0 | CG44: ='Project Overview'!$G$12/12 -> 0 | CH44: ='Project Overview'!$G$12/12 -> 0 | ... CL44: ='Project Overview'!$G$12/12 -> 0
...

Sheet Overall
B1: Tobe Energy Corp. Overall | E1: GH2x - OKC | I1: GH2x2 - Tulsa | M1: GH2x3 - Seattle | Q1: GH2x4 - Spokane | U1: GH2x5 - Albuquerque | Y1: GH2x6 - Des Moines | AC1: GH2x7-12
E2: kg Opex | F2: ='H2 Production Costs'!$D$9 -> 2.6198684 | G2: kg Market | H2: 25 | I2: kg Opex | J2: ='H2 Production Costs'!$D$9 -> 2.6198684 | K2: kg Market | L2: 25 | M2: kg Opex | N2: ='H2 Production Costs'!$D$9 -> 2.6198684 | O2: kg Market | P2: 25 | Q2: kg Opex | R2: ='H2 Production Costs'!$D$9 -> 2.6198684 | S2: kg Market | T2: 25 | U2: kg Opex | V2: ='H2 Production Costs'!$D$9 -> 2.6198684 | W2: kg Market | X2: 25 | Y2: kg Opex | Z2: ='H2 Production Costs'!$D$9 -> 2.6198684 | AA2: kg Market | AB2: 25 | AC2: kg Opex | AD2: ='H2 Production Costs'!$D$9 -> 2.6198684 | AE2: kg Market | AF2: 25
A3: Month | B3: Total Cost | C3: Total Production | D3: Total Profit | E3: Capital Costs | F3: Personnel | G3: Production | H3: Profit | I3: Capital Costs | J3: Personnel | K3: Production | L3: Profit | M3: Capital Costs | N3: Personnel | O3: Production | P3: Profit | Q3: Capital Costs | R3: Personnel | S3: Production | T3: Profit | U3: Capital Costs | V3: Personnel | W3: Production | X3: Profit | Y3: Capital Costs | Z3: Personnel | AA3: Production | AB3: Profit | AC3: Capital Costs | AD3: Personnel | AE3: Production | AF3: Profit
A4: 1 | B4: =E4+F4+I4+J4+M4+N4+Q4+R4+U4+V4+Y4+Z4+AC4+AD4 -> 370833.33 | C4: =G4+K4+O4+S4+W4+AA4+AE4 -> 0 | D4: =(H4+L4+P4+T4+X4+AB4+AF4)-B4 -> -370833.33 | E4: =('Project Overview'!$C$4/12) -> 266666.67 | F4: ='Project Overview'!$C$5/12 -> 104166.67 | G4: 0 | H4: =G4*($H$2-$F$2) -> 0
A5: 2 | B5: =E5+F5+I5+J5+M5+N5+Q5+R5+U5+V5+Y5+Z5+AC5+AD5 -> 370833.33 | C5: =G5+K5+O5+S5+W5+AA5+AE5 -> 0 | D5: =(H5+L5+P5+T5+X5+AB5+AF5)-B5 -> -370833.33 | E5: =('Project Overview'!$C$4/12) -> 266666.67 | F5: ='Project Overview'!$C$5/12 -> 104166.67 | G5: 0 | H5: =G5*($H$2-$F$2) -> 0
A6: 3 | B6: =E6+F6+I6+J6+M6+N6+Q6+R6+U6+V6+Y6+Z6+AC6+AD6 -> 370833.33 | C6: =G6+K6+O6+S6+W6+AA6+AE6 -> 0 | D6: =(H6+L6+P6+T6+X6+AB6+AF6)-B6 -> -370833.33 | E6: =('Project Overview'!$C$4/12) -> 266666.67 | F6: ='Project Overview'!$C$5/12 -> 104166.67 | G6: 0 | H6: =G6*($H$2-$F$2) -> 0
A7: 4 | B7: =E7+F7+I7+J7+M7+N7+Q7+R7+U7+V7+Y7+Z7+AC7+AD7 -> 370833.33 | C7: =G7+K7+O7+S7+W7+AA7+AE7 -> 0 | D7: =(H7+L7+P7+T7+X7+AB7+AF7)-B7 -> -370833.33 | E7: =('Project Overview'!$C$4/12) -> 266666.67 | F7: ='Project Overview'!$C$5/12 -> 104166.67 | G7: 0 | H7: =G7*($H$2-$F$2) -> 0
A8: 5 | B8: =E8+F8+I8+J8+M8+N8+Q8+R8+U8+V8+Y8+Z8+AC8+AD8 -> 370833.33 | C8: =G8+K8+O8+S8+W8+AA8+AE8 -> 0 | D8: =(H8+L8+P8+T8+X8+AB8+AF8)-B8 -> -370833.33 | E8: =('Project Overview'!$C$4/12) -> 266666.67 | F8: ='Project Overview'!$C$5/12 -> 104166.67 | G8: 0 | H8: =G8*($H$2-$F$2) -> 0
A9: 6 | B9: =E9+F9+I9+J9+M9+N9+Q9+R9+U9+V9+Y9+Z9+AC9+AD9 -> 370833.33 | C9: =G9+K9+O9+S9+W9+AA9+AE9 -> 0 | D9: =(H9+L9+P9+T9+X9+AB9+AF9)-B9 -> -370833.33 | E9: =('Project Overview'!$C$4/12) -> 266666.67 | F9: ='Project Overview'!$C$5/12 -> 104166.67 | G9: 0 | H9: =G9*($H$2-$F$2) -> 0
A10: 7 | B10: =E10+F10+I10+J10+M10+N10+Q10+R10+U10+V10+Y10+Z10+AC10+AD10 -> 370833.33 | C10: =G10+K10+O10+S10+W10+AA10+AE10 -> 0 | D10: =(H10+L10+P10+T10+X10+AB10+AF10)-B10 -> -370833.33 | E10: =('Project Overview'!$C$4/12) -> 266666.67 | F10: ='Project Overview'!$C$5/12 -> 104166.67 | G10: 0 | H10: =G10*($H$2-$F$2) -> 0
A11: 8 | B11: =E11+F11+I11+J11+M11+N11+Q11+R11+U11+V11+Y11+Z11+AC11+AD11 -> 370833.33 | C11: =G11+K11+O11+S11+W11+AA11+AE11 -> 0 | D11: =(H11+L11+P11+T11+X11+AB11+AF11)-B11 -> -370833.33 | E11: =('Project Overview'!$C$4/12) -> 266666.67 | F11: ='Project Overview'!$C$5/12 -> 104166.67 | G11: 0 | H11: =G11*($H$2-$F$2) -> 0
A12: 9 | B12: =E12+F12+I12+J12+M12+N12+Q12+R12+U12+V12+Y12+Z12+AC12+AD12 -> 370833.33 | C12: =G12+K12+O12+S12+W12+AA12+AE12 -> 0 | D12: =(H12+L12+P12+T12+X12+AB12+AF12)-B12 -> -370833.33 | E12: =('Project Overview'!$C$4/12) -> 266666.67 | F12: ='Project Overview'!$C$5/12 -> 104166.67 | G12: 0 | H12: =G12*($H$2-$F$2) -> 0
A13: 10 | B13: =E13+F13+I13+J13+M13+N13+Q13+R13+U13+V13+Y13+Z13+AC13+AD13 -> 370833.33 | C13: =G13+K13+O13+S13+W13+AA13+AE13 -> 0 | D13: =(H13+L13+P13+T13+X13+AB13+AF13)-B13 -> -370833.33 | E13: =('Project Overview'!$C$4/12) -> 266666.67 | F13: ='Project Overview'!$C$5/12 -> 104166.67 | G13: 0 | H13: =G13*($H$2-$F$2) -> 0
A14: 11 | B14: =E14+F14+I14+J14+M14+N14+Q14+R14+U14+V14+Y14+Z14+AC14+AD14 -> 370833.33 | C14: =G14+K14+O14+S14+W14+AA14+AE14 -> 0 | D14: =(H14+L14+P14+T14+X14+AB14+AF14)-B14 -> -370833.33 | E14: =('Project Overview'!$C$4/12) -> 266666.67 | F14: ='Project Overview'!$C$5/12 -> 104166.67 | G14: 0 | H14: =G14*($H$2-$F$2) -> 0
A15: 12 | B15: =E15+F15+I15+J15+M15+N15+Q15+R15+U15+V15+Y15+Z15+AC15+AD15 -> 370833.33 | C15: =G15+K15+O15+S15+W15+AA15+AE15 -> 0 | D15: =(H15+L15+P15+T15+X15+AB15+AF15)-B15 -> -370833.33 | E15: =('Project Overview'!$C$4/12) -> 266666.67 | F15: ='Project Overview'!$C$5/12 -> 104166.67 | G15: 0 | H15: =G15*($H$2-$F$2) -> 0
A16: Total | B16: =SUM(B4:B15) -> 4450000 | C16: =SUM(C4:C15) -> 0 | D16: =SUM(D4:D15) -> -4450000 | E16: =SUM(E4:E15) -> 3200000 | F16: =SUM(F4:F15) -> 1250000 | G16: =SUM(G4:G15) -> 0 | H16: =SUM(H4:H15) -> 0
A17: 13 | B17: =E17+F17+I17+J17+M17+N17+Q17+R17+U17+V17+Y17+Z17+AC17+AD17 -> 569269.67 | C17: =G17+K17+O17+S17+W17+AA17+AE17 -> 7500 | D17: =(H17+L17+P17+T17+X17+AB17+AF17)-B17 -> -401418.68 | E17: ='Project Overview'!$D$4/12 -> 83333.333 | F17: ='Project Overview'!$D$5/12 -> 147828.67 | G17: 7500 | H17: =G17*($H$2-$F$2) -> 167850.99 | I17: ='Project Overview'!$C$12/12 -> 270000 | J17: ='Project Overview'!$C$13/12 -> 68107.667 | K17: 0 | L17: =K17*($L$2-$J$2) -> 0
A18: 14 | B18: =E18+F18+I18+J18+M18+N18+Q18+R18+U18+V18+Y18+Z18+AC18+AD18 -> 569269.67 | C18: =G18+K18+O18+S18+W18+AA18+AE18 -> 7500 | D18: =(H18+L18+P18+T18+X18+AB18+AF18)-B18 -> -401418.68 | E18: ='Project Overview'!$D$4/12 -> 83333.333 | F18: ='Project Overview'!$D$5/12 -> 147828.67 | G18: 7500 | H18: =G18*($H$2-$F$2) -> 167850.99 | I18: ='Project Overview'!$C$12/12 -> 270000 | J18: ='Project Overview'!$C$13/12 -> 68107.667 | K18: 0 | L18: =K18*($L$2-$J$2) -> 0
A19: 15 | B19: =E19+F19+I19+J19+M19+N19+Q19+R19+U19+V19+Y19+Z19+AC19+AD19 -> 569269.67 | C19: =G19+K19+O19+S19+W19+AA19+AE19 -> 7500 | D19: =(H19+L19+P19+T19+X19+AB19+AF19)-B19 -> -401418.68 | E19: ='Project Overview'!$D$4/12 -> 83333.333 | F19: ='Project Overview'!$D$5/12 -> 147828.67 | G19: 7500 | H19: =G19*($H$2-$F$2) -> 167850.99 | I19: ='Project Overview'!$C$12/12 -> 270000 | J19: ='Project Overview'!$C$13/12 -> 68107.667 | K19: 0 | L19: =K19*($L$2-$J$2) -> 0
A20: 16 | B20: =E20+F20+I20+J20+M20+N20+Q20+R20+U20+V20+Y20+Z20+AC20+AD20 -> 569269.67 | C20: =G20+K20+O20+S20+W20+AA20+AE20 -> 7500 | D20: =(H20+L20+P20+T20+X20+AB20+AF20)-B20 -> -401418.68 | E20: ='Project Overview'!$D$4/12 -> 83333.333 | F20: ='Project Overview'!$D$5/12 -> 147828.67 | G20: 7500 | H20: =G20*($H$2-$F$2) -> 167850.99 | I20: ='Project Overview'!$C$12/12 -> 270000 | J20: ='Project Overview'!$C$13/12 -> 68107.667 | K20: 0 | L20: =K20*($L$2-$J$2) -> 0
A21: 17 | B21: =E21+F21+I21+J21+M21+N21+Q21+R21+U21+V21+Y21+Z21+AC21+AD21 -> 569269.67 | C21: =G21+K21+O21+S21+W21+AA21+AE21 -> 7500 | D21: =(H21+L21+P21+T21+X21+AB21+AF21)-B21 -> -401418.68 | E21: ='Project Overview'!$D$4/12 -> 83333.333 | F21: ='Project Overview'!$D$5/12 -> 147828.67 | G21: 7500 | H21: =G21*($H$2-$F$2) -> 167850.99 | I21: ='Project Overview'!$C$12/12 -> 270000 | J21: ='Project Overview'!$C$13/12 -> 68107.667 | K21: 0 | L21: =K21*($L$2-$J$2) -> 0
A22: 18 | B22: =E22+F22+I22+J22+M22+N22+Q22+R22+U22+V22+Y22+Z22+AC22+AD22 -> 569269.67 | C22: =G22+K22+O22+S22+W22+AA22+AE22 -> 7500 | D22: =(H22+L22+P22+T22+X22+AB22+AF22)-B22 -> -401418.68 | E22: ='Project Overview'!$D$4/12 -> 83333.333 | F22: ='Project Overview'!$D$5/12 -> 147828.67 | G22: 7500 | H22: =G22*($H$2-$F$2) -> 167850.99 | I22: ='Project Overview'!$C$12/12 -> 270000 | J22: ='Project Overview'!$C$13/12 -> 68107.667 | K22: 0 | L22: =K22*($L$2-$J$2) -> 0
A23: 19 | B23: =E23+F23+I23+J23+M23+N23+Q23+R23+U23+V23+Y23+Z23+AC23+AD23 -> 569269.67 | C23: =G23+K23+O23+S23+W23+AA23+AE23 -> 37500 | D23: =(H23+L23+P23+T23+X23+AB23+AF23)-B23 -> 269985.27 | E23: ='Project Overview'!$D$4/12 -> 83333.333 | F23: ='Project Overview'!$D$5/12 -> 147828.67 | G23: 37500 | H23: =G23*($H$2-$F$2) -> 839254.93 | I23: ='Project Overview'!$C$12/12 -> 270000 | J23: ='Project Overview'!$C$13/12 -> 68107.667 | K23: 0 | L23: =K23*($L$2-$J$2) -> 0
A24: 20 | B24: =E24+F24+I24+J24+M24+N24+Q24+R24+U24+V24+Y24+Z24+AC24+AD24 -> 569269.67 | C24: =G24+K24+O24+S24+W24+AA24+AE24 -> 37500 | D24: =(H24+L24+P24+T24+X24+AB24+AF24)-B24 -> 269985.27 | E24: ='Project Overview'!$D$4/12 -> 83333.333 | F24: ='Project Overview'!$D$5/12 -> 147828.67 | G24: 37500 | H24: =G24*($H$2-$F$2) -> 839254.93 | I24: ='Project Overview'!$C$12/12 -> 270000 | J24: ='Project Overview'!$C$13/12 -> 68107.667 | K24: 0 | L24: =K24*($L$2-$J$2) -> 0
A25: 21 | B25: =E25+F25+I25+J25+M25+N25+Q25+R25+U25+V25+Y25+Z25+AC25+AD25 -> 569269.67 | C25: =G25+K25+O25+S25+W25+AA25+AE25 -> 37500 | D25: =(H25+L25+P25+T25+X25+AB25+AF25)-B25 -> 269985.27 | E25: ='Project Overview'!$D$4/12 -> 83333.333 | F25: ='Project Overview'!$D$5/12 -> 147828.67 | G25: 37500 | H25: =G25*($H$2-$F$2) -> 839254.93 | I25: ='Project Overview'!$C$12/12 -> 270000 | J25: ='Project Overview'!$C$13/12 -> 68107.667 | K25: 0 | L25: =K25*($L$2-$J$2) -> 0
A26: 22 | B26: =E26+F26+I26+J26+M26+N26+Q26+R26+U26+V26+Y26+Z26+AC26+AD26 -> 569269.67 | C26: =G26+K26+O26+S26+W26+AA26+AE26 -> 37500 | D26: =(H26+L26+P26+T26+X26+AB26+AF26)-B26 -> 269985.27 | E26: ='Project Overview'!$D$4/12 -> 83333.333 | F26: ='Project Overview'!$D$5/12 -> 147828.67 | G26: 37500 | H26: =G26*($H$2-$F$2) -> 839254.93 | I26: ='Project Overview'!$C$12/12 -> 270000 | J26: ='Project Overview'!$C$13/12 -> 68107.667 | K26: 0 | L26: =K26*($L$2-$J$2) -> 0
A27: 23 | B27: =E27+F27+I27+J27+M27+N27+Q27+R27+U27+V27+Y27+Z27+AC27+AD27 -> 569269.67 | C27: =G27+K27+O27+S27+W27+AA27+AE27 -> 37500 | D27: =(H27+L27+P27+T27+X27+AB27+AF27)-B27 -> 269985.27 | E27: ='Project Overview'!$D$4/12 -> 83333.333 | F27: ='Project Overview'!$D$5/12 -> 147828.67 | G27: 37500 | H27: =G27*($H$2-$F$2) -> 839254.93 | I27: ='Project Overview'!$C$12/12 -> 270000 | J27: ='Project Overview'!$C$13/12 -> 68107.667 | K27: 0 | L27: =K27*($L$2-$J$2) -> 0
A28: 24 | B28: =E28+F28+I28+J28+M28+N28+Q28+R28+U28+V28+Y28+Z28+AC28+AD28 -> 569269.67 | C28: =G28+K28+O28+S28+W28+AA28+AE28 -> 37500 | D28: =(H28+L28+P28+T28+X28+AB28+AF28)-B28 -> 269985.27 | E28: ='Project Overview'!$D$4/12 -> 83333.333 | F28: ='Project Overview'!$D$5/12 -> 147828.67 | G28: 37500 | H28: =G28*($H$2-$F$2) -> 839254.93 | I28: ='Project Overview'!$C$12/12 -> 270000 | J28: ='Project Overview'!$C$13/12 -> 68107.667 | K28: 0 | L28: =K28*($L$2-$J$2) -> 0
A29: Total | B29: =SUM(B17:B28) -> 6831236 | C29: =SUM(C17:C28) -> 270000 | D29: =SUM(D17:D28) -> -788600.47 | E29: =SUM(E17:E28) -> 1000000 | F29: =SUM(F17:F28) -> 1773944 | G29: =SUM(G17:G28) -> 270000 | H29: =SUM(H17:H28) -> 6042635.5 | I29: =SUM(I17:I28) -> 3240000 | ... L29: =SUM(L17:L28) -> 0
A30: 25 | B30: =E30+F30+I30+J30+M30+N30+Q30+R30+U30+V30+Y30+Z30+AC30+AD30 -> 1206545.1 | C30: =G30+K30+O30+S30+W30+AA30+AE30 -> 75000 | D30: =(H30+L30+P30+T30+X30+AB30+AF30)-B30 -> 471964.76 | E30: =('Project Overview'!$E$4/12) -> 125000 | F30: ='Project Overview'!$E$5/12 -> 190158.65 | G30: 37500 | H30: =G30*($H$2-$F$2) -> 839254.93 | I30: ='Project Overview'!$D$12/12 -> 125000 | J30: ='Project Overview'!$D$13/12 -> 90171.117 | K30: 37500 | L30: =K30*($L$2-$J$2) -> 839254.93 | M30: ='Project Overview'!$C$12/12 -> 270000 | N30: ='Project Overview'!$C$13/12 -> 68107.667 | O30: 0 | P30: =O30*($P$2-$N$2) -> 0 | Q30: ='Project Overview'!$C$12/12 -> 270000 | R30: ='Project Overview'!$C$13/12 -> 68107.667 | S30: 0 | T30: =S30*($T$2-$R$2) -> 0
A31: 26 | B31: =E31+F31+I31+J31+M31+N31+Q31+R31+U31+V31+Y31+Z31+AC31+AD31 -> 1206545.1 | C31: =G31+K31+O31+S31+W31+AA31+AE31 -> 75000 | D31: =(H31+L31+P31+T31+X31+AB31+AF31)-B31 -> 471964.76 | E31: =('Project Overview'!$E$4/12) -> 125000 | F31: ='Project Overview'!$E$5/12 -> 190158.65 | G31: 37500 | H31: =G31*($H$2-$F$2) -> 839254.93 | I31: ='Project Overview'!$D$12/12 -> 125000 | J31: ='Project Overview'!$D$13/12 -> 90171.117 | K31: 37500 | L31: =K31*($L$2-$J$2) -> 839254.93 | M31: ='Project Overview'!$C$12/12 -> 270000 | N31: ='Project Overview'!$C$13/12 -> 68107.667 | O31: 0 | P31: =O31*($P$2-$N$2) -> 0 | Q31: ='Project Overview'!$C$12/12 -> 270000 | R31: ='Project Overview'!$C$13/12 -> 68107.667 | S31: 0 | T31: =S31*($T$2-$R$2) -> 0
A32: 27 | B32: =E32+F32+I32+J32+M32+N32+Q32+R32+U32+V32+Y32+Z32+AC32+AD32 -> 1206545.1 | C32: =G32+K32+O32+S32+W32+AA32+AE32 -> 75000 | D32: =(H32+L32+P32+T32+X32+AB32+AF32)-B32 -> 471964.76 | E32: =('Project Overview'!$E$4/12) -> 125000 | F32: ='Project Overview'!$E$5/12 -> 190158.65 | G32: 37500 | H32: =G32*($H$2-$F$2) -> 839254.93 | I32: ='Project Overview'!$D$12/12 -> 125000 | J32: ='Project Overview'!$D$13/12 -> 90171.117 | K32: 37500 | L32: =K32*($L$2-$J$2) -> 839254.93 | M32: ='Project Overview'!$C$12/12 -> 270000 | N32: ='Project Overview'!$C$13/12 -> 68107.667 | O32: 0 | P32: =O32*($P$2-$N$2) -> 0 | Q32: ='Project Overview'!$C$12/12 -> 270000 | R32: ='Project Overview'!$C$13/12 -> 68107.667 | S32: 0 | T32: =S32*($T$2-$R$2) -> 0
A33: 28 | B33: =E33+F33+I33+J33+M33+N33+Q33+R33+U33+V33+Y33+Z33+AC33+AD33 -> 1206545.1 | C33: =G33+K33+O33+S33+W33+AA33+AE33 -> 75000 | D33: =(H33+L33+P33+T33+X33+AB33+AF33)-B33 -> 471964.76 | E33: =('Project Overview'!$E$4/12) -> 125000 | F33: ='Project Overview'!$E$5/12 -> 190158.65 | G33: 37500 | H33: =G33*($H$2-$F$2) -> 839254.93 | I33: ='Project Overview'!$D$12/12 -> 125000 | J33: ='Project Overview'!$D$13/12 -> 90171.117 | K33: 37500 | L33: =K33*($L$2-$J$2) -> 839254.93 | M33: ='Project Overview'!$C$12/12 -> 270000 | N33: ='Project Overview'!$C$13/12 -> 68107.667 | O33: 0 | P33: =O33*($P$2-$N$2) -> 0 | Q33: ='Project Overview'!$C$12/12 -> 270000 | R33: ='Project Overview'!$C$13/12 -> 68107.667 | S33: 0 | T33: =S33*($T$2-$R$2) -> 0
A34: 29 | B34: =E34+F34+I34+J34+M34+N34+Q34+R34+U34+V34+Y34+Z34+AC34+AD34 -> 1206545.1 | C34: =G34+K34+O34+S34+W34+AA34+AE34 -> 75000 | D34: =(H34+L34+P34+T34+X34+AB34+AF34)-B34 -> 471964.76 | E34: =('Project Overview'!$E$4/12) -> 125000 | F34: ='Project Overview'!$E$5/12 -> 190158.65 | G34: 37500 | H34: =G34*($H$2-$F$2) -> 839254.93 | I34: ='Project Overview'!$D$12/12 -> 125000 | J34: ='Project Overview'!$D$13/12 -> 90171.117 | K34: 37500 | L34: =K34*($L$2-$J$2) -> 839254.93 | M34: ='Project Overview'!$C$12/12 -> 270000 | N34: ='Project Overview'!$C$13/12 -> 68107.667 | O34: 0 | P34: =O34*($P$2-$N$2) -> 0 | Q34: ='Project Overview'!$C$12/12 -> 270000 | R34: ='Project Overview'!$C$13/12 -> 68107.667 | S34: 0 | T34: =S34*($T$2-$R$2) -> 0
A35: 30 | B35: =E35+F35+I35+J35+M35+N35+Q35+R35+U35+V35+Y35+Z35+AC35+AD35 -> 1206545.1 | C35: =G35+K35+O35+S35+W35+AA35+AE35 -> 75000 | D35: =(H35+L35+P35+T35+X35+AB35+AF35)-B35 -> 471964.76 | E35: =('Project Overview'!$E$4/12) -> 125000 | F35: ='Project Overview'!$E$5/12 -> 190158.65 | G35: 37500 | H35: =G35*($H$2-$F$2) -> 839254.93 | I35: ='Project Overview'!$D$12/12 -> 125000 | J35: ='Project Overview'!$D$13/12 -> 90171.117 | K35: 37500 | L35: =K35*($L$2-$J$2) -> 839254.93 | M35: ='Project Overview'!$C$12/12 -> 270000 | N35: ='Project Overview'!$C$13/12 -> 68107.667 | O35: 0 | P35: =O35*($P$2-$N$2) -> 0 | Q35: ='Project Overview'!$C$12/12 -> 270000 | R35: ='Project Overview'!$C$13/12 -> 68107.667 | S35: 0 | T35: =S35*($T$2-$R$2) -> 0
A36: 31 | B36: =E36+F36+I36+J36+M36+N36+Q36+R36+U36+V36+Y36+Z36+AC36+AD36 -> 1206545.1 | C36: =G36+K36+O36+S36+W36+AA36+AE36 -> 112500 | D36: =(H36+L36+P36+T36+X36+AB36+AF36)-B36 -> 1311219.7 | E36: =('Project Overview'!$E$4/12) -> 125000 | F36: ='Project Overview'!$E$5/12 -> 190158.65 | G36: 75000 | H36: =G36*($H$2-$F$2) -> 1678509.9 | I36: ='Project Overview'!$D$12/12 -> 125000 | J36: ='Project Overview'!$D$13/12 -> 90171.117 | K36: 37500 | L36: =K36*($L$2-$J$2) -> 839254.93 | M36: ='Project Overview'!$C$12/12 -> 270000 | N36: ='Project Overview'!$C$13/12 -> 68107.667 | O36: 0 | P36: =O36*($P$2-$N$2) -> 0 | Q36: ='Project Overview'!$C$12/12 -> 270000 | R36: ='Project Overview'!$C$13/12 -> 68107.667 | S36: 0 | T36: =S36*($T$2-$R$2) -> 0
A37: 32 | B37: =E37+F37+I37+J37+M37+N37+Q37+R37+U37+V37+Y37+Z37+AC37+AD37 -> 1206545.1 | C37: =G37+K37+O37+S37+W37+AA37+AE37 -> 112500 | D37: =(H37+L37+P37+T37+X37+AB37+AF37)-B37 -> 1311219.7 | E37: =('Project Overview'!$E$4/12) -> 125000 | F37: ='Project Overview'!$E$5/12 -> 190158.65 | G37: 75000 | H37: =G37*($H$2-$F$2) -> 1678509.9 | I37: ='Project Overview'!$D$12/12 -> 125000 | J37: ='Project Overview'!$D$13/12 -> 90171.117 | K37: 37500 | L37: =K37*($L$2-$J$2) -> 839254.93 | M37: ='Project Overview'!$C$12/12 -> 270000 | N37: ='Project Overview'!$C$13/12 -> 68107.667 | O37: 0 | P37: =O37*($P$2-$N$2) -> 0 | Q37: ='Project Overview'!$C$12/12 -> 270000 | R37: ='Project Overview'!$C$13/12 -> 68107.667 | S37: 0 | T37: =S37*($T$2-$R$2) -> 0
A38: 33 | B38: =E38+F38+I38+J38+M38+N38+Q38+R38+U38+V38+Y38+Z38+AC38+AD38 -> 1206545.1 | C38: =G38+K38+O38+S38+W38+AA38+AE38 -> 112500 | D38: =(H38+L38+P38+T38+X38+AB38+AF38)-B38 -> 1311219.7 | E38: =('Project Overview'!$E$4/12) -> 125000 | F38: ='Project Overview'!$E$5/12 -> 190158.65 | G38: 75000 | H38: =G38*($H$2-$F$2) -> 1678509.9 | I38: ='Project Overview'!$D$12/12 -> 125000 | J38: ='Project Overview'!$D$13/12 -> 90171.117 | K38: 37500 | L38: =K38*($L$2-$J$2) -> 839254.93 | M38: ='Project Overview'!$C$12/12 -> 270000 | N38: ='Project Overview'!$C$13/12 -> 68107.667 | O38: 0 | P38: =O38*($P$2-$N$2) -> 0 | Q38: ='Project Overview'!$C$12/12 -> 270000 | R38: ='Project Overview'!$C$13/12 -> 68107.667 | S38: 0 | T38: =S38*($T$2-$R$2) -> 0
A39: 34 | B39: =E39+F39+I39+J39+M39+N39+Q39+R39+U39+V39+Y39+Z39+AC39+AD39 -> 1206545.1 | C39: =G39+K39+O39+S39+W39+AA39+AE39 -> 112500 | D39: =(H39+L39+P39+T39+X39+AB39+AF39)-B39 -> 1311219.7 | E39: =('Project Overview'!$E$4/12) -> 125000 | F39: ='Project Overview'!$E$5/12 -> 190158.65 | G39: 75000 | H39: =G39*($H$2-$F$2) -> 1678509.9 | I39: ='Project Overview'!$D$12/12 -> 125000 | J39: ='Project Overview'!$D$13/12 -> 90171.117 | K39: 37500 | L39: =K39*($L$2-$J$2) -> 839254.93 | M39: ='Project Overview'!$C$12/12 -> 270000 | N39: ='Project Overview'!$C$13/12 -> 68107.667 | O39: 0 | P39: =O39*($P$2-$N$2) -> 0 | Q39: ='Project Overview'!$C$12/12 -> 270000 | R39: ='Project Overview'!$C$13/12 -> 68107.667 | S39: 0 | T39: =S39*($T$2-$R$2) -> 0
A40: 35 | B40: =E40+F40+I40+J40+M40+N40+Q40+R40+U40+V40+Y40+Z40+AC40+AD40 -> 1206545.1 | C40: =G40+K40+O40+S40+W40+AA40+AE40 -> 112500 | D40: =(H40+L40+P40+T40+X40+AB40+AF40)-B40 -> 1311219.7 | E40: =('Project Overview'!$E$4/12) -> 125000 | F40: ='Project Overview'!$E$5/12 -> 190158.65 | G40: 75000 | H40: =G40*($H$2-$F$2) -> 1678509.9 | I40: ='Project Overview'!$D$12/12 -> 125000 | J40: ='Project Overview'!$D$13/12 -> 90171.117 | K40: 37500 | L40: =K40*($L$2-$J$2) -> 839254.93 | M40: ='Project Overview'!$C$12/12 -> 270000 | N40: ='Project Overview'!$C$13/12 -> 68107.667 | O40: 0 | P40: =O40*($P$2-$N$2) -> 0 | Q40: ='Project Overview'!$C$12/12 -> 270000 | R40: ='Project Overview'!$C$13/12 -> 68107.667 | S40: 0 | T40: =S40*($T$2-$R$2) -> 0
...

Sheet Financials
B1: Year Counter | E1: 1 | F1: 1 | G1: 1 | H1: 1 | I1: 1 | J1: 1 | K1: 1 | L1: 1 | M1: 1 | N1: 1 | O1: 1 | P1: 1 | Q1: 2 | R1: 2 | S1: 2 | T1: 2 | U1: 2 | V1: 2 | W1: 2 | X1: 2 | Y1: 2 | Z1: 2 | AA1: 2 | AB1: 2 | AC1: 3 | AD1: 3 | AE1: 3 | AF1: 3 | AG1: 3 | AH1: 3 | AI1: 3 | AJ1: 3 | AK1: 3 | AL1: 3 | AM1: 3 | AN1: 3 | AO1: 4 | AP1: 4 | AQ1: 4 | AR1: 4 | AS1: 4 | AT1: 4 | AU1: 4 | AV1: 4 | AW1: 4 | AX1: 4 | AY1: 4 | AZ1: 4 | BA1: 5 | BB1: 5 | BC1: 5 | BD1: 5 | BE1: 5 | BF1: 5 | BG1: 5 | BH1: 5 | BI1: 5 | BJ1: 5 | BK1: 5 | BL1: 5 | BM1: 6 | BN1: 6 | BO1: 6 | BP1: 6 | BQ1: 6 | BR1: 6 | BS1: 6 | BT1: 6 | BU1: 6 | BV1: 6 | BW1: 6 | BX1: 6 | BY1: 7 | BZ1: 7 | CA1: 7 | CB1: 7 | CC1: 7 | CD1: 7 | CE1: 7 | CF1: 7 | CG1: 7 | CH1: 7 | CI1: 7 | CJ1: 7
B2: Year | E2: =2024+E1 -> 2025 | F2: =2024+F1 -> 2025 | G2: =2024+G1 -> 2025 | H2: =2024+H1 -> 2025 | I2: =2024+I1 -> 2025 | J2: =2024+J1 -> 2025 | K2: =2024+K1 -> 2025 | L2: =2024+L1 -> 2025 | ... CJ2: =2024+CJ1 -> 2031
B3: Month Counter | E3: 1 | F3: 2 | G3: 3 | H3: 4 | I3: 5 | J3: 6 | K3: 7 | L3: 8 | M3: 9 | N3: 10 | O3: 11 | P3: 12 | Q3: 13 | R3: 14 | S3: 15 | T3: 16 | U3: 17 | V3: 18 | W3: 19 | X3: 20 | Y3: 21 | Z3: 22 | AA3: 23 | AB3: 24 | AC3: 25 | AD3: 26 | AE3: 27 | AF3: 28 | AG3: 29 | AH3: 30 | AI3: 31 | AJ3: 32 | AK3: 33 | AL3: 34 | AM3: 35 | AN3: 36 | AO3: 37 | AP3: 38 | AQ3: 39 | AR3: 40 | AS3: 41 | AT3: 42 | AU3: 43 | AV3: 44 | AW3: 45 | AX3: 46 | AY3: 47 | AZ3: 48 | BA3: 49 | BB3: 50 | BC3: 51 | BD3: 52 | BE3: 53 | BF3: 54 | BG3: 55 | BH3: 56 | BI3: 57 | BJ3: 58 | BK3: 59 | BL3: 60 | BM3: 61 | BN3: 62 | BO3: 63 | BP3: 64 | BQ3: 65 | BR3: 66 | BS3: 67 | BT3: 68 | BU3: 69 | BV3: 70 | BW3: 71 | BX3: 72 | BY3: 73 | BZ3: 74 | CA3: 75 | CB3: 76 | CC3: 77 | CD3: 78 | CE3: 79 | CF3: 80 | CG3: 81 | CH3: 82 | CI3: 83 | CJ3: 84
B4: Date | E4: 45839 | F4: 45870 | G4: 45901 | H4: 45931 | I4: 45962 | J4: 45992 | K4: 46023 | L4: 46054 | M4: 46082 | N4: 46113 | O4: 46143 | P4: 46174 | Q4: 46204 | R4: 8/1/0202 | S4: 46266 | T4: 46204 | U4: 8/1/0202 | V4: 46266 | W4: 46204 | X4: 8/1/0202 | Y4: 46266 | Z4: 46204 | AA4: 8/1/0202 | AB4: 46266 | AC4: 46569 | AD4: 46600 | AE4: 46631 | AF4: 46661 | AG4: 46692 | AH4: 46722 | AI4: 46753 | AJ4: 46784 | AK4: 46813 | AL4: 46844 | AM4: 46874 | AN4: 46905 | AO4: 46935 | AP4: 46966 | AQ4: 46997 | AR4: 47027 | AS4: 47058 | AT4: 47088 | AU4: 47119 | AV4: 47150 | AW4: 47178 | AX4: 47209 | AY4: 47239 | AZ4: 47270 | BA4: 47300 | BB4: 47331 | BC4: 47362 | BD4: 47392 | BE4: 47423 | BF4: 47453 | BG4: 47484 | BH4: 47515 | BI4: 47543 | BJ4: 47574 | BK4: 47604 | BL4: 47635 | BM4: 47665 | BN4: 47696 | BO4: 47727 | BP4: 47757 | BQ4: 47788 | BR4: 47818 | BS4: 47849 | BT4: 47880 | BU4: 47908 | BV4: 47939 | BW4: 47969 | BX4: 48000 | BY4: 48030 | BZ4: 48061 | CA4: 48092 | CB4: 48122 | CC4: 48153 | CD4: 48183 | CE4: 48214 | CF4: 48245 | CG4: 48274 | CH4: 48305 | CI4: 48335 | CJ4: 48366
B6: Income Statement
B8: Revenue | E8: =SUM(E9:E15) -> 0 | F8: =SUM(F9:F15) -> 0 | G8: =SUM(G9:G15) -> 0 | H8: =SUM(H9:H15) -> 0 | I8: =SUM(I9:I15) -> 0 | J8: =SUM(J9:J15) -> 0 | K8: =SUM(K9:K15) -> 0 | L8: =SUM(L9:L15) -> 0 | ... CJ8: =SUM(CJ9:CJ15) -> 22500000
B9: GH2x - OKC | E9: ='Model Assumptions'!G15 -> 0 | F9: ='Model Assumptions'!H15 -> 0 | G9: ='Model Assumptions'!I15 -> 0 | H9: ='Model Assumptions'!J15 -> 0 | I9: ='Model Assumptions'!K15 -> 0 | J9: ='Model Assumptions'!L15 -> 0 | K9: ='Model Assumptions'!M15 -> 0 | L9: ='Model Assumptions'!N15 -> 0 | ... CJ9: ='Model Assumptions'!CL15 -> 1875000
B10: GH2x2 - Tulsa | E10: ='Model Assumptions'!G23 -> 0 | F10: ='Model Assumptions'!H23 -> 0 | G10: ='Model Assumptions'!I23 -> 0 | H10: ='Model Assumptions'!J23 -> 0 | I10: ='Model Assumptions'!K23 -> 0 | J10: ='Model Assumptions'!L23 -> 0 | K10: ='Model Assumptions'!M23 -> 0 | L10: ='Model Assumptions'!N23 -> 0 | ... CJ10: ='Model Assumptions'!CL23 -> 1875000
B11: GH2x3 - Seattle | E11: ='Model Assumptions'!G31 -> 0 | F11: ='Model Assumptions'!H31 -> 0 | G11: ='Model Assumptions'!I31 -> 0 | H11: ='Model Assumptions'!J31 -> 0 | I11: ='Model Assumptions'!K31 -> 0 | J11: ='Model Assumptions'!L31 -> 0 | K11: ='Model Assumptions'!M31 -> 0 | L11: ='Model Assumptions'!N31 -> 0 | ... CJ11: ='Model Assumptions'!CL31 -> 1875000
B12: GH2x4 - Spokane | E12: ='Model Assumptions'!G39 -> 0 | F12: ='Model Assumptions'!H39 -> 0 | G12: ='Model Assumptions'!I39 -> 0 | H12: ='Model Assumptions'!J39 -> 0 | I12: ='Model Assumptions'!K39 -> 0 | J12: ='Model Assumptions'!L39 -> 0 | K12: ='Model Assumptions'!M39 -> 0 | L12: ='Model Assumptions'!N39 -> 0 | ... CJ12: ='Model Assumptions'!CL39 -> 1875000
B13: GH2x5 - Albuquerque | E13: ='Model Assumptions'!G47 -> 0 | F13: ='Model Assumptions'!H47 -> 0 | G13: ='Model Assumptions'!I47 -> 0 | H13: ='Model Assumptions'!J47 -> 0 | I13: ='Model Assumptions'!K47 -> 0 | J13: ='Model Assumptions'!L47 -> 0 | K13: ='Model Assumptions'!M47 -> 0 | L13: ='Model Assumptions'!N47 -> 0 | ... CJ13: ='Model Assumptions'!CL47 -> 1875000
B14: GH2x6 - Des Moines | E14: ='Model Assumptions'!G55 -> 0 | F14: ='Model Assumptions'!H55 -> 0 | G14: ='Model Assumptions'!I55 -> 0 | H14: ='Model Assumptions'!J55 -> 0 | I14: ='Model Assumptions'!K55 -> 0 | J14: ='Model Assumptions'!L55 -> 0 | K14: ='Model Assumptions'!M55 -> 0 | L14: ='Model Assumptions'!N55 -> 0 | ... CJ14: ='Model Assumptions'!CL55 -> 1875000
B15: GH2x7-12 | E15: ='Model Assumptions'!G63 -> 0 | F15: ='Model Assumptions'!H63 -> 0 | G15: ='Model Assumptions'!I63 -> 0 | H15: ='Model Assumptions'!J63 -> 0 | I15: ='Model Assumptions'!K63 -> 0 | J15: ='Model Assumptions'!L63 -> 0 | K15: ='Model Assumptions'!M63 -> 0 | L15: ='Model Assumptions'!N63 -> 0 | ... CJ15: ='Model Assumptions'!CL63 -> 11250000
B17: COGS | E17: ='Model Assumptions'!G32+'Model Assumptions'!G40+'Model Assumptions'!G48+'Model Assumptions'!G56+'Model Assumptions'!G64 -> 0 | F17: ='Model Assumptions'!H32+'Model Assumptions'!H40+'Model Assumptions'!H48+'Model Assumptions'!H56+'Model Assumptions'!H64 -> 0 | G17: ='Model Assumptions'!I32+'Model Assumptions'!I40+'Model Assumptions'!I48+'Model Assumptions'!I56+'Model Assumptions'!I64 -> 0 | H17: ='Model Assumptions'!J32+'Model Assumptions'!J40+'Model Assumptions'!J48+'Model Assumptions'!J56+'Model Assumptions'!J64 -> 0 | I17: ='Model Assumptions'!K32+'Model Assumptions'!K40+'Model Assumptions'!K48+'Model Assumptions'!K56+'Model Assumptions'!K64 -> 0 | J17: ='Model Assumptions'!L32+'Model Assumptions'!L40+'Model Assumptions'!L48+'Model Assumptions'!L56+'Model Assumptions'!L64 -> 0 | K17: ='Model Assumptions'!M32+'Model Assumptions'!M40+'Model Assumptions'!M48+'Model Assumptions'!M56+'Model Assumptions'!M64 -> 0 | L17: ='Model Assumptions'!N32+'Model Assumptions'!N40+'Model Assumptions'!N48+'Model Assumptions'!N56+'Model Assumptions'!N64 -> 0 | ... CJ17: ='Model Assumptions'!CL32+'Model Assumptions'!CL40+'Model Assumptions'!CL48+'Model Assumptions'!CL56+'Model Assumptions'!CL64 -> 1964901.3
