Workbook
Name BenefitsLoading: 'Base Case Inputs'!$B$75
Name CostInflation: 'Base Case Inputs'!$B$88
Name DebtRate: 'Base Case Inputs'!$B$62
Name H2_Price: 'Base Case Inputs'!$B$18
Name OtherOpExRate: 'Base Case Inputs'!$B$77
Name PF_Rate: 'Base Case Inputs'!$B$67
Name ProfFeesRate: 'Base Case Inputs'!$B$76
Name ServiceAttachRate: 'Base Case Inputs'!$B$129
Name ServiceEscalator: 'Base Case Inputs'!$B$132
Name T125_ASP: 'Base Case Inputs'!$B$33
Name T25_ASP: 'Base Case Inputs'!$B$27
Name T2500_ASP: 'Base Case Inputs'!$B$232
Name TaxRate: 'Base Case Inputs'!$B$71

Sheet Overview
B2: ● CONFIDENTIAL · SEED ROUND
B3: Tobe Energy — Financial Model
B4: $10M Seed Round · Green Hydrogen Electrolyzers · 92% System Efficiency · v8.5.2 · March 2026
B7: FY7 REVENUE | E7: FY7 EBITDA | H7: FY7 NET INCOME | K7: FY7 CASH
B8: $467M | E8: $278M | H8: $202M | K8: $921M
B9: 12 facilities · H₂ + Equip + Svc | E9: 59.4% margin · EBITDA+ from Y2 | H9: 43.3% net margin | K9: Self-funding by FY5
B11: ① | C11: REVENUE GROWTH — 7-YEAR PROJECTION ($M)
C12: FY1 | D12: FY2 | E12: FY3 | F12: FY4 | G12: FY5 | H12: FY6 | I12: FY7
B13: H₂ Production | C13: 0 | D13: 11.81 | E13: 77.81 | F13: 141.56 | G13: 210.94 | H13: 264.38 | I13: 270
B14: Equipment Sales | C14: 0.88 | D14: 4.3 | E14: 10.26 | F14: 33.77 | G14: 73.95 | H14: 129.13 | I14: 186.06
B15: Services | C15: 0 | D15: 0.02 | E15: 0.25 | F15: 0.85 | G15: 2.43 | H15: 5.87 | I15: 10.86
B16: EBITDA | C16: -2.65 | D16: 3.75 | E16: 54.91 | F16: 110.52 | G16: 177.64 | H16: 243.1 | I16: 277.57
B17: Net Income | C17: -2.78 | D17: 3.36 | E17: 44.78 | F17: 85.56 | G17: 132.66 | H17: 178.25 | I17: 202.22
B18: Cash | C18: 1.31 | D18: 49.63 | E18: 139.5 | F18: 227.79 | G18: 494.44 | H18: 728.15 | I18: 921.02
B19: EBITDA Margin % | C19: -3 | D19: 23.3 | E19: 62.2 | F19: 62.7 | G19: 61.8 | H19: 60.9 | I19: 59.4
B66: ② | C66: FUNDRAISING WATERFALL — $510M EQUITY · $734M TOTAL CAPITAL
B67: Round | C67: Timing | D67: Pre-Money | E67: Equity | F67: Debt/PF | G67: Total | H67: Post-Money | I67: Step-Up
B68: Pre-Seed | C68: Oct 2025 | D68: $8M | E68: $2.1M | F68: — | G68: $2.1M | H68: $10.1M | I68: —
B69: Seed ★ | C69: May 2026 | D69: $40M | E69: $7.5M | F69: $2.5M | G69: $10M | H69: $47.5M | I69: 4.0x
B70: Series A | C70: Jun 2027 | D70: $210M | E70: $40M | F70: $17M | G70: $57M | H70: $250M | I70: 4.4x | L70: Stream | M70: $M
B71: Series B | C71: Q1 2029 | D71: $500M | E71: $60M | F71: $30M | G71: $90M | H71: $560M | I71: 2.0x | L71: H₂ Production | M71: 270
B72: Series C | C72: Q1 2031 | D72: $1.5B | E72: $150M | F72: $75M | G72: $225M | H72: $1.65B | I72: 2.7x | L72: Equipment | M72: 186.06
B73: Series D | C73: Q1 2033 | D73: $3.5B | E73: $250M | F73: $100M | G73: $350M | H73: $3.75B | I73: 2.1x | L73: Services | M73: 10.86
B76: ③ | C76: INVESTMENT HIGHLIGHTS
B78: ⚡ 92% System Efficiency | E78: Proprietary membrane-free electrolysis. Structural cost moat vs. grey H₂ and PEM competitors.
B79: 📈 EBITDA Positive from Year 2 | E79: Tiered facility ramps (Pilot → Mastered) drive operational mastery and rapid margin expansion.
B80: 🏭 12 Facilities by FY7 | E80: 4 tiers: Pilot 24mo, Early 18mo, Mature 15mo, Mastered 13mo. Each 900K kg/yr nameplate.
B81: 💰 45V PTC: $27M per Facility | E81: $3/kg × 900K kg/yr × 10 years. Must begin construction by Dec 2027 to qualify.
B82: 🔧 3-Engine Revenue Model | E82: H₂ production + equipment sales (T-25 / T-125) + recurring services (75% attach).
B83: 🎯 Single Source of Truth | E83: 15,400+ formulas trace to Base Case Inputs. One cell changes the entire 84-month engine.
B85: v8.5.2 · March 2026 · Prepared for Investor Diligence | H85: ● All integrity checks passing · 0 formula errors · BS balanced 84/84 months

Sheet P&L Summary
B1: P&L SUMMARY
B2: Annual income statement with integrated services and equipment revenue. T-25 and T-125 product lines drive equipment sales; services revenue begins 12 months after first equipment sale with 75% attach rate. Blue cells are adjustable. All figures pull directly from the Financials tab.
B4: REVENUE | C4: FY1 Apr '26 – Mar '27 | D4: FY2 Apr '27 – Mar '28 | E4: FY3 Apr '28 – Mar '29 | F4: FY4 Apr '29 – Mar '30 | G4: FY5 Apr '30 – Mar '31 | H4: FY6 Apr '31 – Mar '32 | I4: FY7 Apr '32 – Mar '33
B5: H₂ Production Revenue | C5: =SUM(Financials!E9:P15) -> 0 | D5: =SUM(Financials!Q9:AB15) -> 11812500 | E5: =SUM(Financials!AC9:AN15) -> 77812500 | F5: =SUM(Financials!AO9:AZ15) -> 141562500 | G5: =SUM(Financials!BA9:BL15) -> 210937500 | H5: =SUM(Financials!BM9:BX15) -> 264375000 | I5: =SUM(Financials!BY9:CJ15) -> 270000000
B6: Equipment Sales Revenue | C6: =SUM(Financials!E16:P16) -> 807692.31 | D6: =SUM(Financials!Q16:AB16) -> 4295000 | E6: =SUM(Financials!AC16:AN16) -> 10260000 | F6: =SUM(Financials!AO16:AZ16) -> 18770000 | G6: =SUM(Financials!BA16:BL16) -> 28950000 | H6: =SUM(Financials!BM16:BX16) -> 39130000 | I6: =SUM(Financials!BY16:CJ16) -> 51060000
B7: Equipment Services Revenue | C7: =SUM(Financials!E17:P17) -> 0 | D7: =SUM(Financials!Q17:AB17) -> 32812.5 | E7: =SUM(Financials!AC17:AN17) -> 242113.14 | F7: =SUM(Financials!AO17:AZ17) -> 848204.85 | G7: =SUM(Financials!BA17:BL17) -> 2092280.6 | H7: =SUM(Financials!BM17:BX17) -> 4204952.3 | I7: =SUM(Financials!BY17:CJ17) -> 6594846.3
B8: 45V Production Tax Credit (non-operating, excluded from Operating Revenue) | C8: =SUM('Model Assumptions'!G69:R69) -> 0 | D8: =SUM('Model Assumptions'!S69:AD69) -> 1417500 | E8: =SUM('Model Assumptions'!AE69:AP69) -> 8887500 | F8: =SUM('Model Assumptions'!AQ69:BB69) -> 10800000 | G8: =SUM('Model Assumptions'!BC69:BN69) -> 10800000 | H8: =SUM('Model Assumptions'!BO69:BZ69) -> 10800000 | I8: =SUM('Model Assumptions'!CA69:CL69) -> 10800000
B9: OPERATING REVENUE (ex-PTC) | C9: =C5+C6+C7 -> 807692.31 | D9: =D5+D6+D7 -> 16140312 | E9: =E5+E6+E7 -> 88314613 | F9: =F5+F6+F7 -> 1.611807e+08 | G9: =G5+G6+G7 -> 2.4197978e+08 | H9: =H5+H6+H7 -> 3.0770995e+08 | I9: =I5+I6+I7 -> 3.2765485e+08
B10: H₂ Revenue % | C10: =IFERROR(C5/C9,0) -> 0 | D10: =IFERROR(D5/D9,0) -> 0.73186315 | E10: =IFERROR(E5/E9,0) -> 0.88108295 | F10: =IFERROR(F5/F9,0) -> 0.87828441 | G10: =IFERROR(G5/G9,0) -> 0.87171539 | H10: =IFERROR(H5/H9,0) -> 0.85916948 | I10: =IFERROR(I5/I9,0) -> 0.82403786
B11: Equipment Revenue % | C11: =IFERROR(C6/C9,0) -> 1 | D11: =IFERROR(D6/D9,0) -> 0.26610389 | E11: =IFERROR(E6/E9,0) -> 0.11617556 | F11: =IFERROR(F6/F9,0) -> 0.11645315 | G11: =IFERROR(G6/G9,0) -> 0.1196381 | H11: =IFERROR(H6/H9,0) -> 0.12716521 | I11: =IFERROR(I6/I9,0) -> 0.15583472
B12: Services Revenue % | C12: =IFERROR(C7/C9,0) -> 0 | D12: =IFERROR(D7/D9,0) -> 0.0020329532 | E12: =IFERROR(E7/E9,0) -> 0.0027414844 | F12: =IFERROR(F7/F9,0) -> 0.0052624466 | G12: =IFERROR(G7/G9,0) -> 0.0086465102 | H12: =IFERROR(H7/H9,0) -> 0.013665311 | I12: =IFERROR(I7/I9,0) -> 0.020127419
B13: PTC % of Operating Revenue | C13: =IFERROR(C8/C9,0) -> 0 | D13: =IFERROR(D8/D9,0) -> 0.087823578 | E13: =IFERROR(E8/E9,0) -> 0.10063453 | F13: =IFERROR(F8/F9,0) -> 0.067005539 | G13: =IFERROR(G8/G9,0) -> 0.044631828 | H13: =IFERROR(H8/H9,0) -> 0.035097987 | I13: =IFERROR(I8/I9,0) -> 0.032961515 | J13: PTC (45V Production Tax Credit) is not included in Operating Revenue. This percentage shows PTC relative to Operating Revenue for comparability.
B14: COST OF GOODS SOLD
B15: H₂ Production COGS | C15: =SUM(Financials!E18:P18) -> 0 | D15: =SUM(Financials!Q18:AB18) -> 1268854.4 | E15: =SUM(Financials!AC18:AN18) -> 9728387.9 | F15: =SUM(Financials!AO18:AZ18) -> 18937473 | G15: =SUM(Financials!BA18:BL18) -> 28621619 | H15: =SUM(Financials!BM18:BX18) -> 36584628 | I15: =SUM(Financials!BY18:CJ18) -> 38281207
B16: Equipment COGS | C16: =SUM(Financials!E19:P19) -> 484615.38 | D16: =SUM(Financials!Q19:AB19) -> 2512000 | E16: =SUM(Financials!AC19:AN19) -> 5793750 | F16: =SUM(Financials!AO19:AZ19) -> 10143750 | G16: =SUM(Financials!BA19:BL19) -> 14813750 | H16: =SUM(Financials!BM19:BX19) -> 19110000 | I16: =SUM(Financials!BY19:CJ19) -> 24030000
B17: Services COGS | C17: =SUM(Financials!E20:P20) -> 0 | D17: =SUM(Financials!Q20:AB20) -> 6562.5 | E17: =SUM(Financials!AC20:AN20) -> 48422.627 | F17: =SUM(Financials!AO20:AZ20) -> 169640.97 | G17: =SUM(Financials!BA20:BL20) -> 418456.13 | H17: =SUM(Financials!BM20:BX20) -> 840990.46 | I17: =SUM(Financials!BY20:CJ20) -> 1318969.3
B18: TOTAL COGS | C18: =C15+C16+C17 -> 484615.38 | D18: =D15+D16+D17 -> 3787416.9 | E18: =E15+E16+E17 -> 15570561 | F18: =F15+F16+F17 -> 29250863 | G18: =G15+G16+G17 -> 43853825 | H18: =H15+H16+H17 -> 56535618 | I18: =I15+I16+I17 -> 63630177
B20: GROSS PROFIT | C20: =C9-C18 -> 323076.92 | D20: =D9-D18 -> 12352896 | E20: =E9-E18 -> 72744053 | F20: =F9-F18 -> 1.3192984e+08 | G20: =G9-G18 -> 1.9812596e+08 | H20: =H9-H18 -> 2.5117433e+08 | I20: =I9-I18 -> 2.6402467e+08
B21: Gross Margin | C21: =IFERROR(C20/C9,0) -> 0.4 | D21: =IFERROR(D20/D9,0) -> 0.76534426 | E21: =IFERROR(E20/E9,0) -> 0.82369214 | F21: =IFERROR(F20/F9,0) -> 0.81852131 | G21: =IFERROR(G20/G9,0) -> 0.8187707 | H21: =IFERROR(H20/H9,0) -> 0.81626978 | I21: =IFERROR(I20/I9,0) -> 0.8058012
B23: OPERATING EXPENSES
B24: Base Salaries | C24: =SUM(Financials!E26:P26) -> 1263500 | D24: =SUM(Financials!Q26:AB26) -> 3509147.2 | E24: =SUM(Financials!AC26:AN26) -> 7590438.4 | F24: =SUM(Financials!AO26:AZ26) -> 12122426 | G24: =SUM(Financials!BA26:BL26) -> 16827031 | H24: =SUM(Financials!BM26:BX26) -> 19624011 | I24: =SUM(Financials!BY26:CJ26) -> 20817306
B25: Benefits & Payroll Taxes | C25: =SUM(Financials!E27:P27) -> 472043.6 | D25: =SUM(Financials!Q27:AB27) -> 1311017.4 | E25: =SUM(Financials!AC27:AN27) -> 2835787.8 | F25: =SUM(Financials!AO27:AZ27) -> 4528938.4 | G25: =SUM(Financials!BA27:BL27) -> 6286578.8 | H25: =SUM(Financials!BM27:BX27) -> 7331530.4 | I25: =SUM(Financials!BY27:CJ27) -> 7777345.5
B26: HQ & Production Facility Leases | C26: =SUM(Financials!E28:P29) -> 262500 | D26: =SUM(Financials!Q28:AB29) -> 580662.5 | E26: =SUM(Financials!AC28:AN29) -> 848642.34 | F26: =SUM(Financials!AO28:AZ29) -> 1027353.7 | G26: =SUM(Financials!BA28:BL29) -> 1450410.1 | H26: =SUM(Financials!BM28:BX29) -> 1758208.4 | I26: =SUM(Financials!BY28:CJ29) -> 1802163.6
B27: Professional Fees + Sales & Mktg | C27: =SUM(Financials!E30:P30) -> 24230.769 | D27: =SUM(Financials!Q30:AB30) -> 484209.38 | E27: =SUM(Financials!AC30:AN30) -> 2649438.4 | F27: =SUM(Financials!AO30:AZ30) -> 4835421.1 | G27: =SUM(Financials!BA30:BL30) -> 7259393.4 | H27: =SUM(Financials!BM30:BX30) -> 9231298.6 | I27: =SUM(Financials!BY30:CJ30) -> 9829645.4
B28: R&D + Other | C28: =SUM(Financials!E31:P31)+SUM(Financials!E32:P32) -> 978903.85 | D28: =SUM(Financials!Q31:AB31)+SUM(Financials!Q32:AB32) -> 2709806.3 | E28: =SUM(Financials!AC31:AN31)+SUM(Financials!AC32:AN32) -> 3916292.3 | F28: =SUM(Financials!AO31:AZ31)+SUM(Financials!AO32:AZ32) -> 3823614.1 | G28: =SUM(Financials!BA31:BL31)+SUM(Financials!BA32:BL32) -> 5589595.6 | H28: =SUM(Financials!BM31:BX31)+SUM(Financials!BM32:BX32) -> 7154199 | I28: =SUM(Financials!BY31:CJ31)+SUM(Financials!BY32:CJ32) -> 7803097
B29: TOTAL OPERATING EXPENSES | C29: =C24+C25+C26+C27+C28 -> 3001178.2 | D29: =D24+D25+D26+D27+D28 -> 8594842.7 | E29: =E24+E25+E26+E27+E28 -> 17840599 | F29: =F24+F25+F26+F27+F28 -> 26337754 | G29: =G24+G25+G26+G27+G28 -> 37413009 | H29: =H24+H25+H26+H27+H28 -> 45099247 | I29: =I24+I25+I26+I27+I28 -> 48029557
B30: OpEx % of Revenue | C30: =IFERROR(C29/C9,0) -> 3.7157445 | D30: =IFERROR(D29/D9,0) -> 0.53250782 | E30: =IFERROR(E29/E9,0) -> 0.20201186 | F30: =IFERROR(F29/F9,0) -> 0.16340513 | G30: =IFERROR(G29/G9,0) -> 0.15461213 | H30: =IFERROR(H29/H9,0) -> 0.14656415 | I30: =IFERROR(I29/I9,0) -> 0.14658583
B31: Headcount (FTEs) | C31: =Personnel!B152 -> 15 | D31: =Personnel!C152 -> 50 | E31: =Personnel!D152 -> 89 | F31: =Personnel!E152 -> 135 | G31: =Personnel!F152 -> 182 | H31: =Personnel!G152 -> 205 | I31: =Personnel!H152 -> 224
B32: EBITDA | C32: =C20-C29 -> -2678101.3 | D32: =D20-D29 -> 3758052.9 | E32: =E20-E29 -> 54903453 | F32: =F20-F29 -> 1.0559209e+08 | G32: =G20-G29 -> 1.6071295e+08 | H32: =H20-H29 -> 2.0607509e+08 | I32: =I20-I29 -> 2.1599511e+08
B33: EBITDA Margin | C33: =IFERROR(C32/C9,0) -> -3.3157445 | D33: =IFERROR(D32/D9,0) -> 0.23283644 | E33: =IFERROR(E32/E9,0) -> 0.62168028 | F33: =IFERROR(F32/F9,0) -> 0.65511618 | G33: =IFERROR(G32/G9,0) -> 0.66415858 | H33: =IFERROR(H32/H9,0) -> 0.66970563 | I33: =IFERROR(I32/I9,0) -> 0.65921537
B35: Non-Operating Items
B36: Depreciation & Amortization | C36: =-SUM(Financials!E36:P36) -> 0 | D36: =-SUM(Financials!Q36:AB36) -> -706250 | E36: =-SUM(Financials!AC36:AN36) -> -1581944.4 | F36: =-SUM(Financials!AO36:AZ36) -> -2598611.1 | G36: =-SUM(Financials!BA36:BL36) -> -4640277.8 | H36: =-SUM(Financials!BM36:BX36) -> -5986111.1 | I36: =-SUM(Financials!BY36:CJ36) -> -6236111.1
B37: 45V PTC (applied in EBIT) | C37: =C8 -> 0 | D37: =D8 -> 1417500 | E37: =E8 -> 8887500 | F37: =F8 -> 10800000 | G37: =G8 -> 10800000 | H37: =H8 -> 10800000 | I37: =I8 -> 10800000
B38: EBIT | C38: =C32+C8+C36 -> -2678101.3 | D38: =D32+D8+D36 -> 4469302.9 | E38: =E32+E8+E36 -> 62209009 | F38: =F32+F8+F36 -> 1.1379348e+08 | G38: =G32+G8+G36 -> 1.6687267e+08 | H38: =H32+H8+H36 -> 2.1088898e+08 | I38: =I32+I8+I36 -> 2.20559e+08
B39: Interest Expense | C39: =SUM(Financials!E38:P38) -> -129908.71 | D39: =SUM(Financials!Q38:AB38) -> -855453.13 | E39: =SUM(Financials!AC38:AN38) -> -906767.09 | F39: =SUM(Financials!AO38:AZ38) -> -1515308.7 | G39: =SUM(Financials!BA38:BL38) -> -2062445.6 | H39: =SUM(Financials!BM38:BX38) -> -3737518.2 | I39: =SUM(Financials!BY38:CJ38) -> -5124499.7
B40: Earnings Before Tax | C40: =C38+C39 -> -2808010 | D40: =D38+D39 -> 3613849.8 | E40: =E38+E39 -> 61302242 | F40: =F38+F39 -> 1.1227817e+08 | G40: =G38+G39 -> 1.6481022e+08 | H40: =H38+H39 -> 2.0715146e+08 | I40: =I38+I39 -> 2.154345e+08
B41: Taxes | C41: =-SUM(Financials!E40:P40) -> 0 | D41: =-SUM(Financials!Q40:AB40) -> -245318.56 | E41: =-SUM(Financials!AC40:AN40) -> -16523863 | F41: =-SUM(Financials!AO40:AZ40) -> -30315105 | G41: =-SUM(Financials!BA40:BL40) -> -44498760 | H41: =-SUM(Financials!BM40:BX40) -> -55930894 | I41: =-SUM(Financials!BY40:CJ40) -> -58167315
B42: NET INCOME | C42: =C40+C41 -> -2808010 | D42: =D40+D41 -> 3368531.2 | E42: =E40+E41 -> 44778378 | F42: =F40+F41 -> 81963063 | G42: =G40+G41 -> 1.2031146e+08 | H42: =H40+H41 -> 1.5122056e+08 | I42: =I40+I41 -> 1.5726719e+08
B43: Net Margin | C43: =IFERROR(C42/C9,0) -> -3.4765838 | D43: =IFERROR(D42/D9,0) -> 0.20870297 | E43: =IFERROR(E42/E9,0) -> 0.50703249 | F43: =IFERROR(F42/F9,0) -> 0.50851659 | G43: =IFERROR(G42/G9,0) -> 0.49719635 | H43: =IFERROR(H42/H9,0) -> 0.49143865 | I43: =IFERROR(I42/I9,0) -> 0.47997821
B45: CASH POSITION
...

Sheet Unit Economics
B1: UNIT ECONOMICS: Structural Cost Advantage → Margin Expansion
B4: 1. PRODUCTION COST BUILDUP ($/kg H₂) — vs. Delivered Grey H₂ (SMR)
B5: Direct variable costs at Oklahoma industrial rates. Compared against delivered grey H₂ (centralized SMR).
B7: Cost Component | C7: Tobe ($/kg) | D7: Grey H₂ Delivered ($/kg) | E7: Tobe Advantage | F7: Source / Note
B8: Production Cost | C8: ='Base Case Inputs'!B90 -> 1.5473684 | D8: 1.25 | E8: =D8-C8 -> -0.29736842 | F8: Tobe: 42 kWh/kg × $0.035/kWh (OK rate). Grey SMR: $1.00-$1.50/kg production. Source: NREL ATB 2025
B9: Compression & Purification | C9: ='Base Case Inputs'!B83*'Base Case Inputs'!B11 -> 0.1225 | D9: 0.75 | E9: =D9-C9 -> 0.6275 | F9: Tobe: 3.5 kWh/kg × $0.035. Grey: $0.50-$1.00/kg at centralized facility. Source: DOE H2A-Lite v1.01
B10: Transportation (50-mile tube trailer / 500-mile liquefied) | C10: ='Base Case Inputs'!B82 -> 0.9 | D10: 8.25 | E10: =D10-C10 -> 7.35 | F10: Tobe: $0.90/kg 50-mi tube trailer. Grey: $2.50-$4.00/kg 150-300+ mi from centralized SMR. Source: NREL ATB 2025 delivery module; Brattle Group Feb 2024
B11: RO Water | C11: ='Base Case Inputs'!B84*'Base Case Inputs'!B85 -> 0.05004 | D11: 0.05 | E11: =D11-C11 -> -4e-05 | F11: 9 L/kg × $0.00556/L; industry ~$0.05/kg (comparable)
B12: TOTAL DIRECT OPEX | C12: =SUM(C8:C11) -> 2.6199084 | D12: =SUM(D8:D11) -> 10.3 | E12: =D12-C12 -> 7.6800916 | F12: Sum of variable production costs
B13: Overhead Absorption (at nameplate: 900,000 kg/year per facility)
B14: Allocated Facility Labor | C14: =Personnel!E15/900000 -> 1.3888622 | D14: N/A (absorbed)¹ | E14: N/A | F14: Tobe: allocated overhead (rent, insurance, admin) spread across production volume. At full capacity (900,000 kg/yr), overhead per kg is minimal.
B15: Allocated Facility CapEx (annualized) | C15: ='Model Assumptions'!$C$79/'Base Case Inputs'!$B$12/'Base Case Inputs'!$B$8 -> 0.40740741 | D15: N/A (absorbed)¹ | E15: N/A | F15: Tobe: capex allocated at $3.3M / 9yr useful life = $367K/yr; divided by annual production volume. Drops rapidly with scale.
B16: Maintenance & Consumables | C16: 0.42 | D16: N/A (absorbed)¹ | E16: N/A | F16: Tobe: $0.42/kg maintenance based on detailed cost analysis. Includes preventive maintenance and consumables.
B17: ALL-IN PRODUCTION COST ($/kg) | C17: =C12+C14+C15+C16 -> 4.8361781 | D17: ='Base Case Inputs'!B160 -> 5.25 | E17: =1-C17/D17 -> 0.078823228 | F17: Tobe all-in: production + overhead. Grey all-in: delivered price (.50-.50/kg). Source: NREL ATB 2025
B18: Base Case Sale Price ($/kg) | C18: ='Base Case Inputs'!B18 -> 25
B19: GROSS MARGIN PER KG | C19: =C18-C17 -> 20.163822
B20: ¹ Grey H₂ overhead note: Centralized SMR producers (Air Liquide, Air Products, Linde) quote all-in delivered prices that embed production cost, overhead, profit margin, and transportation. Their overhead is not shown separately because it's already baked into the $1.00-$1.50/kg production cost. Tobe's model shows overhead as a separate line because we build the full cost stack bottom-up for investor transparency. The comparison is apples-to-apples: both "all-in" numbers include overhead.
B22: 2. COST-DOWN CURVE BY YEAR
B23: Cost per kg decreases as production ramps and overhead absorption improves
C25: Year 2 (2027) | D25: Year 3 (2028) | E25: Year 4 (2029) | F25: Year 5 (2030)
B26: Annual H₂ Production (kg) | C26: =SUM(Financials!Q9:AB15)/'Base Case Inputs'!B18 -> 472500 | D26: ='Base Case Inputs'!$B$8 -> 900000 | E26: ='Base Case Inputs'!$B$8 -> 900000 | F26: ='Base Case Inputs'!$B$8 -> 900000 | G26: Ramp schedule from Model Assumptions
B27: Facility Utilization | C27: =C26/900000 -> 0.525 | D27: =D26/900000 -> 1 | E27: =E26/900000 -> 1 | F27: =F26/900000 -> 1 | G27: Volume ÷ 900K nameplate
B28: Direct OpEx ($/kg) | C28: =C12 -> 2.6199084 | D28: =C12 -> 2.6199084 | E28: =C12 -> 2.6199084 | F28: =C12 -> 2.6199084 | G28: Constant — variable cost per kg
B29: Allocated Labor ($/kg) | C29: =1250000/C26 -> 2.6455026 | D29: =1250000/D26 -> 1.3888889 | E29: =1250000/E26 -> 1.3888889 | F29: =1250000/F26 -> 1.3888889 | G29: $1.25M personnel ÷ actual volume
B30: Allocated CapEx ($/kg) | C30: ='Model Assumptions'!$C$79/'Base Case Inputs'!$B$12/C26 -> 0.77601411 | D30: ='Model Assumptions'!$C$79/'Base Case Inputs'!$B$12/D26 -> 0.40740741 | E30: ='Model Assumptions'!$C$79/'Base Case Inputs'!$B$12/E26 -> 0.40740741 | F30: ='Model Assumptions'!$C$79/'Base Case Inputs'!$B$12/F26 -> 0.40740741 | G30: $3.3M facility ÷ 9yr ÷ actual volume
B31: Maintenance ($/kg) | C31: 0.43 | D31: 0.42 | E31: 0.4 | F31: 0.4 | G31: Declines with operational maturity - Operational learning reduces unplanned maintenance by ~5% per year through Year 4, then stabilizes
B32: ALL-IN COST ($/kg) | C32: =C28+C29+C30+C31 -> 6.4714252 | D32: =D28+D29+D30+D31 -> 4.8362047 | E32: =E28+E29+E30+E31 -> 4.8162047 | F32: =F28+F29+F30+F31 -> 4.8162047
B33: Gross Margin ($/kg) | C33: ='Base Case Inputs'!$B$18-C32 -> 18.528575 | D33: ='Base Case Inputs'!$B$18-D32 -> 20.163795 | E33: ='Base Case Inputs'!$B$18-E32 -> 20.183795 | F33: ='Base Case Inputs'!$B$18-F32 -> 20.183795
B34: Gross Margin % | C34: =1-C32/'Base Case Inputs'!$B$18 -> 0.74114299 | D34: =1-D32/'Base Case Inputs'!$B$18 -> 0.80655181 | E34: =1-E32/'Base Case Inputs'!$B$18 -> 0.80735181 | F34: =1-F32/'Base Case Inputs'!$B$18 -> 0.80735181
B35: YoY Cost Improvement (from Year 2) | C35: =0 -> 0 | D35: =1-D32/C32 -> 0.25268321 | E35: =1-E32/D32 -> 0.0041354742 | F35: =1-F32/E32 -> 0
B37: FY1 shows N/A — no production during ramp-up phase. Meaningful unit economics begin FY2 at ~17.5% of nameplate capacity (157,500 kg). All-in cost drops significantly as production scales toward 900,000 kg/yr.
B39: 3. MARGIN SENSITIVITY ACROSS PRICE ENVIRONMENTS
B40: At full production (Year 3+), showing margin at various H₂ sale prices
B42: H₂ Sale Price | C42: Tobe Cost | D42: Tobe Margin
B43: ='Base Case Inputs'!B19 -> 15 | C43: =C17 -> 4.8361781 | D43: =1-C43/B43 -> 0.67758813
B44: ='Base Case Inputs'!B20 -> 20 | C44: =C17 -> 4.8361781 | D44: =1-C44/B44 -> 0.7581911
B45: ='Base Case Inputs'!B18 -> 25 | C45: =C17 -> 4.8361781 | D45: =1-C45/B45 -> 0.80655288
B46: ='Base Case Inputs'!B21 -> 30 | C46: =C17 -> 4.8361781 | D46: =1-C46/B46 -> 0.83879406
B47: ='Base Case Inputs'!B22 -> 35 | C47: =C17 -> 4.8361781 | D47: =1-C47/B47 -> 0.86182348
B49: Tobe is profitable at every price point.
...

Sheet Fundraising
B1: TOBE ENERGY — FUNDRAISING STORY
B2: $510M equity across 5 rounds · $734M total capital · Seed → Series D → IPO / Strategic Exit
F3: ⚠ ILLUSTRATIVE — NOT MODELED. Series D capital is NOT included in the Financials, Balance Sheet, or Cash Flow projections. The 7-year model covers Seed through Series C only.
B4: 1 · FUNDRAISING WATERFALL
C5: Pre-Seed | D5: Seed ★ | E5: Series A | F5: Series B | G5: Series C | H5: Series D / Growth
B6: Timing | C6: Oct 2025 | D6: May 2026 | E6: Jun 2027 | F6: Q1 2029 | G6: Q1 2031 | H6: Q1 2033
B7: Pre-Money Valuation | C7: 8000000 | D7: 40000000 | E7: 210000000 | F7: 500000000 | G7: 1500000000 | H7: 3500000000 | I7: Series D NOT MODELED - shown for illustrative purposes only
B8: Equity Raised | C8: ='Base Case Inputs'!B86 -> 2050000 | D8: ='Base Case Inputs'!B42 -> 7500000 | E8: ='Base Case Inputs'!B47 -> 40000000 | F8: ='Base Case Inputs'!B52 -> 60000000 | G8: ='Base Case Inputs'!B56 -> 150000000 | H8: 250000000
B9: Debt / Project Finance | C9: 0 | D9: ='Base Case Inputs'!B43+'Base Case Inputs'!B44 -> 2500000 | E9: ='Base Case Inputs'!B49+'Base Case Inputs'!B48 -> 17000000 | F9: ='Base Case Inputs'!B53 -> 30000000 | G9: ='Base Case Inputs'!B57 -> 75000000 | H9: 100000000
B10: Total Capital This Round | C10: =C8+C9 -> 2050000 | D10: =D8+D9 -> 10000000 | E10: =E8+E9 -> 57000000 | F10: =F8+F9 -> 90000000 | G10: =G8+G9 -> 225000000 | H10: =H8+H9 -> 350000000
B11: Post-Money Valuation | C11: =C7+C8 -> 10050000 | D11: =D7+D8 -> 47500000 | E11: =E7+E8 -> 250000000 | F11: =F7+F8 -> 560000000 | G11: =G7+G8 -> 1650000000 | H11: =H7+H8 -> 3750000000
B12: Valuation Step-Up | C12: — | D12: 4.0x | E12: 4.4x | F12: =IFERROR(TEXT(F7/E11,"0.0x"),"—") -> 2.0x | G12: =IFERROR(TEXT(G7/F11,"0.0x"),"—") -> 2.7x | H12: 2.1x
B14: 2 · USE OF CAPITAL — WHAT EACH ROUND FUNDS
B15: Pre-Seed | C15: 45931 | D15: SAFEs — bridge to Seed. Technology validation, patent filings, initial team.
B16: Seed ★ | C16: 46143 | D16: Facility 1 (Tulsa) buildout · Manufacturing pilot · First T-125 units · Core team of 20
B17: Series A | C17: 46539 | D17: Facilities 2–3 · T-125 scale-up launch · Next-gen R&D kickoff · Manufacturing scale to 150+ T-25 units/yr · Team → 66
B18: Series B | C18: Q1 2029 | D18: Facilities 4–7 · T-125 commercial scale · Regional expansion · Team → 109
B19: Series C | C19: Q1 2031 | D19: Facilities 8–12 · T-125 at commercial scale · National footprint · Revenue run-rate $280M+ · Team → 223
B20: Series D / Growth | C20: Q1 2033 | D20: Pre-IPO acceleration · International expansion · $397M+ revenue · 326 FTEs
B23: 3 · IMPLIED EXIT — IPO / STRATEGIC ACQUISITION
C24: Bear (8x Rev) | D24: Base (10x Rev) | E24: Bull (12x Rev) | G24: Bear (15x EBITDA) | H24: Base (20x EBITDA) | I24: Bull (25x EBITDA)
B25: Y7 Revenue / EBITDA Basis | C25: ='P&L Summary'!I9 -> 3.2765485e+08 | D25: ='P&L Summary'!I9 -> 3.2765485e+08 | E25: ='P&L Summary'!I9 -> 3.2765485e+08 | G25: ='P&L Summary'!I32 -> 2.1599511e+08 | H25: ='P&L Summary'!I32 -> 2.1599511e+08 | I25: ='P&L Summary'!I32 -> 2.1599511e+08
B26: Implied Enterprise Value | C26: =C25*8 -> 2.6212388e+09 | D26: =D25*10 -> 3.2765485e+09 | E26: =E25*12 -> 3.9318582e+09 | G26: =G25*15 -> 3.2399267e+09 | H26: =H25*20 -> 4.3199022e+09 | I26: =I25*25 -> 5.3998778e+09
B27: vs. Series D Pre-Money ($3.5B) | C27: =IFERROR(TEXT(C26/H7,"0.0x"),"—") -> 0.7x | D27: =IFERROR(TEXT(D26/H7,"0.0x"),"—") -> 0.9x | E27: =IFERROR(TEXT(E26/H7,"0.0x"),"—") -> 1.1x | G27: =IFERROR(TEXT(G26/H7,"0.0x"),"—") -> 0.9x | H27: =IFERROR(TEXT(H26/H7,"0.0x"),"—") -> 1.2x | I27: =IFERROR(TEXT(I26/H7,"0.0x"),"—") -> 1.5x
B29: ★ Current round · Seed investor ownership at exit ~10.8% (post-Series C dilution) · Trajectory benchmarked to Fervo Energy: Pre-Seed → Seed → A → B → C → IPO / Strategic Exit | G29: Seed ownership calc (post-Series C) | H29: =D8/D11*E7/E11*F7/(F7+F8)*G7/G11 -> 0.1076555

Sheet Use of Funds
B1: 1. SEED ROUND — CAPITAL STRUCTURE
C2: Amount ($) | D2: % of Total | F2: Notes
B3: Equity Financing | C3: ='Base Case Inputs'!B42 -> 7500000 | D3: =C3/C5 -> 0.75 | F3: Priced equity round (Seed)
B4: Debt Financing | C4: ='Base Case Inputs'!B43 -> 2500000 | D4: =C4/C5 -> 0.25 | F4: Venture debt / revenue-based financing; secured by project assets
B5: TOTAL SEED CAPITAL | C5: =C3+C4 -> 10000000 | D5: =C5/C5 -> 1
B7: 2. EQUITY USE OF FUNDS
B8: Category | C8: Budget ($) | D8: % of Equity | E8: Hire Mo | F8: Notes / Milestone
B9: R&D: T-125 System Validation
B10: Stack design, materials, & prototype iteration | C10: 450000 | F10: Cell/stack architecture for commercial-scale 125 kg/day
B11: System integration & BOP engineering | C11: 300000 | F11: Power electronics, thermal management, water/gas handling
B12: Testing & commissioning (at Zeeco facility) | C12: 200000 | F12: $1.1M total R&D — $1.875M saved vs. standalone facility electrical upgrades
B13: Certification test specimens & destructive testing | C13: 150000 | F13: ASME, DOT test articles
B14: Subtotal: R&D | C14: =SUM(C10:C13) -> 1100000 | D14: =C14/C3 -> 0.14666667
B16: Manufacturing Equipment & Automation
B17: 5-Axis CNC Machine (#2) | C17: 140000 | F17: Second unit for production throughput
B18: CNC Lathe (precision electrode/manifold work) | C18: 95000 | F18: Turning operations for cylindrical components
B19: CNC Transformer Winder (#2) | C19: 90000 | F19: Coil winding for power electronics
B20: Laser Cutter / Waterjet | C20: 120000 | F20: Plate cutting for bipolar plates, gaskets, enclosures
B21: Welding Automation (TIG/MIG cell) | C21: 150000 | F21: Automated TIG/MIG cell + orbital welding for pressure circuits
B22: Assembly fixtures, jigs, & tooling | C22: 110000 | F22: Custom production tooling & work-holding fixtures
B23: 3D Printer (Industrial — metal/polymer) | C23: 85000 | F23: Rapid prototyping, custom fittings, test fixtures
B24: Electronics test & lab equipment | C24: 80000 | F24: Oscilloscopes, power analyzers, impedance spectroscopy, DAQ
B25: CAD/CAM/PLM Software Licenses | C25: 100000 | F25: SolidWorks, Mastercam, Arena PLM
B26: Spares & replacement parts inventory | C26: 100000 | F26: Critical spares for production uptime: electrodes, membranes, seals, gaskets
B27: Safety equipment & infrastructure | C27: 50000 | F27: H₂ leak detection, ventilation, fire suppression, PPE, safety signage
B28: Subtotal: Manufacturing Equipment | C28: =SUM(C17:C27) -> 1120000 | D28: =C28/C3 -> 0.14933333
B30: Personnel (15-Month Seed Period)
B31: Benefits Loading % | C31: ='Base Case Inputs'!$B$75 -> 0.3736 | F31: From Base Case Inputs B75 (benefits loading)
B32: Role | C32: Annual Base ($) | D32: Monthly Loaded | E32: Hire Mo | F32: Seed Period Cost (to Mo 15)
B33: Existing Team (7 FTEs) | C33: 665000 | D33: =C33*(1+$C$31)/12 -> 76120.333 | E33: Existing | F33: =D33*15 -> 1141805
B34: Sales Representative | C34: 95000 | D34: =C34*(1+$C$31)/12 -> 10874.333 | E34: Mo 2 | F34: =D34*14 -> 152240.67
B35: Electrical Engineer | C35: 110000 | D35: =C35*(1+$C$31)/12 -> 12591.333 | E35: Mo 3 | F35: =D35*13 -> 163687.33
B36: Mechanical Engineer | C36: 110000 | D36: =C36*(1+$C$31)/12 -> 12591.333 | E36: Mo 3 | F36: =D36*13 -> 163687.33
B37: Chemical Engineer | C37: 110000 | D37: =C37*(1+$C$31)/12 -> 12591.333 | E37: Mo 4 | F37: =D37*12 -> 151096
B38: Electrical Technician | C38: 85000 | D38: =C38*(1+$C$31)/12 -> 9729.6667 | E38: Mo 4 | F38: =D38*12 -> 116756
B39: Mechanical Technician | C39: 85000 | D39: =C39*(1+$C$31)/12 -> 9729.6667 | E39: Mo 5 | F39: =D39*11 -> 107026.33
B40: Chemical Technician | C40: 80000 | D40: =C40*(1+$C$31)/12 -> 9157.3333 | E40: Mo 6 | F40: =D40*10 -> 91573.333
B41: Field Service Install Technician | C41: 90000 | D41: =C41*(1+$C$31)/12 -> 10302 | E41: Mo 4 | F41: =D41*12 -> 123624
B42: Subtotal: Personnel | D42: =F42/C3 -> 0.29486613 | F42: =SUM(F33:F41) -> 2211496
B44: Certifications & Compliance
...

Sheet Tax Credits
B1: TAX CREDITS & SENSITIVITY ANALYSIS
B2: 45V Production Tax Credit · H₂ price sensitivity · facility ramp speed · facility buildout pace · combined scenario tables. Scenario B (premium geography) parked — review with Lou. Scenario C (tube trailer fleet) parked to Notes tab.
B5: SCENARIO A: 45V PRODUCTION TAX CREDIT
B6: $3/kg federal credit for qualifying green H₂ (IRA §45V). 10-year credit per facility. Begin-construction deadline Dec 2027. Toggle: Base Case Inputs.
C7: FY1 Apr '26 – Mar '27 | D7: FY2 Apr '27 – Mar '28 | E7: FY3 Apr '28 – Mar '29 | F7: FY4 Apr '29 – Mar '30 | G7: FY5 Apr '30 – Mar '31
B8: PTC Revenue ($3/kg) | C8: =SUM('Model Assumptions'!G69:R69) -> 0 | D8: =SUM('Model Assumptions'!S69:AD69) -> 1417500 | E8: =SUM('Model Assumptions'!AE69:AP69) -> 8887500 | F8: =SUM('Model Assumptions'!AQ69:BB69) -> 10800000 | G8: =SUM('Model Assumptions'!BC69:BN69) -> 10800000
B9: Total H₂ Production (kg) | C9: =SUM('Model Assumptions'!G15:R15)+SUM('Model Assumptions'!G23:R23)+SUM('Model Assumptions'!G31:R31)+SUM('Model Assumptions'!G39:R39)+SUM('Model Assumptions'!G47:R47)+SUM('Model Assumptions'!G55:R55)+SUM('Model Assumptions'!G63:R63) -> 0 | D9: =SUM('Model Assumptions'!S15:AD15)+SUM('Model Assumptions'!S23:AD23)+SUM('Model Assumptions'!S31:AD31)+SUM('Model Assumptions'!S39:AD39)+SUM('Model Assumptions'!S47:AD47)+SUM('Model Assumptions'!S55:AD55)+SUM('Model Assumptions'!S63:AD63) -> 472500 | E9: =SUM('Model Assumptions'!AE15:AP15)+SUM('Model Assumptions'!AE23:AP23)+SUM('Model Assumptions'!AE31:AP31)+SUM('Model Assumptions'!AE39:AP39)+SUM('Model Assumptions'!AE47:AP47)+SUM('Model Assumptions'!AE55:AP55)+SUM('Model Assumptions'!AE63:AP63) -> 3112500 | F9: =SUM('Model Assumptions'!AQ15:BB15)+SUM('Model Assumptions'!AQ23:BB23)+SUM('Model Assumptions'!AQ31:BB31)+SUM('Model Assumptions'!AQ39:BB39)+SUM('Model Assumptions'!AQ47:BB47)+SUM('Model Assumptions'!AQ55:BB55)+SUM('Model Assumptions'!AQ63:BB63) -> 5662500 | G9: =SUM('Model Assumptions'!BC15:BN15)+SUM('Model Assumptions'!BC23:BN23)+SUM('Model Assumptions'!BC31:BN31)+SUM('Model Assumptions'!BC39:BN39)+SUM('Model Assumptions'!BC47:BN47)+SUM('Model Assumptions'!BC55:BN55)+SUM('Model Assumptions'!BC63:BN63) -> 8437500
B10: Incremental EBITDA from PTC | C10: =C8 -> 0 | D10: =D8 -> 1417500 | E10: =E8 -> 8887500 | F10: =F8 -> 10800000 | G10: =G8 -> 10800000
B11: Cumulative PTC Cash | C11: =C8 -> 0 | D11: =C11+D8 -> 1417500 | E11: =D11+E8 -> 10305000 | F11: =E11+F8 -> 21105000 | G11: =F11+G8 -> 31905000
B13: The PTC is pure margin — no incremental COGS. Adds $3/kg to every qualifying kg produced. Toggle in Base Case Inputs.
B16: SCENARIO UPSIDE SUMMARY
C17: FY1 Apr '26 – Mar '27 | D17: FY2 Apr '27 – Mar '28 | E17: FY3 Apr '28 – Mar '29 | F17: FY4 Apr '29 – Mar '30 | G17: FY5 Apr '30 – Mar '31
B18: A: 45V PTC Revenue | C18: =C8 -> 0 | D18: =D8 -> 1417500 | E18: =E8 -> 8887500 | F18: =F8 -> 10800000 | G18: =G8 -> 10800000
B19: TOTAL UPSIDE vs. BASE | C19: =C8 -> 0 | D19: =D8 -> 1417500 | E19: =E8 -> 8887500 | F19: =F8 -> 10800000 | G19: =G8 -> 10800000
B21: Additional scenarios (e.g. premium geographies, fleet) may be added here once validated.
B23: BASE CASE ANNUAL SUMMARY (from Core Financials Engine)
B24: All figures sourced directly from P&L Summary / Financials. No parallel calculations — single source of truth.
C25: FY1 Apr '26 – Mar '27 | D25: FY2 Apr '27 – Mar '28 | E25: FY3 Apr '28 – Mar '29 | F25: FY4 Apr '29 – Mar '30 | G25: FY5 Apr '30 – Mar '31 | H25: Source
B26: Total Revenue | C26: ='P&L Summary'!C9 -> 807692.31 | D26: ='P&L Summary'!D9 -> 16140312 | E26: ='P&L Summary'!E9 -> 88314613 | F26: ='P&L Summary'!F9 -> 1.611807e+08 | G26: ='P&L Summary'!G9 -> 2.4197978e+08 | H26: P&L Summary row 10
B27: H₂ Revenue | C27: ='P&L Summary'!C5 -> 0 | D27: ='P&L Summary'!D5 -> 11812500 | E27: ='P&L Summary'!E5 -> 77812500 | F27: ='P&L Summary'!F5 -> 141562500 | G27: ='P&L Summary'!G5 -> 210937500 | H27: P&L Summary row 6
B28: Equipment + Services + 45V | C28: ='P&L Summary'!C6+'P&L Summary'!C7+'P&L Summary'!C8 -> 807692.31 | D28: ='P&L Summary'!D6+'P&L Summary'!D7+'P&L Summary'!D8 -> 5745312.5 | E28: ='P&L Summary'!E6+'P&L Summary'!E7+'P&L Summary'!E8 -> 19389613 | F28: ='P&L Summary'!F6+'P&L Summary'!F7+'P&L Summary'!F8 -> 30418205 | G28: ='P&L Summary'!G6+'P&L Summary'!G7+'P&L Summary'!G8 -> 41842281 | H28: P&L Summary rows 7+8+9
B29: Total COGS | C29: ='P&L Summary'!C18 -> 484615.38 | D29: ='P&L Summary'!D18 -> 3787416.9 | E29: ='P&L Summary'!E18 -> 15570561 | F29: ='P&L Summary'!F18 -> 29250863 | G29: ='P&L Summary'!G18 -> 43853825 | H29: P&L Summary row 18
B30: Total OpEx | C30: ='P&L Summary'!C29 -> 3001178.2 | D30: ='P&L Summary'!D29 -> 8594842.7 | E30: ='P&L Summary'!E29 -> 17840599 | F30: ='P&L Summary'!F29 -> 26337754 | G30: ='P&L Summary'!G29 -> 37413009 | H30: P&L Summary row 29 (incl R&D, Site Occ)
B31: EBITDA | C31: ='P&L Summary'!C32 -> -2678101.3 | D31: ='P&L Summary'!D32 -> 3758052.9 | E31: ='P&L Summary'!E32 -> 54903453 | F31: ='P&L Summary'!F32 -> 1.0559209e+08 | G31: ='P&L Summary'!G32 -> 1.6071295e+08 | H31: P&L Summary row 32
B32: EBITDA Margin | C32: =IFERROR(C31/C26,0) -> -3.3157445 | D32: =IFERROR(D31/D26,0) -> 0.23283644 | E32: =IFERROR(E31/E26,0) -> 0.62168028 | F32: =IFERROR(F31/F26,0) -> 0.65511618 | G32: =IFERROR(G31/G26,0) -> 0.66415858 | H32: EBITDA / Revenue
B33: Net Income | C33: ='P&L Summary'!C42 -> -2808010 | D33: ='P&L Summary'!D42 -> 3368531.2 | E33: ='P&L Summary'!E42 -> 44778378 | F33: ='P&L Summary'!F42 -> 81963063 | G33: ='P&L Summary'!G42 -> 1.2031146e+08 | H33: P&L Summary row 41
B34: Year-End Cash | C34: =Financials!P101 -> 1289092.1 | D34: =Financials!AB101 -> 49613513 | E34: =Financials!AN101 -> 1.3948772e+08 | F34: =Financials!AZ101 -> 2.241518e+08 | G34: =Financials!BL101 -> 4.7838468e+08 | H34: Financials row 97
B35: H₂ Production Vol (kg) | C35: =IFERROR(C27/'Base Case Inputs'!$B$18,0) -> 0 | D35: =IFERROR(D27/'Base Case Inputs'!$B$18,0) -> 472500 | E35: =IFERROR(E27/'Base Case Inputs'!$B$18,0) -> 3112500 | F35: =IFERROR(F27/'Base Case Inputs'!$B$18,0) -> 5662500 | G35: =IFERROR(G27/'Base Case Inputs'!$B$18,0) -> 8437500 | H35: H₂ Rev ÷ base price
B36: R&D | C36: ='Base Case Inputs'!B135 -> 962750 | D36: ='Base Case Inputs'!B136 -> 2387000 | E36: ='Base Case Inputs'!B137 -> 2150000 | F36: ='Base Case Inputs'!B138 -> 600000 | G36: ='Base Case Inputs'!B139 -> 750000 | H36: BCI rows 117-121
B37: Blended Variable Cost Rate | C37: =IFERROR('Base Case Inputs'!$B$76+'Base Case Inputs'!$B$77+C36/C26,0) -> 1.2419762 | D37: =IFERROR('Base Case Inputs'!$B$76+'Base Case Inputs'!$B$77+D36/D26,0) -> 0.19789057 | E37: =IFERROR('Base Case Inputs'!$B$76+'Base Case Inputs'!$B$77+E36/E26,0) -> 0.074344782 | F37: =IFERROR('Base Case Inputs'!$B$76+'Base Case Inputs'!$B$77+F36/F26,0) -> 0.05372253 | G37: =IFERROR('Base Case Inputs'!$B$76+'Base Case Inputs'!$B$77+G36/G26,0) -> 0.053099433 | H37: 3% + 2% + R&D/Revenue
B39: SENSITIVITY 1: H₂ SALE PRICE (Engine-Referenced)
B40: EBITDA = Core EBITDA + (SensPrice/BasePrice − 1) × H₂ Rev × (1 − VarCostRate). Exact match at $25/kg. Revenue & EBITDA shown per scenario.
C41: FY1 Apr '26 – Mar '27 | D41: FY2 Apr '27 – Mar '28 | E41: FY3 Apr '28 – Mar '29 | F41: FY4 Apr '29 – Mar '30 | G41: FY5 Apr '30 – Mar '31
B42: $15/kg (Bear)
B43: Revenue | C43: =IFERROR(C27*('Base Case Inputs'!$B$19/'Base Case Inputs'!$B$18)+C28,0) -> 807692.31 | D43: =IFERROR(D27*('Base Case Inputs'!$B$19/'Base Case Inputs'!$B$18)+D28,0) -> 12832812 | E43: =IFERROR(E27*('Base Case Inputs'!$B$19/'Base Case Inputs'!$B$18)+E28,0) -> 66077113 | F43: =IFERROR(F27*('Base Case Inputs'!$B$19/'Base Case Inputs'!$B$18)+F28,0) -> 1.153557e+08 | G43: =IFERROR(G27*('Base Case Inputs'!$B$19/'Base Case Inputs'!$B$18)+G28,0) -> 1.6840478e+08 | H43: H₂ repriced + Equip+Svc+45V
B44: EBITDA | C44: =IFERROR(C31+('Base Case Inputs'!$B$19/'Base Case Inputs'!$B$18-1)*C27*(1-C37),0) -> -2678101.3 | D44: =IFERROR(D31+('Base Case Inputs'!$B$19/'Base Case Inputs'!$B$18-1)*D27*(1-D37),0) -> -31914.137 | E44: =IFERROR(E31+('Base Case Inputs'!$B$19/'Base Case Inputs'!$B$18-1)*E27*(1-E37),0) -> 26092435 | F44: =IFERROR(F31+('Base Case Inputs'!$B$19/'Base Case Inputs'!$B$18-1)*F27*(1-F37),0) -> 52009126 | G44: =IFERROR(G31+('Base Case Inputs'!$B$19/'Base Case Inputs'!$B$18-1)*G27*(1-G37),0) -> 80818211 | H44: Core EBITDA + Δ adjustment
B45: $20/kg
B46: Revenue | C46: =IFERROR(C27*('Base Case Inputs'!$B$20/'Base Case Inputs'!$B$18)+C28,0) -> 807692.31 | D46: =IFERROR(D27*('Base Case Inputs'!$B$20/'Base Case Inputs'!$B$18)+D28,0) -> 15195312 | E46: =IFERROR(E27*('Base Case Inputs'!$B$20/'Base Case Inputs'!$B$18)+E28,0) -> 81639613 | F46: =IFERROR(F27*('Base Case Inputs'!$B$20/'Base Case Inputs'!$B$18)+F28,0) -> 1.436682e+08 | G46: =IFERROR(G27*('Base Case Inputs'!$B$20/'Base Case Inputs'!$B$18)+G28,0) -> 2.1059228e+08
B47: EBITDA | C47: =IFERROR(C31+('Base Case Inputs'!$B$20/'Base Case Inputs'!$B$18-1)*C27*(1-C37),0) -> -2678101.3 | D47: =IFERROR(D31+('Base Case Inputs'!$B$20/'Base Case Inputs'!$B$18-1)*D27*(1-D37),0) -> 1863069.4 | E47: =IFERROR(E31+('Base Case Inputs'!$B$20/'Base Case Inputs'!$B$18-1)*E27*(1-E37),0) -> 40497944 | F47: =IFERROR(F31+('Base Case Inputs'!$B$20/'Base Case Inputs'!$B$18-1)*F27*(1-F37),0) -> 78800607 | G47: =IFERROR(G31+('Base Case Inputs'!$B$20/'Base Case Inputs'!$B$18-1)*G27*(1-G37),0) -> 1.2076558e+08
B48: $25/kg (Base Case)
...

Sheet Learning Curve
B1: MANUFACTURING COST ANALYSIS
B2: Blended cost reduction across T-25 and T-125 product lines. ~15% average learning rate (Wright’s Law). Blended BOM declines as mix shifts toward higher-value units and cumulative production drives manufacturing efficiency.
B4: 1. BLENDED ELECTROLYZER COST (T-25 + T-125 — includes mix effect)
C5: Launch Year 2 | D5: First Scale Year 3 | E5: Multi-Line Year 4 | F5: Volume Mfg Year 5 | G5: At Scale Year 6+ | H5: At Scale Year 7
B6: Cumulative Units Produced | C6: ='Unit Economics'!C62 -> 85 | D6: =C6+'Unit Economics'!D62 -> 265 | E6: =D6+'Unit Economics'!E62 -> 575 | F6: =E6+'Unit Economics'!F62 -> 1025 | G6: =F6+'Unit Economics'!G62 -> 2395 | H6: =G6+SUM('Model Assumptions'!CA133:CL133)+SUM('Model Assumptions'!CA67:CL67)+SUM('Model Assumptions'!CA136:CL136) -> 3175
B7: Total Units Sold in Period | C7: ='Unit Economics'!C62 -> 85 | D7: ='Unit Economics'!D62 -> 180 | E7: ='Unit Economics'!E62 -> 310 | F7: ='Unit Economics'!F62 -> 450 | G7: ='Unit Economics'!G62 -> 1370 | H7: =SUM('Model Assumptions'!CA133:CL133)+SUM('Model Assumptions'!CA67:CL67)+SUM('Model Assumptions'!CA136:CL136) -> 780
B8: Blended Avg BOM ($/unit) | C8: =IFERROR(('Unit Economics'!C59*$C$74+'Unit Economics'!C60*$C$75+'Unit Economics'!C61*$C$76)/('Unit Economics'!C62),0) -> 30294.118 | D8: =IFERROR(('Unit Economics'!D59*$D$74+'Unit Economics'!D60*$D$75+'Unit Economics'!D61*$D$76)/('Unit Economics'!D62),0) -> 32800 | E8: =IFERROR(('Unit Economics'!E59*$E$74+'Unit Economics'!E60*$E$75+'Unit Economics'!E61*$E$76)/('Unit Economics'!E62),0) -> 33568.548 | F8: =IFERROR(('Unit Economics'!F59*$F$74+'Unit Economics'!F60*$F$75+'Unit Economics'!F61*$F$76)/('Unit Economics'!F62),0) -> 33736.111 | G8: =IFERROR(('Unit Economics'!G59*$G$74+'Unit Economics'!G60*$G$75+'Unit Economics'!G61*$G$76)/('Unit Economics'!G62),0) -> 32548.358 | H8: =IFERROR((SUM('Model Assumptions'!CA67:CL67)*$H$74+SUM('Model Assumptions'!CA133:CL133)*$H$75+SUM('Model Assumptions'!CA136:CL136)*$H$76)/(SUM('Model Assumptions'!CA67:CL67)+SUM('Model Assumptions'!CA133:CL133)+SUM('Model Assumptions'!CA136:CL136)),0) -> 30807.692 | I8: Blended BOM reflects both per-unit cost-down (learning curve) AND product mix shift. T-125 share grows from 44%→62% in Y2-Y4, which increases the blend even though per-unit costs decline. See R71-R72 for per-product trends.
B9: Blended BOM Change vs. Launch (includes mix effect) | C9: =1-C8/C8 -> 0 | D9: =1-D8/C8 -> -0.082718447 | E9: =1-E8/C8 -> -0.10808801 | F9: =1-F8/C8 -> -0.1136192 | G9: =1-G8/C8 -> -0.074411806 | H9: =1-H8/C8 -> -0.01695295
B11: T-25 Cost Reduction vs. Launch | C11: =1-C74/$C$74 -> 0 | D11: =1-D74/$C$74 -> 0.04 | E11: =1-E74/$C$74 -> 0.075 | F11: =1-F74/$C$74 -> 0.125 | G11: =1-G74/$C$74 -> 0.175 | H11: =1-H74/$C$74 -> 0.2
B12: T-125 Cost Reduction vs. Launch | C12: =1-C75/$C$75 -> 0 | D12: =1-D75/$C$75 -> 0.04 | E12: =1-E75/$C$75 -> 0.075 | F12: =1-F75/$C$75 -> 0.125 | G12: =1-G75/$C$75 -> 0.175 | H12: =1-H75/$C$75 -> 0.225
B14: Blended ASP ($/unit) | C14: =IFERROR('Unit Economics'!C63/'Unit Economics'!C62,0) -> 50529.412 | D14: =IFERROR('Unit Economics'!D63/'Unit Economics'!D62,0) -> 57000 | E14: =IFERROR('Unit Economics'!E63/'Unit Economics'!E62,0) -> 60548.387 | F14: =IFERROR('Unit Economics'!F63/'Unit Economics'!F62,0) -> 64333.333 | G14: =IFERROR('Unit Economics'!G63/'Unit Economics'!G62,0) -> 65832.117 | H14: =IFERROR((SUM('Model Assumptions'!CA67:CL67)*35000+SUM('Model Assumptions'!CA133:CL133)*167000+SUM('Model Assumptions'!CA136:CL136)*3000000)/(SUM('Model Assumptions'!CA67:CL67)+SUM('Model Assumptions'!CA133:CL133)+SUM('Model Assumptions'!CA136:CL136)),0) -> 65461.538
B15: Blended Gross Margin | C15: =IFERROR(1-C8/C14,0) -> 0.40046566 | D15: =IFERROR(1-D8/D14,0) -> 0.4245614 | E15: =IFERROR(1-E8/E14,0) -> 0.44559137 | F15: =IFERROR(1-F8/F14,0) -> 0.47560449 | G15: =IFERROR(1-G8/G14,0) -> 0.50558543 | H15: =IFERROR(1-H8/H14,0) -> 0.5293772
B16: Blended Gross Profit per Unit | C16: =IFERROR(C14-C8,0) -> 20235.294 | D16: =IFERROR(D14-D8,0) -> 24200 | E16: =IFERROR(E14-E8,0) -> 26979.839 | F16: =IFERROR(F14-F8,0) -> 30597.222 | G16: =IFERROR(G14-G8,0) -> 33283.759 | H16: =IFERROR(H14-H8,0) -> 34653.846
B17: Install Cost per Unit (with inflation) | C17: =75000*(1+'Base Case Inputs'!$B$88)^1 -> 76875 | D17: =75000*(1+'Base Case Inputs'!$B$88)^2 -> 78796.875 | E17: =75000*(1+'Base Case Inputs'!$B$88)^3 -> 80766.797 | F17: =75000*(1+'Base Case Inputs'!$B$88)^4 -> 82785.967 | G17: =75000*(1+'Base Case Inputs'!$B$88)^5 -> 84855.616 | H17: =75000*(1+'Base Case Inputs'!$B$88)^6 -> 86977.006 | I17: $75k calculated in Y1 with detailed engineering analysis; annual inflation added thereafter
B18: 2. COST-DOWN DRIVER DECOMPOSITION — What Actually Moves the BOM
B19: Cost reductions modeled per $100K of equipment BOM (T-125 base). T-25 follows the same proportional trajectory at its ~$15K base. Costs shown as absolute $ on T-125 equivalent unit.
B20: Phase 1: Standardization (SN 1→20) | C20: Cost Δ: $100K → $82K (−18%)
B21: Design-for-Manufacturability (DFM) redesign | C21: −$6,000 | D21: Eliminate hand-fitted parts; tolerance stack analysis; reduce unique fasteners from ~120 to ~40
B22: First CNC automation (5-axis mill + transformer winder) | C22: −$4,000 | D22: Replace hand-machined manifolds & plates with CNC-cut parts; 60% labor reduction on machined components
B23: Standardized BOP packaging | C23: −$3,000 | D23: Common piping/valve/sensor kits; eliminate one-off field-fit assemblies
B24: Initial bulk procurement (stainless, copper, seals) | C24: −$3,000 | D24: 10-unit MOQ pricing vs. single-unit spot buys; ~15% materials discount
B25: Assembly sequence optimization | C25: −$2,000 | D25: Documented build procedures; fixture-based alignment; reduced rework from ~15% to ~3%
B26: Phase 2: Automation Ramp (SN 20→130) | C26: Cost Δ: $82K → $76K (−7.3%)
B27: AI-powered QA/QC automation | C27: −$2,000 | D27: Computer vision for weld inspection, dimensional verification; replaces 2 manual QC steps per unit
B28: Automated stack testing & conditioning | C28: −$1,500 | D28: AI-controlled break-in protocol; reduces test time from 72hr to 24hr; catches defects earlier
B29: Volume purchasing agreements (25+ unit MOQ) | C29: −$1,500 | D29: Locked pricing on SS316L plate, Viton seals, power electronics modules
B30: Laser cutter / waterjet integration | C30: −$1,000 | D30: Bipolar plate & gasket cutting automated; replaces outsourced waterjet job shop
B31: Phase 3: Mature Optimization (SN 130→535) | C31: Cost Δ: $76K → $73K (−3.9%)
B32: AI engineering tools (FEA/CFD/thermal, human-approved) | C32: −$1,000 | D32: Automated design iteration; senior engineer reviews & approves. Reduces eng. hours per design change by ~60%
B33: Robotic sub-assembly (first station) | C33: −$800 | D33: Automated cell stacking or electrode assembly; first commercially available cobot deployment
B34: Supply chain optimization (dual-sourcing, JIT) | C34: −$700 | D34: Reduced inventory carrying cost; competitive bidding on long-lead items
B35: Continuous improvement (kaizen) + workforce learning | C35: −$500 | D35: Technician experience curve; reduced scrap rate from ~3% to <1%
B36: Phase 4: Plateau → Inflation (SN 535→1560) | C36: Cost Δ: $73K → $73.5K (+0.7%) — Materials inflation begins to dominate
B37: Raw materials inflation (+2.5%/yr on ~60% of BOM) | C37: 1100 | D37: SS316L, nickel, copper — long-run 2-3% annual commodity inflation is the historical norm
B38: AI-driven predictive maintenance & process control | C38: −$400 | D38: Reduce unplanned downtime; optimize power electronics burn-in; ML on production data
B39: Additional robotic stations (welding, material handling) | C39: −$400 | D39: As cobot costs decline ~15%/yr, ROI threshold drops; deploy 2nd and 3rd stations
B40: Net: slight increase | C40: 300 | D40: The uncomfortable truth — at this point, further optimization cannot fully offset commodity inflation
B41: Phase 5+: Scale Production (SN 1560→6000+) | C41: Cost Δ: $73.5K → $74.5K (+1.4%) — Net annual creep ~1%/yr
B42: Materials inflation continues (+2.5%/yr) | C42: 1800 | D42: Stainless steel historically inflates 2-4%/yr; copper 3-5%/yr. Every financial model that ignores this is wrong.
B43: Full AI engineering pipeline (design → test → cert) | C43: −$500 | D43: AI generates design variants, runs simulations, drafts certification packages. Senior engineer approves.
...

Sheet Error Dashboard
A1: MODEL INTEGRITY DASHBOARD
A3: Balance Sheet Check (EOY)
B4: FY1 | C4: FY2 | D4: FY3 | E4: FY4 | F4: FY5 | G4: FY6 | H4: FY7
B5: =IF(Financials!P70="OK","OK","FAIL") -> OK | C5: =IF(Financials!AB70="OK","OK","FAIL") -> OK | D5: =IF(Financials!AN70="OK","OK","FAIL") -> OK | E5: =IF(Financials!AZ70="OK","OK","FAIL") -> OK | F5: =IF(Financials!BL70="OK","OK","FAIL") -> OK | G5: =IF(Financials!BX70="OK","OK","FAIL") -> OK | H5: =IF(Financials!CJ70="OK","OK","FAIL") -> OK
A7: Minimum Ending Cash (>= 0) | B7: =MIN(Financials!E101:CJ101) -> 273110.92 | C7: =IF(B7>=0,"OK","FAIL") -> OK
A8: Minimum Debt Outstanding (>= 0) | B8: =MIN(Financials!E58:CJ58) -> 0 | C8: =IF(B8>=0,"OK","FAIL") -> OK
A9: Minimum Total Revenue (>= 0) | B9: =MIN(Financials!E8:CJ8) -> 67307.692 | C9: =IF(B9>=0,"OK","FAIL") -> OK
A10: Max COGS - Revenue (<= 0) | B10: =SUMPRODUCT((Financials!E21:CJ21-Financials!E8:CJ8)*(Financials!E21:CJ21>Financials!E8:CJ8)) -> 0 | C10: =IF(B10<=0,"OK","FAIL") -> OK
A11: Formula Error Count (Financials + Model Assumptions) | B11: =SUMPRODUCT(--ISERROR(Financials!E1:CJ200))+SUMPRODUCT(--ISERROR('Model Assumptions'!G1:CL200)) -> 0 | C11: =IF(B11=0,"OK","FAIL") -> OK
A13: P&L Summary Operating Revenue Tie-Out (ex-PTC)
B14: FY1 | C14: FY2 | D14: FY3 | E14: FY4 | F14: FY5 | G14: FY6 | H14: FY7
B15: =IF(ABS('P&L Summary'!C9-SUM(Financials!E8:P8))<1,"OK","FAIL") -> OK | C15: =IF(ABS('P&L Summary'!D9-SUM(Financials!Q8:AB8))<1,"OK","FAIL") -> OK | D15: =IF(ABS('P&L Summary'!E9-SUM(Financials!AC8:AN8))<1,"OK","FAIL") -> OK | E15: =IF(ABS('P&L Summary'!F9-SUM(Financials!AO8:AZ8))<1,"OK","FAIL") -> OK | F15: =IF(ABS('P&L Summary'!G9-SUM(Financials!BA8:BL8))<1,"OK","FAIL") -> OK | G15: =IF(ABS('P&L Summary'!H9-SUM(Financials!BM8:BX8))<1,"OK","FAIL") -> OK | H15: =IF(ABS('P&L Summary'!I9-SUM(Financials!BY8:CJ8))<1,"OK","FAIL") -> OK
A17: Last verified: 2026-03-04 | B17: =Financials!AQ58 -> 0 | C17: =IF(B17=0,"OK","FAIL") -> OK

Sheet Change Log
A1: Version | B1: Date | C1: Author | D1: Summary
A2: v7.x | B2: 2024 | C2: Original | D2: Original model build (pre-Techstars).
A3: v8.0 | B3: 2025 | C3: Team | D3: Techstars restructure and metric overhaul.
A4: v8.1–v8.2 | B4: 2026-02 | C4: Claude | D4: Audit remediation, fiscal year labels, and sensitivity rebuild.
A5: v8.3 | B5: 2026-02 | C5: Claude | D5: T-2500 integration across inputs, schedules, and outputs.
A6: v8.4 | B6: 2026-03 | C6: Claude | D6: Text audit and investor-facing polish.
A7: v8.5 | B7: 2026-03-04 | C7: Codex | D7: Comprehensive remediation: debt terms docs, error dashboard, archive link break, tab order/colors, and final verification.
A8: v8.5.1 | B8: 2026-03-04 | C8: Codex | D8: Final audit remediation: Error Dashboard fixes, PTC presentation clarity, internal tab organization, verification pass complete.
A9: v8.5.2 | B9: 2026-03-04 | C9: Claude | D9: Final investor-readiness remediation: 39 false-positive error codes escaped in Claude Log/Notes text, Fundraising rows 10-11 converted from hardcodes to formulas (=X8+X9, =X7+X8), green font applied to cross-sheet links, end-to-end verification of 3 months, debt schedule, BS integrity (84/84 OK), Error Dashboard all-pass confirmed.
A10: v8.5.3 | B10: 2026-03-16 | C10: Remove T-2500 product line | D10: Removed T-2500 from all formulas (Financials rows 16/17/19), BCI inputs (rows 231-238), Model Assumptions schedules (rows 136-138), Learning Curve BOM (row 76), Personnel EU calc (row 146), and all text references across Overview, P&L Summary, Unit Economics, Fundraising, Use of Funds. Two-product model: T-25 + T-125.

Sheet Base Case Inputs
A1: TIMELINE | B1: Value | C1: Unit | D1: Note
A2: Start Month | B2: 46113 | D2: Month 1
A5: Facility Expansion Base Date | B5: =EDATE(B2,3) -> 46204 | D5: Base date for facility expansion schedule
A7: FACILITY / PRODUCTION | B7: Value | C7: Unit | D7: Note
A8: Nameplate H2 Production Per Facility | B8: 900000 | C8: kg / year | E8: Engineering design target
A10: kWh/kg | B10: 42 | D10: From H2 Production Costs | E10: Lab-validated at stack level; commercial system TBD
A11: Electricity Price | B11: =B98 -> 0.035 | C11: $ / kWh | D11: Shown for reference - determined in cell B97 | E11: Published OK industrial rate
A12: Asset Useful Life | B12: 9 | C12: years | D12: Straight-line depreciation period | E12: Engineering estimate
A13: Pilot Facility CapEx | B13: ='Facility AFE'!C29 -> 3300000 | C13: $ | D13: Capex drawn as straight-line over construction period. Actual draws will be milestone-based per EPC contract.
A14: Construction Duration (months) | B14: 12 | C14: months | D14: Months over which facility capex is drawn down during construction and commissioning
A15: H₂ Production Cost ($/kg) | B15: =ROUND(B94,2) -> 2.62 | D15: ROUND(B94, 2). B94 = Direct OpEx total (electricity + compression + transport + water). See B90:B93 for component breakdown.
A16: DO NOT ENTER H2 PRICE ANYWHERE ELSE IN THE WORKBOOK
A17: HYDROGEN SALE ASSUMPTIONS | B17: Value | C17: Unit | D17: Note
A18: Hydrogen Sale Price (Base) | B18: 25 | C18: $ / kg | D18: Base Case | Flat 7yr — no escalator. Conservative vs. cost inflation at 2.5%/yr. | E18: On-site small-volume pricing — validated by Airgas cylinder quote ($121/kg) and Platts specialty data ($15–$36/kg delivered)
A19: Hydrogen Sale Price (Sens 1) | B19: 15 | C19: $ / kg | D19: Sensitivity 1 | E19: Bear scenario — bulk industrial pricing near grey H₂ parity
A20: Hydrogen Sale Price (Sens 2) | B20: 20 | C20: $ / kg | D20: Sensitivity 2 | E20: Sensitivity scenario — mid-market delivered pricing
A21: Hydrogen Sale Price (Sens 3) | B21: 30 | C21: $ / kg | D21: Sensitivity 3 | E21: Sensitivity scenario — premium specialty applications
A22: Hydrogen Sale Price (Sens 4) | B22: 35 | C22: $ / kg | D22: Sensitivity 4 | E22: Bull scenario — cylinder-replacement pricing (incumbent $30–$121/kg)
A26: EQUIPMENT SALES ASSUMPTIONS | B26: Value | C26: Unit | D26: Note
A27: Unit Sale Price Per T-25 (25 kg/day) | B27: 35000 | C27: $ | D27: $35K blended ASP: $25K base + 50% options attach (~$10K avg). Source: Pulse Holdings Quote TE-PH-ELX-88-51 Jan 2026. Options: remote monitoring HW $3K, consumables $3K, extended warranty $6K = $12K at 50% attach = ~$6K avg uplift.
A28: T-25 Equipment COGS Rate | B28: ='Learning Curve'!C74/B27 -> 0.6 | D28: T-25 launch COGS rate. References LC R74 (T-25 BOM $15K) / B27 ($35K ASP). Starting at 42.9% — margin improves as BOM declines per learning curve (85% Wright's Law). Matches T-125 methodology in B34. Prior value: flat 60% hardcode (overestimated COGS by ~$6K/unit at launch). | E28: Starting rate — actual COGS decline per Learning Curve tab
A29: Annual T-25 Equipment Sales Schedule | D29: T-25 targets: Y1:25, Y2:75, Y3:150, Y4:250, Y5:350, Y6:450, Y7:600. Modular entry-level unit — lower price point drives higher volume. Door-opener product converting to T-125 upsell. | F29: Y1 | G29: Y2 | H29: Y3 | I29: Y4 | J29: Y5 | K29: Y6 | L29: Y7
A30: T-25 Total 7yr Units | B30: =SUM(F30:L30) -> 1900 | D30: Total T-25 units over 7 years. | F30: 25 | G30: 75 | H30: 150 | I30: 250 | J30: 350 | K30: 450 | L30: 600
A31: T-25 Annual Service Price ($/yr) | B31: 3500 | C31: $ | D31: ~10% of $35K T-25 sale price. Separated from B29 (unit total) to eliminate dual-purpose ambiguity. | E31: Validated — industry benchmark OEM service contracts avg 10%/yr of equipment capex. | F31: Y1 assumption: 25 units based on initial channel partner commitments (nexAir, Norco).
A33: Unit Sale Price Per T-125 (125 kg/day) | B33: 167000 | C33: $ | D33: $167K standard optioned ASP. Validated: Pulse Holdings Quote base $120K + options ($3K remote HW + $7.5K subscription + $30K SCADA + $4K consumables + $7.5K warranty = $52K at ~90% attach) ≈ $167K. | E33: Validated: $120K base + ~$47K options at standard attach = $167K. Source: Pulse Holdings Quote TE-PH-ELX-88-51.
A34: T-125 Equipment COGS Rate | B34: ='Learning Curve'!C75/B33 -> 0.5988024 | D34: T-125 launch COGS rate. References LC!C75 / B33 ($167K ASP). Starting at 59.9% — margin improves as BOM declines per learning curve. REFERENCE ONLY — not used in Financials engine. Actual COGS pulled directly from Learning Curve tab. | E34: Starting rate — actual COGS decline per Learning Curve tab
A35: Annual T-125 Equipment Sales Schedule | D35: T-125 targets: Y1:0, Y2:10, Y3:30, Y4:60, Y5:100, Y6:140, Y7:180. Commercial-scale unit at $167K — lower price than legacy T-500 ($750K) drives higher accessible volume. Introduced Y2 as early adopters emerge. | F35: Y1 | G35: Y2 | H35: Y3 | I35: Y4 | J35: Y5 | K35: Y6 | L35: Y7
A36: T-125 Total 7yr Units | B36: =SUM(F36:L36) -> 520 | D36: SUM(F35:L35) formula. Auto-calculated from annual schedule. Prior value (16,700) was a stale service price — fixed to 520 actual units. | F36: 0 | G36: 10 | H36: 30 | I36: 60 | J36: 100 | K36: 140 | L36: 180
A37: T-125 Annual Service Price ($/yr) | B37: 16700 | C37: $ | D37: ~10% of $167K T-125 sale price. Separated from B35 (unit total) to eliminate dual-purpose ambiguity. | E37: Validated — industry benchmark OEM service contracts avg 10%/yr of equipment capex. | F37: T-125 launches Y2. 10 units = early adopter estimate based on LOI pipeline. Scales with facility capacity addition.
A39: Services COGS Rate | B39: 0.2 | D39: 20% COGS = 80% gross margin on services | E39: Assumed: standard services margin for monitoring + maintenance. Service prices set at ~10% of unit capex per industry benchmark (OEM service contracts avg 10%/yr of equipment value).
A40: FINANCING | B40: Value | C40: Unit | D40: Note
A41: Seed Close Date | B41: 46143 | D41: In progress — fundraise launched Feb 2026; targeting May close
A42: Seed Equity | B42: 7500000 | D42: Target
A43: Seed Debt | B43: 2500000 | D43: Target
A44: Seed Project Financing | B44: 0 | D44: No separate project financing at Seed. The $2.5M venture debt (B43) covers all facility project costs including Zeeco CAPEX.
A46: Series A Close Date | B46: 46539 | D46: Manually set. Assumed: Series A timing dependent on seed milestones
A47: Series A Equity | B47: 40000000 | D47: Series A equity — funds R&D + manufacturing scale. Equity-heavy; tech proving stage
A48: Series A Debt | B48: 0
A49: Series A Project Financing | B49: 17000000 | D49: Sized to facility pipeline + inventory
A51: Series B Close Date | B51: =DATE(2029,3,1) -> 47178 | D51: Manually set. Assumed: Series B timing dependent on Series A milestones
...

Sheet Financials
B1: Year Counter | E1: 1 | F1: 1 | G1: 1 | H1: 1 | I1: 1 | J1: 1 | K1: 1 | L1: 1 | M1: 1 | N1: 1 | O1: 1 | P1: 1 | Q1: 2 | R1: 2 | S1: 2 | T1: 2 | U1: 2 | V1: 2 | W1: 2 | X1: 2 | Y1: 2 | Z1: 2 | AA1: 2 | AB1: 2 | AC1: 3 | AD1: 3 | AE1: 3 | AF1: 3 | AG1: 3 | AH1: 3 | AI1: 3 | AJ1: 3 | AK1: 3 | AL1: 3 | AM1: 3 | AN1: 3 | AO1: 4 | AP1: 4 | AQ1: 4 | AR1: 4 | AS1: 4 | AT1: 4 | AU1: 4 | AV1: 4 | AW1: 4 | AX1: 4 | AY1: 4 | AZ1: 4 | BA1: 5 | BB1: 5 | BC1: 5 | BD1: 5 | BE1: 5 | BF1: 5 | BG1: 5 | BH1: 5 | BI1: 5 | BJ1: 5 | BK1: 5 | BL1: 5 | BM1: 6 | BN1: 6 | BO1: 6 | BP1: 6 | BQ1: 6 | BR1: 6 | BS1: 6 | BT1: 6 | BU1: 6 | BV1: 6 | BW1: 6 | BX1: 6 | BY1: 7 | BZ1: 7 | CA1: 7 | CB1: 7 | CC1: 7 | CD1: 7 | CE1: 7 | CF1: 7 | CG1: 7 | CH1: 7 | CI1: 7 | CJ1: 7
B2: Year | E2: =YEAR(E4) -> 2026 | F2: =YEAR(F4) -> 2026 | G2: =YEAR(G4) -> 2026 | H2: =YEAR(H4) -> 2026 | I2: =YEAR(I4) -> 2026 | J2: =YEAR(J4) -> 2026 | K2: =YEAR(K4) -> 2026 | L2: =YEAR(L4) -> 2026 | ... CJ2: =YEAR(CJ4) -> 2033
B3: Month Counter | E3: 1 | F3: 2 | G3: 3 | H3: 4 | I3: 5 | J3: 6 | K3: 7 | L3: 8 | M3: 9 | N3: 10 | O3: 11 | P3: 12 | Q3: 13 | R3: 14 | S3: 15 | T3: 16 | U3: 17 | V3: 18 | W3: 19 | X3: 20 | Y3: 21 | Z3: 22 | AA3: 23 | AB3: 24 | AC3: 25 | AD3: 26 | AE3: 27 | AF3: 28 | AG3: 29 | AH3: 30 | AI3: 31 | AJ3: 32 | AK3: 33 | AL3: 34 | AM3: 35 | AN3: 36 | AO3: 37 | AP3: 38 | AQ3: 39 | AR3: 40 | AS3: 41 | AT3: 42 | AU3: 43 | AV3: 44 | AW3: 45 | AX3: 46 | AY3: 47 | AZ3: 48 | BA3: 49 | BB3: 50 | BC3: 51 | BD3: 52 | BE3: 53 | BF3: 54 | BG3: 55 | BH3: 56 | BI3: 57 | BJ3: 58 | BK3: 59 | BL3: 60 | BM3: 61 | BN3: 62 | BO3: 63 | BP3: 64 | BQ3: 65 | BR3: 66 | BS3: 67 | BT3: 68 | BU3: 69 | BV3: 70 | BW3: 71 | BX3: 72 | BY3: 73 | BZ3: 74 | CA3: 75 | CB3: 76 | CC3: 77 | CD3: 78 | CE3: 79 | CF3: 80 | CG3: 81 | CH3: 82 | CI3: 83 | CJ3: 84
B4: Date | E4: ='Base Case Inputs'!$B$2 -> 46113 | F4: =EDATE(E4,1) -> 46143 | G4: =EDATE(F4,1) -> 46174 | H4: =EDATE(G4,1) -> 46204 | I4: =EDATE(H4,1) -> 46235 | J4: =EDATE(I4,1) -> 46266 | K4: =EDATE(J4,1) -> 46296 | L4: =EDATE(K4,1) -> 46327 | M4: =EDATE(L4,1) -> 46357 | ... CJ4: =EDATE(CI4,1) -> 48639
B6: Income Statement
B8: Revenue | E8: =SUM(E9:E17) -> 67307.692 | F8: =SUM(F9:F17) -> 67307.692 | G8: =SUM(G9:G17) -> 67307.692 | H8: =SUM(H9:H17) -> 67307.692 | I8: =SUM(I9:I17) -> 67307.692 | J8: =SUM(J9:J17) -> 67307.692 | K8: =SUM(K9:K17) -> 67307.692 | L8: =SUM(L9:L17) -> 67307.692 | ... CJ8: =SUM(CJ9:CJ17) -> 27421520
